ERROR 2025-05-12 19:00:02,650 auth_views Giriþ sýrasýnda bir hata oluþtu: auth/logi.html
ERROR 2025-05-12 19:00:02,659 auth_views Giriþ sýrasýnda bir hata oluþtu: auth/logi.html
ERROR 2025-05-12 19:00:02,669 auth_views Giriþ sýrasýnda bir hata oluþtu: auth/logi.html
ERROR 2025-05-12 19:00:02,681 auth_views Giriþ sýrasýnda bir hata oluþtu: auth/logi.html
ERROR 2025-05-12 19:00:02,687 auth_views Giriþ sýrasýnda bir hata oluþtu: auth/logi.html
ERROR 2025-05-12 19:00:02,695 auth_views Giriþ sýrasýnda bir hata oluþtu: auth/logi.html
ERROR 2025-05-12 19:00:02,702 auth_views Giriþ sýrasýnda bir hata oluþtu: auth/logi.html
ERROR 2025-05-12 19:00:02,714 auth_views Giriþ sýrasýnda bir hata oluþtu: auth/logi.html
ERROR 2025-05-12 19:00:02,719 auth_views Giriþ sýrasýnda bir hata oluþtu: auth/logi.html
ERROR 2025-05-12 19:00:02,730 auth_views Giriþ sýrasýnda bir hata oluþtu: auth/logi.html
ERROR 2025-05-12 19:00:02,736 auth_views Giriþ sýrasýnda bir hata oluþtu: auth/logi.html
ERROR 2025-05-12 19:00:02,742 auth_views Giriþ sýrasýnda bir hata oluþtu: auth/logi.html
ERROR 2025-05-12 19:00:02,751 auth_views Giriþ sýrasýnda bir hata oluþtu: auth/logi.html
ERROR 2025-05-12 19:00:02,756 auth_views Giriþ sýrasýnda bir hata oluþtu: auth/logi.html
ERROR 2025-05-12 19:00:02,764 auth_views Giriþ sýrasýnda bir hata oluþtu: auth/logi.html
ERROR 2025-05-12 19:00:02,772 auth_views Giriþ sýrasýnda bir hata oluþtu: auth/logi.html
ERROR 2025-05-12 19:00:02,780 auth_views Giriþ sýrasýnda bir hata oluþtu: auth/logi.html
ERROR 2025-05-12 19:00:02,787 auth_views Giriþ sýrasýnda bir hata oluþtu: auth/logi.html
ERROR 2025-05-12 19:00:02,791 auth_views Giriþ sýrasýnda bir hata oluþtu: auth/logi.html
ERROR 2025-05-12 19:00:02,801 auth_views Giriþ sýrasýnda bir hata oluþtu: auth/logi.html
ERROR 2025-05-12 19:00:32,851 auth_views Giriþ sýrasýnda bir hata oluþtu: auth/logi.html
ERROR 2025-05-12 19:00:32,865 auth_views Giriþ sýrasýnda bir hata oluþtu: auth/logi.html
ERROR 2025-05-12 19:00:32,873 auth_views Giriþ sýrasýnda bir hata oluþtu: auth/logi.html
ERROR 2025-05-12 19:00:32,884 auth_views Giriþ sýrasýnda bir hata oluþtu: auth/logi.html
ERROR 2025-05-12 19:00:32,891 auth_views Giriþ sýrasýnda bir hata oluþtu: auth/logi.html
ERROR 2025-05-12 19:00:32,900 auth_views Giriþ sýrasýnda bir hata oluþtu: auth/logi.html
ERROR 2025-05-12 19:00:32,911 auth_views Giriþ sýrasýnda bir hata oluþtu: auth/logi.html
ERROR 2025-05-12 19:00:32,918 auth_views Giriþ sýrasýnda bir hata oluþtu: auth/logi.html
ERROR 2025-05-12 19:00:32,930 auth_views Giriþ sýrasýnda bir hata oluþtu: auth/logi.html
ERROR 2025-05-12 19:00:32,936 auth_views Giriþ sýrasýnda bir hata oluþtu: auth/logi.html
ERROR 2025-05-12 19:00:32,948 auth_views Giriþ sýrasýnda bir hata oluþtu: auth/logi.html
ERROR 2025-05-12 19:00:32,953 auth_views Giriþ sýrasýnda bir hata oluþtu: auth/logi.html
ERROR 2025-05-12 19:00:32,966 auth_views Giriþ sýrasýnda bir hata oluþtu: auth/logi.html
ERROR 2025-05-12 19:00:32,972 auth_views Giriþ sýrasýnda bir hata oluþtu: auth/logi.html
ERROR 2025-05-12 19:00:32,984 auth_views Giriþ sýrasýnda bir hata oluþtu: auth/logi.html
ERROR 2025-05-12 19:00:32,991 auth_views Giriþ sýrasýnda bir hata oluþtu: auth/logi.html
ERROR 2025-05-12 19:00:33,001 auth_views Giriþ sýrasýnda bir hata oluþtu: auth/logi.html
ERROR 2025-05-12 19:00:33,010 auth_views Giriþ sýrasýnda bir hata oluþtu: auth/logi.html
ERROR 2025-05-12 19:00:33,017 auth_views Giriþ sýrasýnda bir hata oluþtu: auth/logi.html
ERROR 2025-05-12 19:00:33,024 auth_views Giriþ sýrasýnda bir hata oluþtu: auth/logi.html
ERROR 2025-05-12 19:53:04,533 log Internal Server Error: /products/
Traceback (most recent call last):
  File "C:\Users\Nova Akademi\Desktop\oguzhan\oguzhanCrm\venv\Lib\site-packages\django\core\handlers\exception.py", line 47, in inner
    response = get_response(request)
               ^^^^^^^^^^^^^^^^^^^^^
  File "C:\Users\Nova Akademi\Desktop\oguzhan\oguzhanCrm\venv\Lib\site-packages\django\core\handlers\base.py", line 181, in _get_response
    response = wrapped_callback(request, *callback_args, **callback_kwargs)
               ^^^^^^^^^^^^^^^^^^^^^^^^^^^^^^^^^^^^^^^^^^^^^^^^^^^^^^^^^^^^
  File "C:\Users\Nova Akademi\Desktop\oguzhan\oguzhanCrm\django_dashboard\dashboard\views\product_view.py", line 8, in product_list
    return render(request, 'products/product_list.html', {'products': products})
           ^^^^^^^^^^^^^^^^^^^^^^^^^^^^^^^^^^^^^^^^^^^^^^^^^^^^^^^^^^^^^^^^^^^^^
  File "C:\Users\Nova Akademi\Desktop\oguzhan\oguzhanCrm\venv\Lib\site-packages\django\shortcuts.py", line 19, in render
    content = loader.render_to_string(template_name, context, request, using=using)
              ^^^^^^^^^^^^^^^^^^^^^^^^^^^^^^^^^^^^^^^^^^^^^^^^^^^^^^^^^^^^^^^^^^^^^
  File "C:\Users\Nova Akademi\Desktop\oguzhan\oguzhanCrm\venv\Lib\site-packages\django\template\loader.py", line 61, in render_to_string
    template = get_template(template_name, using=using)
               ^^^^^^^^^^^^^^^^^^^^^^^^^^^^^^^^^^^^^^^^
  File "C:\Users\Nova Akademi\Desktop\oguzhan\oguzhanCrm\venv\Lib\site-packages\django\template\loader.py", line 19, in get_template
    raise TemplateDoesNotExist(template_name, chain=chain)
django.template.exceptions.TemplateDoesNotExist: products/product_list.html
ERROR 2025-05-12 19:53:04,541 basehttp "GET /products/ HTTP/1.1" 500 82944
ERROR 2025-05-12 19:54:27,746 log Internal Server Error: /products/
Traceback (most recent call last):
  File "C:\Users\Nova Akademi\Desktop\oguzhan\oguzhanCrm\venv\Lib\site-packages\django\db\backends\utils.py", line 84, in _execute
    return self.cursor.execute(sql, params)
           ^^^^^^^^^^^^^^^^^^^^^^^^^^^^^^^^
  File "C:\Users\Nova Akademi\Desktop\oguzhan\oguzhanCrm\venv\Lib\site-packages\django\db\backends\mysql\base.py", line 73, in execute
    return self.cursor.execute(query, args)
           ^^^^^^^^^^^^^^^^^^^^^^^^^^^^^^^^
  File "C:\Users\Nova Akademi\Desktop\oguzhan\oguzhanCrm\venv\Lib\site-packages\MySQLdb\cursors.py", line 179, in execute
    res = self._query(mogrified_query)
          ^^^^^^^^^^^^^^^^^^^^^^^^^^^^
  File "C:\Users\Nova Akademi\Desktop\oguzhan\oguzhanCrm\venv\Lib\site-packages\MySQLdb\cursors.py", line 330, in _query
    db.query(q)
  File "C:\Users\Nova Akademi\Desktop\oguzhan\oguzhanCrm\venv\Lib\site-packages\MySQLdb\connections.py", line 280, in query
    _mysql.connection.query(self, query)
MySQLdb.ProgrammingError: (1146, "Table 'crm_db.dashboard_product' doesn't exist")

The above exception was the direct cause of the following exception:

Traceback (most recent call last):
  File "C:\Users\Nova Akademi\Desktop\oguzhan\oguzhanCrm\venv\Lib\site-packages\django\core\handlers\exception.py", line 47, in inner
    response = get_response(request)
               ^^^^^^^^^^^^^^^^^^^^^
  File "C:\Users\Nova Akademi\Desktop\oguzhan\oguzhanCrm\venv\Lib\site-packages\django\core\handlers\base.py", line 181, in _get_response
    response = wrapped_callback(request, *callback_args, **callback_kwargs)
               ^^^^^^^^^^^^^^^^^^^^^^^^^^^^^^^^^^^^^^^^^^^^^^^^^^^^^^^^^^^^
  File "C:\Users\Nova Akademi\Desktop\oguzhan\oguzhanCrm\django_dashboard\dashboard\views\product_view.py", line 8, in product_list
    return render(request, 'products/product_list.html', {'products': products})
           ^^^^^^^^^^^^^^^^^^^^^^^^^^^^^^^^^^^^^^^^^^^^^^^^^^^^^^^^^^^^^^^^^^^^^
  File "C:\Users\Nova Akademi\Desktop\oguzhan\oguzhanCrm\venv\Lib\site-packages\django\shortcuts.py", line 19, in render
    content = loader.render_to_string(template_name, context, request, using=using)
              ^^^^^^^^^^^^^^^^^^^^^^^^^^^^^^^^^^^^^^^^^^^^^^^^^^^^^^^^^^^^^^^^^^^^^
  File "C:\Users\Nova Akademi\Desktop\oguzhan\oguzhanCrm\venv\Lib\site-packages\django\template\loader.py", line 62, in render_to_string
    return template.render(context, request)
           ^^^^^^^^^^^^^^^^^^^^^^^^^^^^^^^^^
  File "C:\Users\Nova Akademi\Desktop\oguzhan\oguzhanCrm\venv\Lib\site-packages\django\template\backends\django.py", line 61, in render
    return self.template.render(context)
           ^^^^^^^^^^^^^^^^^^^^^^^^^^^^^
  File "C:\Users\Nova Akademi\Desktop\oguzhan\oguzhanCrm\venv\Lib\site-packages\django\template\base.py", line 170, in render
    return self._render(context)
           ^^^^^^^^^^^^^^^^^^^^^
  File "C:\Users\Nova Akademi\Desktop\oguzhan\oguzhanCrm\venv\Lib\site-packages\django\template\base.py", line 162, in _render
    return self.nodelist.render(context)
           ^^^^^^^^^^^^^^^^^^^^^^^^^^^^^
  File "C:\Users\Nova Akademi\Desktop\oguzhan\oguzhanCrm\venv\Lib\site-packages\django\template\base.py", line 938, in render
    bit = node.render_annotated(context)
          ^^^^^^^^^^^^^^^^^^^^^^^^^^^^^^
  File "C:\Users\Nova Akademi\Desktop\oguzhan\oguzhanCrm\venv\Lib\site-packages\django\template\base.py", line 905, in render_annotated
    return self.render(context)
           ^^^^^^^^^^^^^^^^^^^^
  File "C:\Users\Nova Akademi\Desktop\oguzhan\oguzhanCrm\venv\Lib\site-packages\django\template\defaulttags.py", line 168, in render
    len_values = len(values)
                 ^^^^^^^^^^^
  File "C:\Users\Nova Akademi\Desktop\oguzhan\oguzhanCrm\venv\Lib\site-packages\django\db\models\query.py", line 262, in __len__
    self._fetch_all()
  File "C:\Users\Nova Akademi\Desktop\oguzhan\oguzhanCrm\venv\Lib\site-packages\django\db\models\query.py", line 1324, in _fetch_all
    self._result_cache = list(self._iterable_class(self))
                         ^^^^^^^^^^^^^^^^^^^^^^^^^^^^^^^^
  File "C:\Users\Nova Akademi\Desktop\oguzhan\oguzhanCrm\venv\Lib\site-packages\django\db\models\query.py", line 51, in __iter__
    results = compiler.execute_sql(chunked_fetch=self.chunked_fetch, chunk_size=self.chunk_size)
              ^^^^^^^^^^^^^^^^^^^^^^^^^^^^^^^^^^^^^^^^^^^^^^^^^^^^^^^^^^^^^^^^^^^^^^^^^^^^^^^^^^
  File "C:\Users\Nova Akademi\Desktop\oguzhan\oguzhanCrm\venv\Lib\site-packages\django\db\models\sql\compiler.py", line 1169, in execute_sql
    cursor.execute(sql, params)
  File "C:\Users\Nova Akademi\Desktop\oguzhan\oguzhanCrm\venv\Lib\site-packages\django\db\backends\utils.py", line 98, in execute
    return super().execute(sql, params)
           ^^^^^^^^^^^^^^^^^^^^^^^^^^^^
  File "C:\Users\Nova Akademi\Desktop\oguzhan\oguzhanCrm\venv\Lib\site-packages\django\db\backends\utils.py", line 66, in execute
    return self._execute_with_wrappers(sql, params, many=False, executor=self._execute)
           ^^^^^^^^^^^^^^^^^^^^^^^^^^^^^^^^^^^^^^^^^^^^^^^^^^^^^^^^^^^^^^^^^^^^^^^^^^^^
  File "C:\Users\Nova Akademi\Desktop\oguzhan\oguzhanCrm\venv\Lib\site-packages\django\db\backends\utils.py", line 75, in _execute_with_wrappers
    return executor(sql, params, many, context)
           ^^^^^^^^^^^^^^^^^^^^^^^^^^^^^^^^^^^^
  File "C:\Users\Nova Akademi\Desktop\oguzhan\oguzhanCrm\venv\Lib\site-packages\django\db\backends\utils.py", line 79, in _execute
    with self.db.wrap_database_errors:
  File "C:\Users\Nova Akademi\Desktop\oguzhan\oguzhanCrm\venv\Lib\site-packages\django\db\utils.py", line 90, in __exit__
    raise dj_exc_value.with_traceback(traceback) from exc_value
  File "C:\Users\Nova Akademi\Desktop\oguzhan\oguzhanCrm\venv\Lib\site-packages\django\db\backends\utils.py", line 84, in _execute
    return self.cursor.execute(sql, params)
           ^^^^^^^^^^^^^^^^^^^^^^^^^^^^^^^^
  File "C:\Users\Nova Akademi\Desktop\oguzhan\oguzhanCrm\venv\Lib\site-packages\django\db\backends\mysql\base.py", line 73, in execute
    return self.cursor.execute(query, args)
           ^^^^^^^^^^^^^^^^^^^^^^^^^^^^^^^^
  File "C:\Users\Nova Akademi\Desktop\oguzhan\oguzhanCrm\venv\Lib\site-packages\MySQLdb\cursors.py", line 179, in execute
    res = self._query(mogrified_query)
          ^^^^^^^^^^^^^^^^^^^^^^^^^^^^
  File "C:\Users\Nova Akademi\Desktop\oguzhan\oguzhanCrm\venv\Lib\site-packages\MySQLdb\cursors.py", line 330, in _query
    db.query(q)
  File "C:\Users\Nova Akademi\Desktop\oguzhan\oguzhanCrm\venv\Lib\site-packages\MySQLdb\connections.py", line 280, in query
    _mysql.connection.query(self, query)
django.db.utils.ProgrammingError: (1146, "Table 'crm_db.dashboard_product' doesn't exist")
ERROR 2025-05-12 19:54:27,767 basehttp "GET /products/ HTTP/1.1" 500 202852
ERROR 2025-05-12 19:54:30,317 log Internal Server Error: /products/
Traceback (most recent call last):
  File "C:\Users\Nova Akademi\Desktop\oguzhan\oguzhanCrm\venv\Lib\site-packages\django\db\backends\utils.py", line 84, in _execute
    return self.cursor.execute(sql, params)
           ^^^^^^^^^^^^^^^^^^^^^^^^^^^^^^^^
  File "C:\Users\Nova Akademi\Desktop\oguzhan\oguzhanCrm\venv\Lib\site-packages\django\db\backends\mysql\base.py", line 73, in execute
    return self.cursor.execute(query, args)
           ^^^^^^^^^^^^^^^^^^^^^^^^^^^^^^^^
  File "C:\Users\Nova Akademi\Desktop\oguzhan\oguzhanCrm\venv\Lib\site-packages\MySQLdb\cursors.py", line 179, in execute
    res = self._query(mogrified_query)
          ^^^^^^^^^^^^^^^^^^^^^^^^^^^^
  File "C:\Users\Nova Akademi\Desktop\oguzhan\oguzhanCrm\venv\Lib\site-packages\MySQLdb\cursors.py", line 330, in _query
    db.query(q)
  File "C:\Users\Nova Akademi\Desktop\oguzhan\oguzhanCrm\venv\Lib\site-packages\MySQLdb\connections.py", line 280, in query
    _mysql.connection.query(self, query)
MySQLdb.ProgrammingError: (1146, "Table 'crm_db.dashboard_product' doesn't exist")

The above exception was the direct cause of the following exception:

Traceback (most recent call last):
  File "C:\Users\Nova Akademi\Desktop\oguzhan\oguzhanCrm\venv\Lib\site-packages\django\core\handlers\exception.py", line 47, in inner
    response = get_response(request)
               ^^^^^^^^^^^^^^^^^^^^^
  File "C:\Users\Nova Akademi\Desktop\oguzhan\oguzhanCrm\venv\Lib\site-packages\django\core\handlers\base.py", line 181, in _get_response
    response = wrapped_callback(request, *callback_args, **callback_kwargs)
               ^^^^^^^^^^^^^^^^^^^^^^^^^^^^^^^^^^^^^^^^^^^^^^^^^^^^^^^^^^^^
  File "C:\Users\Nova Akademi\Desktop\oguzhan\oguzhanCrm\django_dashboard\dashboard\views\product_view.py", line 8, in product_list
    return render(request, 'products/product_list.html', {'products': products})
           ^^^^^^^^^^^^^^^^^^^^^^^^^^^^^^^^^^^^^^^^^^^^^^^^^^^^^^^^^^^^^^^^^^^^^
  File "C:\Users\Nova Akademi\Desktop\oguzhan\oguzhanCrm\venv\Lib\site-packages\django\shortcuts.py", line 19, in render
    content = loader.render_to_string(template_name, context, request, using=using)
              ^^^^^^^^^^^^^^^^^^^^^^^^^^^^^^^^^^^^^^^^^^^^^^^^^^^^^^^^^^^^^^^^^^^^^
  File "C:\Users\Nova Akademi\Desktop\oguzhan\oguzhanCrm\venv\Lib\site-packages\django\template\loader.py", line 62, in render_to_string
    return template.render(context, request)
           ^^^^^^^^^^^^^^^^^^^^^^^^^^^^^^^^^
  File "C:\Users\Nova Akademi\Desktop\oguzhan\oguzhanCrm\venv\Lib\site-packages\django\template\backends\django.py", line 61, in render
    return self.template.render(context)
           ^^^^^^^^^^^^^^^^^^^^^^^^^^^^^
  File "C:\Users\Nova Akademi\Desktop\oguzhan\oguzhanCrm\venv\Lib\site-packages\django\template\base.py", line 170, in render
    return self._render(context)
           ^^^^^^^^^^^^^^^^^^^^^
  File "C:\Users\Nova Akademi\Desktop\oguzhan\oguzhanCrm\venv\Lib\site-packages\django\template\base.py", line 162, in _render
    return self.nodelist.render(context)
           ^^^^^^^^^^^^^^^^^^^^^^^^^^^^^
  File "C:\Users\Nova Akademi\Desktop\oguzhan\oguzhanCrm\venv\Lib\site-packages\django\template\base.py", line 938, in render
    bit = node.render_annotated(context)
          ^^^^^^^^^^^^^^^^^^^^^^^^^^^^^^
  File "C:\Users\Nova Akademi\Desktop\oguzhan\oguzhanCrm\venv\Lib\site-packages\django\template\base.py", line 905, in render_annotated
    return self.render(context)
           ^^^^^^^^^^^^^^^^^^^^
  File "C:\Users\Nova Akademi\Desktop\oguzhan\oguzhanCrm\venv\Lib\site-packages\django\template\defaulttags.py", line 168, in render
    len_values = len(values)
                 ^^^^^^^^^^^
  File "C:\Users\Nova Akademi\Desktop\oguzhan\oguzhanCrm\venv\Lib\site-packages\django\db\models\query.py", line 262, in __len__
    self._fetch_all()
  File "C:\Users\Nova Akademi\Desktop\oguzhan\oguzhanCrm\venv\Lib\site-packages\django\db\models\query.py", line 1324, in _fetch_all
    self._result_cache = list(self._iterable_class(self))
                         ^^^^^^^^^^^^^^^^^^^^^^^^^^^^^^^^
  File "C:\Users\Nova Akademi\Desktop\oguzhan\oguzhanCrm\venv\Lib\site-packages\django\db\models\query.py", line 51, in __iter__
    results = compiler.execute_sql(chunked_fetch=self.chunked_fetch, chunk_size=self.chunk_size)
              ^^^^^^^^^^^^^^^^^^^^^^^^^^^^^^^^^^^^^^^^^^^^^^^^^^^^^^^^^^^^^^^^^^^^^^^^^^^^^^^^^^
  File "C:\Users\Nova Akademi\Desktop\oguzhan\oguzhanCrm\venv\Lib\site-packages\django\db\models\sql\compiler.py", line 1169, in execute_sql
    cursor.execute(sql, params)
  File "C:\Users\Nova Akademi\Desktop\oguzhan\oguzhanCrm\venv\Lib\site-packages\django\db\backends\utils.py", line 98, in execute
    return super().execute(sql, params)
           ^^^^^^^^^^^^^^^^^^^^^^^^^^^^
  File "C:\Users\Nova Akademi\Desktop\oguzhan\oguzhanCrm\venv\Lib\site-packages\django\db\backends\utils.py", line 66, in execute
    return self._execute_with_wrappers(sql, params, many=False, executor=self._execute)
           ^^^^^^^^^^^^^^^^^^^^^^^^^^^^^^^^^^^^^^^^^^^^^^^^^^^^^^^^^^^^^^^^^^^^^^^^^^^^
  File "C:\Users\Nova Akademi\Desktop\oguzhan\oguzhanCrm\venv\Lib\site-packages\django\db\backends\utils.py", line 75, in _execute_with_wrappers
    return executor(sql, params, many, context)
           ^^^^^^^^^^^^^^^^^^^^^^^^^^^^^^^^^^^^
  File "C:\Users\Nova Akademi\Desktop\oguzhan\oguzhanCrm\venv\Lib\site-packages\django\db\backends\utils.py", line 79, in _execute
    with self.db.wrap_database_errors:
  File "C:\Users\Nova Akademi\Desktop\oguzhan\oguzhanCrm\venv\Lib\site-packages\django\db\utils.py", line 90, in __exit__
    raise dj_exc_value.with_traceback(traceback) from exc_value
  File "C:\Users\Nova Akademi\Desktop\oguzhan\oguzhanCrm\venv\Lib\site-packages\django\db\backends\utils.py", line 84, in _execute
    return self.cursor.execute(sql, params)
           ^^^^^^^^^^^^^^^^^^^^^^^^^^^^^^^^
  File "C:\Users\Nova Akademi\Desktop\oguzhan\oguzhanCrm\venv\Lib\site-packages\django\db\backends\mysql\base.py", line 73, in execute
    return self.cursor.execute(query, args)
           ^^^^^^^^^^^^^^^^^^^^^^^^^^^^^^^^
  File "C:\Users\Nova Akademi\Desktop\oguzhan\oguzhanCrm\venv\Lib\site-packages\MySQLdb\cursors.py", line 179, in execute
    res = self._query(mogrified_query)
          ^^^^^^^^^^^^^^^^^^^^^^^^^^^^
  File "C:\Users\Nova Akademi\Desktop\oguzhan\oguzhanCrm\venv\Lib\site-packages\MySQLdb\cursors.py", line 330, in _query
    db.query(q)
  File "C:\Users\Nova Akademi\Desktop\oguzhan\oguzhanCrm\venv\Lib\site-packages\MySQLdb\connections.py", line 280, in query
    _mysql.connection.query(self, query)
django.db.utils.ProgrammingError: (1146, "Table 'crm_db.dashboard_product' doesn't exist")
ERROR 2025-05-12 19:54:30,332 basehttp "GET /products/ HTTP/1.1" 500 202852
ERROR 2025-05-12 20:00:47,011 log Internal Server Error: /products/
Traceback (most recent call last):
  File "C:\Users\Nova Akademi\Desktop\oguzhan\oguzhanCrm\venv\Lib\site-packages\django\core\handlers\exception.py", line 47, in inner
    response = get_response(request)
               ^^^^^^^^^^^^^^^^^^^^^
  File "C:\Users\Nova Akademi\Desktop\oguzhan\oguzhanCrm\venv\Lib\site-packages\django\core\handlers\base.py", line 181, in _get_response
    response = wrapped_callback(request, *callback_args, **callback_kwargs)
               ^^^^^^^^^^^^^^^^^^^^^^^^^^^^^^^^^^^^^^^^^^^^^^^^^^^^^^^^^^^^
  File "C:\Users\Nova Akademi\Desktop\oguzhan\oguzhanCrm\django_dashboard\dashboard\views\product_view.py", line 8, in product_list
    return render(request, 'products/product_list.html', {'products': products})
           ^^^^^^^^^^^^^^^^^^^^^^^^^^^^^^^^^^^^^^^^^^^^^^^^^^^^^^^^^^^^^^^^^^^^^
  File "C:\Users\Nova Akademi\Desktop\oguzhan\oguzhanCrm\venv\Lib\site-packages\django\shortcuts.py", line 19, in render
    content = loader.render_to_string(template_name, context, request, using=using)
              ^^^^^^^^^^^^^^^^^^^^^^^^^^^^^^^^^^^^^^^^^^^^^^^^^^^^^^^^^^^^^^^^^^^^^
  File "C:\Users\Nova Akademi\Desktop\oguzhan\oguzhanCrm\venv\Lib\site-packages\django\template\loader.py", line 62, in render_to_string
    return template.render(context, request)
           ^^^^^^^^^^^^^^^^^^^^^^^^^^^^^^^^^
  File "C:\Users\Nova Akademi\Desktop\oguzhan\oguzhanCrm\venv\Lib\site-packages\django\template\backends\django.py", line 61, in render
    return self.template.render(context)
           ^^^^^^^^^^^^^^^^^^^^^^^^^^^^^
  File "C:\Users\Nova Akademi\Desktop\oguzhan\oguzhanCrm\venv\Lib\site-packages\django\template\base.py", line 170, in render
    return self._render(context)
           ^^^^^^^^^^^^^^^^^^^^^
  File "C:\Users\Nova Akademi\Desktop\oguzhan\oguzhanCrm\venv\Lib\site-packages\django\template\base.py", line 162, in _render
    return self.nodelist.render(context)
           ^^^^^^^^^^^^^^^^^^^^^^^^^^^^^
  File "C:\Users\Nova Akademi\Desktop\oguzhan\oguzhanCrm\venv\Lib\site-packages\django\template\base.py", line 938, in render
    bit = node.render_annotated(context)
          ^^^^^^^^^^^^^^^^^^^^^^^^^^^^^^
  File "C:\Users\Nova Akademi\Desktop\oguzhan\oguzhanCrm\venv\Lib\site-packages\django\template\base.py", line 905, in render_annotated
    return self.render(context)
           ^^^^^^^^^^^^^^^^^^^^
  File "C:\Users\Nova Akademi\Desktop\oguzhan\oguzhanCrm\venv\Lib\site-packages\django\template\defaulttags.py", line 446, in render
    url = reverse(view_name, args=args, kwargs=kwargs, current_app=current_app)
          ^^^^^^^^^^^^^^^^^^^^^^^^^^^^^^^^^^^^^^^^^^^^^^^^^^^^^^^^^^^^^^^^^^^^^
  File "C:\Users\Nova Akademi\Desktop\oguzhan\oguzhanCrm\venv\Lib\site-packages\django\urls\base.py", line 86, in reverse
    return resolver._reverse_with_prefix(view, prefix, *args, **kwargs)
           ^^^^^^^^^^^^^^^^^^^^^^^^^^^^^^^^^^^^^^^^^^^^^^^^^^^^^^^^^^^^
  File "C:\Users\Nova Akademi\Desktop\oguzhan\oguzhanCrm\venv\Lib\site-packages\django\urls\resolvers.py", line 694, in _reverse_with_prefix
    raise NoReverseMatch(msg)
django.urls.exceptions.NoReverseMatch: Reverse for 'dashboard_view' not found. 'dashboard_view' is not a valid view function or pattern name.
ERROR 2025-05-12 20:00:47,021 basehttp "GET /products/ HTTP/1.1" 500 127460
ERROR 2025-05-12 20:00:52,087 log Internal Server Error: /users/
Traceback (most recent call last):
  File "C:\Users\Nova Akademi\Desktop\oguzhan\oguzhanCrm\venv\Lib\site-packages\django\core\handlers\exception.py", line 47, in inner
    response = get_response(request)
               ^^^^^^^^^^^^^^^^^^^^^
  File "C:\Users\Nova Akademi\Desktop\oguzhan\oguzhanCrm\venv\Lib\site-packages\django\core\handlers\base.py", line 181, in _get_response
    response = wrapped_callback(request, *callback_args, **callback_kwargs)
               ^^^^^^^^^^^^^^^^^^^^^^^^^^^^^^^^^^^^^^^^^^^^^^^^^^^^^^^^^^^^
  File "C:\Users\Nova Akademi\Desktop\oguzhan\oguzhanCrm\django_dashboard\dashboard\views\auth_views.py", line 68, in users_page
    return render(request, 'auth/users.html', {'users': users})
           ^^^^^^^^^^^^^^^^^^^^^^^^^^^^^^^^^^^^^^^^^^^^^^^^^^^^
  File "C:\Users\Nova Akademi\Desktop\oguzhan\oguzhanCrm\venv\Lib\site-packages\django\shortcuts.py", line 19, in render
    content = loader.render_to_string(template_name, context, request, using=using)
              ^^^^^^^^^^^^^^^^^^^^^^^^^^^^^^^^^^^^^^^^^^^^^^^^^^^^^^^^^^^^^^^^^^^^^
  File "C:\Users\Nova Akademi\Desktop\oguzhan\oguzhanCrm\venv\Lib\site-packages\django\template\loader.py", line 62, in render_to_string
    return template.render(context, request)
           ^^^^^^^^^^^^^^^^^^^^^^^^^^^^^^^^^
  File "C:\Users\Nova Akademi\Desktop\oguzhan\oguzhanCrm\venv\Lib\site-packages\django\template\backends\django.py", line 61, in render
    return self.template.render(context)
           ^^^^^^^^^^^^^^^^^^^^^^^^^^^^^
  File "C:\Users\Nova Akademi\Desktop\oguzhan\oguzhanCrm\venv\Lib\site-packages\django\template\base.py", line 170, in render
    return self._render(context)
           ^^^^^^^^^^^^^^^^^^^^^
  File "C:\Users\Nova Akademi\Desktop\oguzhan\oguzhanCrm\venv\Lib\site-packages\django\template\base.py", line 162, in _render
    return self.nodelist.render(context)
           ^^^^^^^^^^^^^^^^^^^^^^^^^^^^^
  File "C:\Users\Nova Akademi\Desktop\oguzhan\oguzhanCrm\venv\Lib\site-packages\django\template\base.py", line 938, in render
    bit = node.render_annotated(context)
          ^^^^^^^^^^^^^^^^^^^^^^^^^^^^^^
  File "C:\Users\Nova Akademi\Desktop\oguzhan\oguzhanCrm\venv\Lib\site-packages\django\template\base.py", line 905, in render_annotated
    return self.render(context)
           ^^^^^^^^^^^^^^^^^^^^
  File "C:\Users\Nova Akademi\Desktop\oguzhan\oguzhanCrm\venv\Lib\site-packages\django\template\defaulttags.py", line 446, in render
    url = reverse(view_name, args=args, kwargs=kwargs, current_app=current_app)
          ^^^^^^^^^^^^^^^^^^^^^^^^^^^^^^^^^^^^^^^^^^^^^^^^^^^^^^^^^^^^^^^^^^^^^
  File "C:\Users\Nova Akademi\Desktop\oguzhan\oguzhanCrm\venv\Lib\site-packages\django\urls\base.py", line 86, in reverse
    return resolver._reverse_with_prefix(view, prefix, *args, **kwargs)
           ^^^^^^^^^^^^^^^^^^^^^^^^^^^^^^^^^^^^^^^^^^^^^^^^^^^^^^^^^^^^
  File "C:\Users\Nova Akademi\Desktop\oguzhan\oguzhanCrm\venv\Lib\site-packages\django\urls\resolvers.py", line 694, in _reverse_with_prefix
    raise NoReverseMatch(msg)
django.urls.exceptions.NoReverseMatch: Reverse for 'dashboard_view' not found. 'dashboard_view' is not a valid view function or pattern name.
ERROR 2025-05-12 20:00:52,095 basehttp "GET /users/ HTTP/1.1" 500 123756
ERROR 2025-05-12 20:01:15,742 log Internal Server Error: /users/
Traceback (most recent call last):
  File "C:\Users\Nova Akademi\Desktop\oguzhan\oguzhanCrm\venv\Lib\site-packages\django\core\handlers\exception.py", line 47, in inner
    response = get_response(request)
               ^^^^^^^^^^^^^^^^^^^^^
  File "C:\Users\Nova Akademi\Desktop\oguzhan\oguzhanCrm\venv\Lib\site-packages\django\core\handlers\base.py", line 181, in _get_response
    response = wrapped_callback(request, *callback_args, **callback_kwargs)
               ^^^^^^^^^^^^^^^^^^^^^^^^^^^^^^^^^^^^^^^^^^^^^^^^^^^^^^^^^^^^
  File "C:\Users\Nova Akademi\Desktop\oguzhan\oguzhanCrm\django_dashboard\dashboard\views\auth_views.py", line 68, in users_page
    return render(request, 'auth/users.html', {'users': users})
           ^^^^^^^^^^^^^^^^^^^^^^^^^^^^^^^^^^^^^^^^^^^^^^^^^^^^
  File "C:\Users\Nova Akademi\Desktop\oguzhan\oguzhanCrm\venv\Lib\site-packages\django\shortcuts.py", line 19, in render
    content = loader.render_to_string(template_name, context, request, using=using)
              ^^^^^^^^^^^^^^^^^^^^^^^^^^^^^^^^^^^^^^^^^^^^^^^^^^^^^^^^^^^^^^^^^^^^^
  File "C:\Users\Nova Akademi\Desktop\oguzhan\oguzhanCrm\venv\Lib\site-packages\django\template\loader.py", line 62, in render_to_string
    return template.render(context, request)
           ^^^^^^^^^^^^^^^^^^^^^^^^^^^^^^^^^
  File "C:\Users\Nova Akademi\Desktop\oguzhan\oguzhanCrm\venv\Lib\site-packages\django\template\backends\django.py", line 61, in render
    return self.template.render(context)
           ^^^^^^^^^^^^^^^^^^^^^^^^^^^^^
  File "C:\Users\Nova Akademi\Desktop\oguzhan\oguzhanCrm\venv\Lib\site-packages\django\template\base.py", line 170, in render
    return self._render(context)
           ^^^^^^^^^^^^^^^^^^^^^
  File "C:\Users\Nova Akademi\Desktop\oguzhan\oguzhanCrm\venv\Lib\site-packages\django\template\base.py", line 162, in _render
    return self.nodelist.render(context)
           ^^^^^^^^^^^^^^^^^^^^^^^^^^^^^
  File "C:\Users\Nova Akademi\Desktop\oguzhan\oguzhanCrm\venv\Lib\site-packages\django\template\base.py", line 938, in render
    bit = node.render_annotated(context)
          ^^^^^^^^^^^^^^^^^^^^^^^^^^^^^^
  File "C:\Users\Nova Akademi\Desktop\oguzhan\oguzhanCrm\venv\Lib\site-packages\django\template\base.py", line 905, in render_annotated
    return self.render(context)
           ^^^^^^^^^^^^^^^^^^^^
  File "C:\Users\Nova Akademi\Desktop\oguzhan\oguzhanCrm\venv\Lib\site-packages\django\template\defaulttags.py", line 446, in render
    url = reverse(view_name, args=args, kwargs=kwargs, current_app=current_app)
          ^^^^^^^^^^^^^^^^^^^^^^^^^^^^^^^^^^^^^^^^^^^^^^^^^^^^^^^^^^^^^^^^^^^^^
  File "C:\Users\Nova Akademi\Desktop\oguzhan\oguzhanCrm\venv\Lib\site-packages\django\urls\base.py", line 86, in reverse
    return resolver._reverse_with_prefix(view, prefix, *args, **kwargs)
           ^^^^^^^^^^^^^^^^^^^^^^^^^^^^^^^^^^^^^^^^^^^^^^^^^^^^^^^^^^^^
  File "C:\Users\Nova Akademi\Desktop\oguzhan\oguzhanCrm\venv\Lib\site-packages\django\urls\resolvers.py", line 694, in _reverse_with_prefix
    raise NoReverseMatch(msg)
django.urls.exceptions.NoReverseMatch: Reverse for 'dashboard_view' not found. 'dashboard_view' is not a valid view function or pattern name.
ERROR 2025-05-12 20:01:15,750 basehttp "GET /users/ HTTP/1.1" 500 123760
ERROR 2025-05-12 20:01:19,493 log Internal Server Error: /products/
Traceback (most recent call last):
  File "C:\Users\Nova Akademi\Desktop\oguzhan\oguzhanCrm\venv\Lib\site-packages\django\core\handlers\exception.py", line 47, in inner
    response = get_response(request)
               ^^^^^^^^^^^^^^^^^^^^^
  File "C:\Users\Nova Akademi\Desktop\oguzhan\oguzhanCrm\venv\Lib\site-packages\django\core\handlers\base.py", line 181, in _get_response
    response = wrapped_callback(request, *callback_args, **callback_kwargs)
               ^^^^^^^^^^^^^^^^^^^^^^^^^^^^^^^^^^^^^^^^^^^^^^^^^^^^^^^^^^^^
  File "C:\Users\Nova Akademi\Desktop\oguzhan\oguzhanCrm\django_dashboard\dashboard\views\product_view.py", line 8, in product_list
    return render(request, 'products/product_list.html', {'products': products})
           ^^^^^^^^^^^^^^^^^^^^^^^^^^^^^^^^^^^^^^^^^^^^^^^^^^^^^^^^^^^^^^^^^^^^^
  File "C:\Users\Nova Akademi\Desktop\oguzhan\oguzhanCrm\venv\Lib\site-packages\django\shortcuts.py", line 19, in render
    content = loader.render_to_string(template_name, context, request, using=using)
              ^^^^^^^^^^^^^^^^^^^^^^^^^^^^^^^^^^^^^^^^^^^^^^^^^^^^^^^^^^^^^^^^^^^^^
  File "C:\Users\Nova Akademi\Desktop\oguzhan\oguzhanCrm\venv\Lib\site-packages\django\template\loader.py", line 62, in render_to_string
    return template.render(context, request)
           ^^^^^^^^^^^^^^^^^^^^^^^^^^^^^^^^^
  File "C:\Users\Nova Akademi\Desktop\oguzhan\oguzhanCrm\venv\Lib\site-packages\django\template\backends\django.py", line 61, in render
    return self.template.render(context)
           ^^^^^^^^^^^^^^^^^^^^^^^^^^^^^
  File "C:\Users\Nova Akademi\Desktop\oguzhan\oguzhanCrm\venv\Lib\site-packages\django\template\base.py", line 170, in render
    return self._render(context)
           ^^^^^^^^^^^^^^^^^^^^^
  File "C:\Users\Nova Akademi\Desktop\oguzhan\oguzhanCrm\venv\Lib\site-packages\django\template\base.py", line 162, in _render
    return self.nodelist.render(context)
           ^^^^^^^^^^^^^^^^^^^^^^^^^^^^^
  File "C:\Users\Nova Akademi\Desktop\oguzhan\oguzhanCrm\venv\Lib\site-packages\django\template\base.py", line 938, in render
    bit = node.render_annotated(context)
          ^^^^^^^^^^^^^^^^^^^^^^^^^^^^^^
  File "C:\Users\Nova Akademi\Desktop\oguzhan\oguzhanCrm\venv\Lib\site-packages\django\template\base.py", line 905, in render_annotated
    return self.render(context)
           ^^^^^^^^^^^^^^^^^^^^
  File "C:\Users\Nova Akademi\Desktop\oguzhan\oguzhanCrm\venv\Lib\site-packages\django\template\defaulttags.py", line 446, in render
    url = reverse(view_name, args=args, kwargs=kwargs, current_app=current_app)
          ^^^^^^^^^^^^^^^^^^^^^^^^^^^^^^^^^^^^^^^^^^^^^^^^^^^^^^^^^^^^^^^^^^^^^
  File "C:\Users\Nova Akademi\Desktop\oguzhan\oguzhanCrm\venv\Lib\site-packages\django\urls\base.py", line 86, in reverse
    return resolver._reverse_with_prefix(view, prefix, *args, **kwargs)
           ^^^^^^^^^^^^^^^^^^^^^^^^^^^^^^^^^^^^^^^^^^^^^^^^^^^^^^^^^^^^
  File "C:\Users\Nova Akademi\Desktop\oguzhan\oguzhanCrm\venv\Lib\site-packages\django\urls\resolvers.py", line 694, in _reverse_with_prefix
    raise NoReverseMatch(msg)
django.urls.exceptions.NoReverseMatch: Reverse for 'dashboard_view' not found. 'dashboard_view' is not a valid view function or pattern name.
ERROR 2025-05-12 20:01:19,502 basehttp "GET /products/ HTTP/1.1" 500 127327
ERROR 2025-05-12 20:01:26,701 log Internal Server Error: /users/
Traceback (most recent call last):
  File "C:\Users\Nova Akademi\Desktop\oguzhan\oguzhanCrm\venv\Lib\site-packages\django\core\handlers\exception.py", line 47, in inner
    response = get_response(request)
               ^^^^^^^^^^^^^^^^^^^^^
  File "C:\Users\Nova Akademi\Desktop\oguzhan\oguzhanCrm\venv\Lib\site-packages\django\core\handlers\base.py", line 181, in _get_response
    response = wrapped_callback(request, *callback_args, **callback_kwargs)
               ^^^^^^^^^^^^^^^^^^^^^^^^^^^^^^^^^^^^^^^^^^^^^^^^^^^^^^^^^^^^
  File "C:\Users\Nova Akademi\Desktop\oguzhan\oguzhanCrm\django_dashboard\dashboard\views\auth_views.py", line 68, in users_page
    return render(request, 'auth/users.html', {'users': users})
           ^^^^^^^^^^^^^^^^^^^^^^^^^^^^^^^^^^^^^^^^^^^^^^^^^^^^
  File "C:\Users\Nova Akademi\Desktop\oguzhan\oguzhanCrm\venv\Lib\site-packages\django\shortcuts.py", line 19, in render
    content = loader.render_to_string(template_name, context, request, using=using)
              ^^^^^^^^^^^^^^^^^^^^^^^^^^^^^^^^^^^^^^^^^^^^^^^^^^^^^^^^^^^^^^^^^^^^^
  File "C:\Users\Nova Akademi\Desktop\oguzhan\oguzhanCrm\venv\Lib\site-packages\django\template\loader.py", line 62, in render_to_string
    return template.render(context, request)
           ^^^^^^^^^^^^^^^^^^^^^^^^^^^^^^^^^
  File "C:\Users\Nova Akademi\Desktop\oguzhan\oguzhanCrm\venv\Lib\site-packages\django\template\backends\django.py", line 61, in render
    return self.template.render(context)
           ^^^^^^^^^^^^^^^^^^^^^^^^^^^^^
  File "C:\Users\Nova Akademi\Desktop\oguzhan\oguzhanCrm\venv\Lib\site-packages\django\template\base.py", line 170, in render
    return self._render(context)
           ^^^^^^^^^^^^^^^^^^^^^
  File "C:\Users\Nova Akademi\Desktop\oguzhan\oguzhanCrm\venv\Lib\site-packages\django\template\base.py", line 162, in _render
    return self.nodelist.render(context)
           ^^^^^^^^^^^^^^^^^^^^^^^^^^^^^
  File "C:\Users\Nova Akademi\Desktop\oguzhan\oguzhanCrm\venv\Lib\site-packages\django\template\base.py", line 938, in render
    bit = node.render_annotated(context)
          ^^^^^^^^^^^^^^^^^^^^^^^^^^^^^^
  File "C:\Users\Nova Akademi\Desktop\oguzhan\oguzhanCrm\venv\Lib\site-packages\django\template\base.py", line 905, in render_annotated
    return self.render(context)
           ^^^^^^^^^^^^^^^^^^^^
  File "C:\Users\Nova Akademi\Desktop\oguzhan\oguzhanCrm\venv\Lib\site-packages\django\template\defaulttags.py", line 446, in render
    url = reverse(view_name, args=args, kwargs=kwargs, current_app=current_app)
          ^^^^^^^^^^^^^^^^^^^^^^^^^^^^^^^^^^^^^^^^^^^^^^^^^^^^^^^^^^^^^^^^^^^^^
  File "C:\Users\Nova Akademi\Desktop\oguzhan\oguzhanCrm\venv\Lib\site-packages\django\urls\base.py", line 86, in reverse
    return resolver._reverse_with_prefix(view, prefix, *args, **kwargs)
           ^^^^^^^^^^^^^^^^^^^^^^^^^^^^^^^^^^^^^^^^^^^^^^^^^^^^^^^^^^^^
  File "C:\Users\Nova Akademi\Desktop\oguzhan\oguzhanCrm\venv\Lib\site-packages\django\urls\resolvers.py", line 694, in _reverse_with_prefix
    raise NoReverseMatch(msg)
django.urls.exceptions.NoReverseMatch: Reverse for 'dashboard_view' not found. 'dashboard_view' is not a valid view function or pattern name.
ERROR 2025-05-12 20:01:26,711 basehttp "GET /users/ HTTP/1.1" 500 123760
ERROR 2025-05-12 20:01:27,348 log Internal Server Error: /users/
Traceback (most recent call last):
  File "C:\Users\Nova Akademi\Desktop\oguzhan\oguzhanCrm\venv\Lib\site-packages\django\core\handlers\exception.py", line 47, in inner
    response = get_response(request)
               ^^^^^^^^^^^^^^^^^^^^^
  File "C:\Users\Nova Akademi\Desktop\oguzhan\oguzhanCrm\venv\Lib\site-packages\django\core\handlers\base.py", line 181, in _get_response
    response = wrapped_callback(request, *callback_args, **callback_kwargs)
               ^^^^^^^^^^^^^^^^^^^^^^^^^^^^^^^^^^^^^^^^^^^^^^^^^^^^^^^^^^^^
  File "C:\Users\Nova Akademi\Desktop\oguzhan\oguzhanCrm\django_dashboard\dashboard\views\auth_views.py", line 68, in users_page
    return render(request, 'auth/users.html', {'users': users})
           ^^^^^^^^^^^^^^^^^^^^^^^^^^^^^^^^^^^^^^^^^^^^^^^^^^^^
  File "C:\Users\Nova Akademi\Desktop\oguzhan\oguzhanCrm\venv\Lib\site-packages\django\shortcuts.py", line 19, in render
    content = loader.render_to_string(template_name, context, request, using=using)
              ^^^^^^^^^^^^^^^^^^^^^^^^^^^^^^^^^^^^^^^^^^^^^^^^^^^^^^^^^^^^^^^^^^^^^
  File "C:\Users\Nova Akademi\Desktop\oguzhan\oguzhanCrm\venv\Lib\site-packages\django\template\loader.py", line 62, in render_to_string
    return template.render(context, request)
           ^^^^^^^^^^^^^^^^^^^^^^^^^^^^^^^^^
  File "C:\Users\Nova Akademi\Desktop\oguzhan\oguzhanCrm\venv\Lib\site-packages\django\template\backends\django.py", line 61, in render
    return self.template.render(context)
           ^^^^^^^^^^^^^^^^^^^^^^^^^^^^^
  File "C:\Users\Nova Akademi\Desktop\oguzhan\oguzhanCrm\venv\Lib\site-packages\django\template\base.py", line 170, in render
    return self._render(context)
           ^^^^^^^^^^^^^^^^^^^^^
  File "C:\Users\Nova Akademi\Desktop\oguzhan\oguzhanCrm\venv\Lib\site-packages\django\template\base.py", line 162, in _render
    return self.nodelist.render(context)
           ^^^^^^^^^^^^^^^^^^^^^^^^^^^^^
  File "C:\Users\Nova Akademi\Desktop\oguzhan\oguzhanCrm\venv\Lib\site-packages\django\template\base.py", line 938, in render
    bit = node.render_annotated(context)
          ^^^^^^^^^^^^^^^^^^^^^^^^^^^^^^
  File "C:\Users\Nova Akademi\Desktop\oguzhan\oguzhanCrm\venv\Lib\site-packages\django\template\base.py", line 905, in render_annotated
    return self.render(context)
           ^^^^^^^^^^^^^^^^^^^^
  File "C:\Users\Nova Akademi\Desktop\oguzhan\oguzhanCrm\venv\Lib\site-packages\django\template\defaulttags.py", line 446, in render
    url = reverse(view_name, args=args, kwargs=kwargs, current_app=current_app)
          ^^^^^^^^^^^^^^^^^^^^^^^^^^^^^^^^^^^^^^^^^^^^^^^^^^^^^^^^^^^^^^^^^^^^^
  File "C:\Users\Nova Akademi\Desktop\oguzhan\oguzhanCrm\venv\Lib\site-packages\django\urls\base.py", line 86, in reverse
    return resolver._reverse_with_prefix(view, prefix, *args, **kwargs)
           ^^^^^^^^^^^^^^^^^^^^^^^^^^^^^^^^^^^^^^^^^^^^^^^^^^^^^^^^^^^^
  File "C:\Users\Nova Akademi\Desktop\oguzhan\oguzhanCrm\venv\Lib\site-packages\django\urls\resolvers.py", line 694, in _reverse_with_prefix
    raise NoReverseMatch(msg)
django.urls.exceptions.NoReverseMatch: Reverse for 'dashboard_view' not found. 'dashboard_view' is not a valid view function or pattern name.
ERROR 2025-05-12 20:01:27,352 basehttp "GET /users/ HTTP/1.1" 500 123897
ERROR 2025-05-12 20:01:41,870 log Internal Server Error: /users/
Traceback (most recent call last):
  File "C:\Users\Nova Akademi\Desktop\oguzhan\oguzhanCrm\venv\Lib\site-packages\django\core\handlers\exception.py", line 47, in inner
    response = get_response(request)
               ^^^^^^^^^^^^^^^^^^^^^
  File "C:\Users\Nova Akademi\Desktop\oguzhan\oguzhanCrm\venv\Lib\site-packages\django\core\handlers\base.py", line 181, in _get_response
    response = wrapped_callback(request, *callback_args, **callback_kwargs)
               ^^^^^^^^^^^^^^^^^^^^^^^^^^^^^^^^^^^^^^^^^^^^^^^^^^^^^^^^^^^^
  File "C:\Users\Nova Akademi\Desktop\oguzhan\oguzhanCrm\django_dashboard\dashboard\views\auth_views.py", line 68, in users_page
    return render(request, 'auth/users.html', {'users': users})
           ^^^^^^^^^^^^^^^^^^^^^^^^^^^^^^^^^^^^^^^^^^^^^^^^^^^^
  File "C:\Users\Nova Akademi\Desktop\oguzhan\oguzhanCrm\venv\Lib\site-packages\django\shortcuts.py", line 19, in render
    content = loader.render_to_string(template_name, context, request, using=using)
              ^^^^^^^^^^^^^^^^^^^^^^^^^^^^^^^^^^^^^^^^^^^^^^^^^^^^^^^^^^^^^^^^^^^^^
  File "C:\Users\Nova Akademi\Desktop\oguzhan\oguzhanCrm\venv\Lib\site-packages\django\template\loader.py", line 62, in render_to_string
    return template.render(context, request)
           ^^^^^^^^^^^^^^^^^^^^^^^^^^^^^^^^^
  File "C:\Users\Nova Akademi\Desktop\oguzhan\oguzhanCrm\venv\Lib\site-packages\django\template\backends\django.py", line 61, in render
    return self.template.render(context)
           ^^^^^^^^^^^^^^^^^^^^^^^^^^^^^
  File "C:\Users\Nova Akademi\Desktop\oguzhan\oguzhanCrm\venv\Lib\site-packages\django\template\base.py", line 170, in render
    return self._render(context)
           ^^^^^^^^^^^^^^^^^^^^^
  File "C:\Users\Nova Akademi\Desktop\oguzhan\oguzhanCrm\venv\Lib\site-packages\django\template\base.py", line 162, in _render
    return self.nodelist.render(context)
           ^^^^^^^^^^^^^^^^^^^^^^^^^^^^^
  File "C:\Users\Nova Akademi\Desktop\oguzhan\oguzhanCrm\venv\Lib\site-packages\django\template\base.py", line 938, in render
    bit = node.render_annotated(context)
          ^^^^^^^^^^^^^^^^^^^^^^^^^^^^^^
  File "C:\Users\Nova Akademi\Desktop\oguzhan\oguzhanCrm\venv\Lib\site-packages\django\template\base.py", line 905, in render_annotated
    return self.render(context)
           ^^^^^^^^^^^^^^^^^^^^
  File "C:\Users\Nova Akademi\Desktop\oguzhan\oguzhanCrm\venv\Lib\site-packages\django\template\defaulttags.py", line 446, in render
    url = reverse(view_name, args=args, kwargs=kwargs, current_app=current_app)
          ^^^^^^^^^^^^^^^^^^^^^^^^^^^^^^^^^^^^^^^^^^^^^^^^^^^^^^^^^^^^^^^^^^^^^
  File "C:\Users\Nova Akademi\Desktop\oguzhan\oguzhanCrm\venv\Lib\site-packages\django\urls\base.py", line 86, in reverse
    return resolver._reverse_with_prefix(view, prefix, *args, **kwargs)
           ^^^^^^^^^^^^^^^^^^^^^^^^^^^^^^^^^^^^^^^^^^^^^^^^^^^^^^^^^^^^
  File "C:\Users\Nova Akademi\Desktop\oguzhan\oguzhanCrm\venv\Lib\site-packages\django\urls\resolvers.py", line 694, in _reverse_with_prefix
    raise NoReverseMatch(msg)
django.urls.exceptions.NoReverseMatch: Reverse for 'dashboard_view' not found. 'dashboard_view' is not a valid view function or pattern name.
ERROR 2025-05-12 20:01:41,874 basehttp "GET /users/ HTTP/1.1" 500 123760
ERROR 2025-05-12 20:07:31,878 log Internal Server Error: /products/
Traceback (most recent call last):
  File "C:\Users\Nova Akademi\Desktop\oguzhan\oguzhanCrm\venv\Lib\site-packages\django\core\handlers\exception.py", line 47, in inner
    response = get_response(request)
               ^^^^^^^^^^^^^^^^^^^^^
  File "C:\Users\Nova Akademi\Desktop\oguzhan\oguzhanCrm\venv\Lib\site-packages\django\core\handlers\base.py", line 181, in _get_response
    response = wrapped_callback(request, *callback_args, **callback_kwargs)
               ^^^^^^^^^^^^^^^^^^^^^^^^^^^^^^^^^^^^^^^^^^^^^^^^^^^^^^^^^^^^
  File "C:\Users\Nova Akademi\Desktop\oguzhan\oguzhanCrm\django_dashboard\dashboard\views\product_view.py", line 8, in product_list
    return render(request, 'products/product_list.html', {'products': products})
           ^^^^^^^^^^^^^^^^^^^^^^^^^^^^^^^^^^^^^^^^^^^^^^^^^^^^^^^^^^^^^^^^^^^^^
  File "C:\Users\Nova Akademi\Desktop\oguzhan\oguzhanCrm\venv\Lib\site-packages\django\shortcuts.py", line 19, in render
    content = loader.render_to_string(template_name, context, request, using=using)
              ^^^^^^^^^^^^^^^^^^^^^^^^^^^^^^^^^^^^^^^^^^^^^^^^^^^^^^^^^^^^^^^^^^^^^
  File "C:\Users\Nova Akademi\Desktop\oguzhan\oguzhanCrm\venv\Lib\site-packages\django\template\loader.py", line 62, in render_to_string
    return template.render(context, request)
           ^^^^^^^^^^^^^^^^^^^^^^^^^^^^^^^^^
  File "C:\Users\Nova Akademi\Desktop\oguzhan\oguzhanCrm\venv\Lib\site-packages\django\template\backends\django.py", line 61, in render
    return self.template.render(context)
           ^^^^^^^^^^^^^^^^^^^^^^^^^^^^^
  File "C:\Users\Nova Akademi\Desktop\oguzhan\oguzhanCrm\venv\Lib\site-packages\django\template\base.py", line 170, in render
    return self._render(context)
           ^^^^^^^^^^^^^^^^^^^^^
  File "C:\Users\Nova Akademi\Desktop\oguzhan\oguzhanCrm\venv\Lib\site-packages\django\template\base.py", line 162, in _render
    return self.nodelist.render(context)
           ^^^^^^^^^^^^^^^^^^^^^^^^^^^^^
  File "C:\Users\Nova Akademi\Desktop\oguzhan\oguzhanCrm\venv\Lib\site-packages\django\template\base.py", line 938, in render
    bit = node.render_annotated(context)
          ^^^^^^^^^^^^^^^^^^^^^^^^^^^^^^
  File "C:\Users\Nova Akademi\Desktop\oguzhan\oguzhanCrm\venv\Lib\site-packages\django\template\base.py", line 905, in render_annotated
    return self.render(context)
           ^^^^^^^^^^^^^^^^^^^^
  File "C:\Users\Nova Akademi\Desktop\oguzhan\oguzhanCrm\venv\Lib\site-packages\django\template\defaulttags.py", line 446, in render
    url = reverse(view_name, args=args, kwargs=kwargs, current_app=current_app)
          ^^^^^^^^^^^^^^^^^^^^^^^^^^^^^^^^^^^^^^^^^^^^^^^^^^^^^^^^^^^^^^^^^^^^^
  File "C:\Users\Nova Akademi\Desktop\oguzhan\oguzhanCrm\venv\Lib\site-packages\django\urls\base.py", line 86, in reverse
    return resolver._reverse_with_prefix(view, prefix, *args, **kwargs)
           ^^^^^^^^^^^^^^^^^^^^^^^^^^^^^^^^^^^^^^^^^^^^^^^^^^^^^^^^^^^^
  File "C:\Users\Nova Akademi\Desktop\oguzhan\oguzhanCrm\venv\Lib\site-packages\django\urls\resolvers.py", line 694, in _reverse_with_prefix
    raise NoReverseMatch(msg)
django.urls.exceptions.NoReverseMatch: Reverse for 'add_product' not found. 'add_product' is not a valid view function or pattern name.
ERROR 2025-05-12 20:07:31,892 basehttp "GET /products/ HTTP/1.1" 500 120434
ERROR 2025-05-12 20:07:32,827 log Internal Server Error: /products/
Traceback (most recent call last):
  File "C:\Users\Nova Akademi\Desktop\oguzhan\oguzhanCrm\venv\Lib\site-packages\django\core\handlers\exception.py", line 47, in inner
    response = get_response(request)
               ^^^^^^^^^^^^^^^^^^^^^
  File "C:\Users\Nova Akademi\Desktop\oguzhan\oguzhanCrm\venv\Lib\site-packages\django\core\handlers\base.py", line 181, in _get_response
    response = wrapped_callback(request, *callback_args, **callback_kwargs)
               ^^^^^^^^^^^^^^^^^^^^^^^^^^^^^^^^^^^^^^^^^^^^^^^^^^^^^^^^^^^^
  File "C:\Users\Nova Akademi\Desktop\oguzhan\oguzhanCrm\django_dashboard\dashboard\views\product_view.py", line 8, in product_list
    return render(request, 'products/product_list.html', {'products': products})
           ^^^^^^^^^^^^^^^^^^^^^^^^^^^^^^^^^^^^^^^^^^^^^^^^^^^^^^^^^^^^^^^^^^^^^
  File "C:\Users\Nova Akademi\Desktop\oguzhan\oguzhanCrm\venv\Lib\site-packages\django\shortcuts.py", line 19, in render
    content = loader.render_to_string(template_name, context, request, using=using)
              ^^^^^^^^^^^^^^^^^^^^^^^^^^^^^^^^^^^^^^^^^^^^^^^^^^^^^^^^^^^^^^^^^^^^^
  File "C:\Users\Nova Akademi\Desktop\oguzhan\oguzhanCrm\venv\Lib\site-packages\django\template\loader.py", line 62, in render_to_string
    return template.render(context, request)
           ^^^^^^^^^^^^^^^^^^^^^^^^^^^^^^^^^
  File "C:\Users\Nova Akademi\Desktop\oguzhan\oguzhanCrm\venv\Lib\site-packages\django\template\backends\django.py", line 61, in render
    return self.template.render(context)
           ^^^^^^^^^^^^^^^^^^^^^^^^^^^^^
  File "C:\Users\Nova Akademi\Desktop\oguzhan\oguzhanCrm\venv\Lib\site-packages\django\template\base.py", line 170, in render
    return self._render(context)
           ^^^^^^^^^^^^^^^^^^^^^
  File "C:\Users\Nova Akademi\Desktop\oguzhan\oguzhanCrm\venv\Lib\site-packages\django\template\base.py", line 162, in _render
    return self.nodelist.render(context)
           ^^^^^^^^^^^^^^^^^^^^^^^^^^^^^
  File "C:\Users\Nova Akademi\Desktop\oguzhan\oguzhanCrm\venv\Lib\site-packages\django\template\base.py", line 938, in render
    bit = node.render_annotated(context)
          ^^^^^^^^^^^^^^^^^^^^^^^^^^^^^^
  File "C:\Users\Nova Akademi\Desktop\oguzhan\oguzhanCrm\venv\Lib\site-packages\django\template\base.py", line 905, in render_annotated
    return self.render(context)
           ^^^^^^^^^^^^^^^^^^^^
  File "C:\Users\Nova Akademi\Desktop\oguzhan\oguzhanCrm\venv\Lib\site-packages\django\template\defaulttags.py", line 446, in render
    url = reverse(view_name, args=args, kwargs=kwargs, current_app=current_app)
          ^^^^^^^^^^^^^^^^^^^^^^^^^^^^^^^^^^^^^^^^^^^^^^^^^^^^^^^^^^^^^^^^^^^^^
  File "C:\Users\Nova Akademi\Desktop\oguzhan\oguzhanCrm\venv\Lib\site-packages\django\urls\base.py", line 86, in reverse
    return resolver._reverse_with_prefix(view, prefix, *args, **kwargs)
           ^^^^^^^^^^^^^^^^^^^^^^^^^^^^^^^^^^^^^^^^^^^^^^^^^^^^^^^^^^^^
  File "C:\Users\Nova Akademi\Desktop\oguzhan\oguzhanCrm\venv\Lib\site-packages\django\urls\resolvers.py", line 694, in _reverse_with_prefix
    raise NoReverseMatch(msg)
django.urls.exceptions.NoReverseMatch: Reverse for 'add_product' not found. 'add_product' is not a valid view function or pattern name.
ERROR 2025-05-12 20:07:32,834 basehttp "GET /products/ HTTP/1.1" 500 120434
ERROR 2025-05-12 20:07:48,605 log Internal Server Error: /products/
Traceback (most recent call last):
  File "C:\Users\Nova Akademi\Desktop\oguzhan\oguzhanCrm\venv\Lib\site-packages\django\core\handlers\exception.py", line 47, in inner
    response = get_response(request)
               ^^^^^^^^^^^^^^^^^^^^^
  File "C:\Users\Nova Akademi\Desktop\oguzhan\oguzhanCrm\venv\Lib\site-packages\django\core\handlers\base.py", line 181, in _get_response
    response = wrapped_callback(request, *callback_args, **callback_kwargs)
               ^^^^^^^^^^^^^^^^^^^^^^^^^^^^^^^^^^^^^^^^^^^^^^^^^^^^^^^^^^^^
  File "C:\Users\Nova Akademi\Desktop\oguzhan\oguzhanCrm\django_dashboard\dashboard\views\product_view.py", line 8, in product_list
    return render(request, 'products/product_list.html', {'products': products})
           ^^^^^^^^^^^^^^^^^^^^^^^^^^^^^^^^^^^^^^^^^^^^^^^^^^^^^^^^^^^^^^^^^^^^^
  File "C:\Users\Nova Akademi\Desktop\oguzhan\oguzhanCrm\venv\Lib\site-packages\django\shortcuts.py", line 19, in render
    content = loader.render_to_string(template_name, context, request, using=using)
              ^^^^^^^^^^^^^^^^^^^^^^^^^^^^^^^^^^^^^^^^^^^^^^^^^^^^^^^^^^^^^^^^^^^^^
  File "C:\Users\Nova Akademi\Desktop\oguzhan\oguzhanCrm\venv\Lib\site-packages\django\template\loader.py", line 62, in render_to_string
    return template.render(context, request)
           ^^^^^^^^^^^^^^^^^^^^^^^^^^^^^^^^^
  File "C:\Users\Nova Akademi\Desktop\oguzhan\oguzhanCrm\venv\Lib\site-packages\django\template\backends\django.py", line 61, in render
    return self.template.render(context)
           ^^^^^^^^^^^^^^^^^^^^^^^^^^^^^
  File "C:\Users\Nova Akademi\Desktop\oguzhan\oguzhanCrm\venv\Lib\site-packages\django\template\base.py", line 170, in render
    return self._render(context)
           ^^^^^^^^^^^^^^^^^^^^^
  File "C:\Users\Nova Akademi\Desktop\oguzhan\oguzhanCrm\venv\Lib\site-packages\django\template\base.py", line 162, in _render
    return self.nodelist.render(context)
           ^^^^^^^^^^^^^^^^^^^^^^^^^^^^^
  File "C:\Users\Nova Akademi\Desktop\oguzhan\oguzhanCrm\venv\Lib\site-packages\django\template\base.py", line 938, in render
    bit = node.render_annotated(context)
          ^^^^^^^^^^^^^^^^^^^^^^^^^^^^^^
  File "C:\Users\Nova Akademi\Desktop\oguzhan\oguzhanCrm\venv\Lib\site-packages\django\template\base.py", line 905, in render_annotated
    return self.render(context)
           ^^^^^^^^^^^^^^^^^^^^
  File "C:\Users\Nova Akademi\Desktop\oguzhan\oguzhanCrm\venv\Lib\site-packages\django\template\defaulttags.py", line 446, in render
    url = reverse(view_name, args=args, kwargs=kwargs, current_app=current_app)
          ^^^^^^^^^^^^^^^^^^^^^^^^^^^^^^^^^^^^^^^^^^^^^^^^^^^^^^^^^^^^^^^^^^^^^
  File "C:\Users\Nova Akademi\Desktop\oguzhan\oguzhanCrm\venv\Lib\site-packages\django\urls\base.py", line 86, in reverse
    return resolver._reverse_with_prefix(view, prefix, *args, **kwargs)
           ^^^^^^^^^^^^^^^^^^^^^^^^^^^^^^^^^^^^^^^^^^^^^^^^^^^^^^^^^^^^
  File "C:\Users\Nova Akademi\Desktop\oguzhan\oguzhanCrm\venv\Lib\site-packages\django\urls\resolvers.py", line 694, in _reverse_with_prefix
    raise NoReverseMatch(msg)
django.urls.exceptions.NoReverseMatch: Reverse for 'add_product' not found. 'add_product' is not a valid view function or pattern name.
ERROR 2025-05-12 20:07:48,609 basehttp "GET /products/ HTTP/1.1" 500 120303
ERROR 2025-05-14 18:21:42,428 log Internal Server Error: /products/
Traceback (most recent call last):
  File "C:\Users\Nova Akademi\Desktop\oguzhan\oguzhanCrm\venv\Lib\site-packages\django\core\handlers\exception.py", line 47, in inner
    response = get_response(request)
               ^^^^^^^^^^^^^^^^^^^^^
  File "C:\Users\Nova Akademi\Desktop\oguzhan\oguzhanCrm\venv\Lib\site-packages\django\core\handlers\base.py", line 181, in _get_response
    response = wrapped_callback(request, *callback_args, **callback_kwargs)
               ^^^^^^^^^^^^^^^^^^^^^^^^^^^^^^^^^^^^^^^^^^^^^^^^^^^^^^^^^^^^
  File "C:\Users\Nova Akademi\Desktop\oguzhan\oguzhanCrm\django_dashboard\dashboard\views\product_view.py", line 8, in product_list
    return render(request, 'products/product_list.html', {'products': products})
           ^^^^^^^^^^^^^^^^^^^^^^^^^^^^^^^^^^^^^^^^^^^^^^^^^^^^^^^^^^^^^^^^^^^^^
  File "C:\Users\Nova Akademi\Desktop\oguzhan\oguzhanCrm\venv\Lib\site-packages\django\shortcuts.py", line 19, in render
    content = loader.render_to_string(template_name, context, request, using=using)
              ^^^^^^^^^^^^^^^^^^^^^^^^^^^^^^^^^^^^^^^^^^^^^^^^^^^^^^^^^^^^^^^^^^^^^
  File "C:\Users\Nova Akademi\Desktop\oguzhan\oguzhanCrm\venv\Lib\site-packages\django\template\loader.py", line 62, in render_to_string
    return template.render(context, request)
           ^^^^^^^^^^^^^^^^^^^^^^^^^^^^^^^^^
  File "C:\Users\Nova Akademi\Desktop\oguzhan\oguzhanCrm\venv\Lib\site-packages\django\template\backends\django.py", line 61, in render
    return self.template.render(context)
           ^^^^^^^^^^^^^^^^^^^^^^^^^^^^^
  File "C:\Users\Nova Akademi\Desktop\oguzhan\oguzhanCrm\venv\Lib\site-packages\django\template\base.py", line 170, in render
    return self._render(context)
           ^^^^^^^^^^^^^^^^^^^^^
  File "C:\Users\Nova Akademi\Desktop\oguzhan\oguzhanCrm\venv\Lib\site-packages\django\template\base.py", line 162, in _render
    return self.nodelist.render(context)
           ^^^^^^^^^^^^^^^^^^^^^^^^^^^^^
  File "C:\Users\Nova Akademi\Desktop\oguzhan\oguzhanCrm\venv\Lib\site-packages\django\template\base.py", line 938, in render
    bit = node.render_annotated(context)
          ^^^^^^^^^^^^^^^^^^^^^^^^^^^^^^
  File "C:\Users\Nova Akademi\Desktop\oguzhan\oguzhanCrm\venv\Lib\site-packages\django\template\base.py", line 905, in render_annotated
    return self.render(context)
           ^^^^^^^^^^^^^^^^^^^^
  File "C:\Users\Nova Akademi\Desktop\oguzhan\oguzhanCrm\venv\Lib\site-packages\django\template\defaulttags.py", line 211, in render
    nodelist.append(node.render_annotated(context))
                    ^^^^^^^^^^^^^^^^^^^^^^^^^^^^^^
  File "C:\Users\Nova Akademi\Desktop\oguzhan\oguzhanCrm\venv\Lib\site-packages\django\template\base.py", line 905, in render_annotated
    return self.render(context)
           ^^^^^^^^^^^^^^^^^^^^
  File "C:\Users\Nova Akademi\Desktop\oguzhan\oguzhanCrm\venv\Lib\site-packages\django\template\defaulttags.py", line 446, in render
    url = reverse(view_name, args=args, kwargs=kwargs, current_app=current_app)
          ^^^^^^^^^^^^^^^^^^^^^^^^^^^^^^^^^^^^^^^^^^^^^^^^^^^^^^^^^^^^^^^^^^^^^
  File "C:\Users\Nova Akademi\Desktop\oguzhan\oguzhanCrm\venv\Lib\site-packages\django\urls\base.py", line 86, in reverse
    return resolver._reverse_with_prefix(view, prefix, *args, **kwargs)
           ^^^^^^^^^^^^^^^^^^^^^^^^^^^^^^^^^^^^^^^^^^^^^^^^^^^^^^^^^^^^
  File "C:\Users\Nova Akademi\Desktop\oguzhan\oguzhanCrm\venv\Lib\site-packages\django\urls\resolvers.py", line 694, in _reverse_with_prefix
    raise NoReverseMatch(msg)
django.urls.exceptions.NoReverseMatch: Reverse for 'delete_product' not found. 'delete_product' is not a valid view function or pattern name.
ERROR 2025-05-14 18:21:42,443 basehttp "GET /products/ HTTP/1.1" 500 138356
ERROR 2025-05-14 18:21:49,130 log Internal Server Error: /products/
Traceback (most recent call last):
  File "C:\Users\Nova Akademi\Desktop\oguzhan\oguzhanCrm\venv\Lib\site-packages\django\core\handlers\exception.py", line 47, in inner
    response = get_response(request)
               ^^^^^^^^^^^^^^^^^^^^^
  File "C:\Users\Nova Akademi\Desktop\oguzhan\oguzhanCrm\venv\Lib\site-packages\django\core\handlers\base.py", line 181, in _get_response
    response = wrapped_callback(request, *callback_args, **callback_kwargs)
               ^^^^^^^^^^^^^^^^^^^^^^^^^^^^^^^^^^^^^^^^^^^^^^^^^^^^^^^^^^^^
  File "C:\Users\Nova Akademi\Desktop\oguzhan\oguzhanCrm\django_dashboard\dashboard\views\product_view.py", line 8, in product_list
    return render(request, 'products/product_list.html', {'products': products})
           ^^^^^^^^^^^^^^^^^^^^^^^^^^^^^^^^^^^^^^^^^^^^^^^^^^^^^^^^^^^^^^^^^^^^^
  File "C:\Users\Nova Akademi\Desktop\oguzhan\oguzhanCrm\venv\Lib\site-packages\django\shortcuts.py", line 19, in render
    content = loader.render_to_string(template_name, context, request, using=using)
              ^^^^^^^^^^^^^^^^^^^^^^^^^^^^^^^^^^^^^^^^^^^^^^^^^^^^^^^^^^^^^^^^^^^^^
  File "C:\Users\Nova Akademi\Desktop\oguzhan\oguzhanCrm\venv\Lib\site-packages\django\template\loader.py", line 62, in render_to_string
    return template.render(context, request)
           ^^^^^^^^^^^^^^^^^^^^^^^^^^^^^^^^^
  File "C:\Users\Nova Akademi\Desktop\oguzhan\oguzhanCrm\venv\Lib\site-packages\django\template\backends\django.py", line 61, in render
    return self.template.render(context)
           ^^^^^^^^^^^^^^^^^^^^^^^^^^^^^
  File "C:\Users\Nova Akademi\Desktop\oguzhan\oguzhanCrm\venv\Lib\site-packages\django\template\base.py", line 170, in render
    return self._render(context)
           ^^^^^^^^^^^^^^^^^^^^^
  File "C:\Users\Nova Akademi\Desktop\oguzhan\oguzhanCrm\venv\Lib\site-packages\django\template\base.py", line 162, in _render
    return self.nodelist.render(context)
           ^^^^^^^^^^^^^^^^^^^^^^^^^^^^^
  File "C:\Users\Nova Akademi\Desktop\oguzhan\oguzhanCrm\venv\Lib\site-packages\django\template\base.py", line 938, in render
    bit = node.render_annotated(context)
          ^^^^^^^^^^^^^^^^^^^^^^^^^^^^^^
  File "C:\Users\Nova Akademi\Desktop\oguzhan\oguzhanCrm\venv\Lib\site-packages\django\template\base.py", line 905, in render_annotated
    return self.render(context)
           ^^^^^^^^^^^^^^^^^^^^
  File "C:\Users\Nova Akademi\Desktop\oguzhan\oguzhanCrm\venv\Lib\site-packages\django\template\defaulttags.py", line 211, in render
    nodelist.append(node.render_annotated(context))
                    ^^^^^^^^^^^^^^^^^^^^^^^^^^^^^^
  File "C:\Users\Nova Akademi\Desktop\oguzhan\oguzhanCrm\venv\Lib\site-packages\django\template\base.py", line 905, in render_annotated
    return self.render(context)
           ^^^^^^^^^^^^^^^^^^^^
  File "C:\Users\Nova Akademi\Desktop\oguzhan\oguzhanCrm\venv\Lib\site-packages\django\template\defaulttags.py", line 446, in render
    url = reverse(view_name, args=args, kwargs=kwargs, current_app=current_app)
          ^^^^^^^^^^^^^^^^^^^^^^^^^^^^^^^^^^^^^^^^^^^^^^^^^^^^^^^^^^^^^^^^^^^^^
  File "C:\Users\Nova Akademi\Desktop\oguzhan\oguzhanCrm\venv\Lib\site-packages\django\urls\base.py", line 86, in reverse
    return resolver._reverse_with_prefix(view, prefix, *args, **kwargs)
           ^^^^^^^^^^^^^^^^^^^^^^^^^^^^^^^^^^^^^^^^^^^^^^^^^^^^^^^^^^^^
  File "C:\Users\Nova Akademi\Desktop\oguzhan\oguzhanCrm\venv\Lib\site-packages\django\urls\resolvers.py", line 694, in _reverse_with_prefix
    raise NoReverseMatch(msg)
django.urls.exceptions.NoReverseMatch: Reverse for 'delete_product' not found. 'delete_product' is not a valid view function or pattern name.
ERROR 2025-05-14 18:21:49,140 basehttp "GET /products/ HTTP/1.1" 500 138356
ERROR 2025-05-14 18:30:00,067 log Internal Server Error: /products/
Traceback (most recent call last):
  File "C:\Users\Nova Akademi\Desktop\oguzhan\oguzhanCrm\venv\Lib\site-packages\django\core\handlers\exception.py", line 47, in inner
    response = get_response(request)
               ^^^^^^^^^^^^^^^^^^^^^
  File "C:\Users\Nova Akademi\Desktop\oguzhan\oguzhanCrm\venv\Lib\site-packages\django\core\handlers\base.py", line 181, in _get_response
    response = wrapped_callback(request, *callback_args, **callback_kwargs)
               ^^^^^^^^^^^^^^^^^^^^^^^^^^^^^^^^^^^^^^^^^^^^^^^^^^^^^^^^^^^^
  File "C:\Users\Nova Akademi\Desktop\oguzhan\oguzhanCrm\django_dashboard\dashboard\views\product_view.py", line 8, in product_list
    return render(request, 'products/product_list.html', {'products': products})
           ^^^^^^^^^^^^^^^^^^^^^^^^^^^^^^^^^^^^^^^^^^^^^^^^^^^^^^^^^^^^^^^^^^^^^
  File "C:\Users\Nova Akademi\Desktop\oguzhan\oguzhanCrm\venv\Lib\site-packages\django\shortcuts.py", line 19, in render
    content = loader.render_to_string(template_name, context, request, using=using)
              ^^^^^^^^^^^^^^^^^^^^^^^^^^^^^^^^^^^^^^^^^^^^^^^^^^^^^^^^^^^^^^^^^^^^^
  File "C:\Users\Nova Akademi\Desktop\oguzhan\oguzhanCrm\venv\Lib\site-packages\django\template\loader.py", line 62, in render_to_string
    return template.render(context, request)
           ^^^^^^^^^^^^^^^^^^^^^^^^^^^^^^^^^
  File "C:\Users\Nova Akademi\Desktop\oguzhan\oguzhanCrm\venv\Lib\site-packages\django\template\backends\django.py", line 61, in render
    return self.template.render(context)
           ^^^^^^^^^^^^^^^^^^^^^^^^^^^^^
  File "C:\Users\Nova Akademi\Desktop\oguzhan\oguzhanCrm\venv\Lib\site-packages\django\template\base.py", line 170, in render
    return self._render(context)
           ^^^^^^^^^^^^^^^^^^^^^
  File "C:\Users\Nova Akademi\Desktop\oguzhan\oguzhanCrm\venv\Lib\site-packages\django\template\base.py", line 162, in _render
    return self.nodelist.render(context)
           ^^^^^^^^^^^^^^^^^^^^^^^^^^^^^
  File "C:\Users\Nova Akademi\Desktop\oguzhan\oguzhanCrm\venv\Lib\site-packages\django\template\base.py", line 938, in render
    bit = node.render_annotated(context)
          ^^^^^^^^^^^^^^^^^^^^^^^^^^^^^^
  File "C:\Users\Nova Akademi\Desktop\oguzhan\oguzhanCrm\venv\Lib\site-packages\django\template\base.py", line 905, in render_annotated
    return self.render(context)
           ^^^^^^^^^^^^^^^^^^^^
  File "C:\Users\Nova Akademi\Desktop\oguzhan\oguzhanCrm\venv\Lib\site-packages\django\template\defaulttags.py", line 211, in render
    nodelist.append(node.render_annotated(context))
                    ^^^^^^^^^^^^^^^^^^^^^^^^^^^^^^
  File "C:\Users\Nova Akademi\Desktop\oguzhan\oguzhanCrm\venv\Lib\site-packages\django\template\base.py", line 905, in render_annotated
    return self.render(context)
           ^^^^^^^^^^^^^^^^^^^^
  File "C:\Users\Nova Akademi\Desktop\oguzhan\oguzhanCrm\venv\Lib\site-packages\django\template\defaulttags.py", line 446, in render
    url = reverse(view_name, args=args, kwargs=kwargs, current_app=current_app)
          ^^^^^^^^^^^^^^^^^^^^^^^^^^^^^^^^^^^^^^^^^^^^^^^^^^^^^^^^^^^^^^^^^^^^^
  File "C:\Users\Nova Akademi\Desktop\oguzhan\oguzhanCrm\venv\Lib\site-packages\django\urls\base.py", line 86, in reverse
    return resolver._reverse_with_prefix(view, prefix, *args, **kwargs)
           ^^^^^^^^^^^^^^^^^^^^^^^^^^^^^^^^^^^^^^^^^^^^^^^^^^^^^^^^^^^^
  File "C:\Users\Nova Akademi\Desktop\oguzhan\oguzhanCrm\venv\Lib\site-packages\django\urls\resolvers.py", line 694, in _reverse_with_prefix
    raise NoReverseMatch(msg)
django.urls.exceptions.NoReverseMatch: Reverse for 'delete_product' not found. 'delete_product' is not a valid view function or pattern name.
ERROR 2025-05-14 18:30:00,084 basehttp "GET /products/ HTTP/1.1" 500 138219
ERROR 2025-05-14 18:31:13,843 log Internal Server Error: /products/
Traceback (most recent call last):
  File "C:\Users\Nova Akademi\Desktop\oguzhan\oguzhanCrm\venv\Lib\site-packages\django\core\handlers\exception.py", line 47, in inner
    response = get_response(request)
               ^^^^^^^^^^^^^^^^^^^^^
  File "C:\Users\Nova Akademi\Desktop\oguzhan\oguzhanCrm\venv\Lib\site-packages\django\core\handlers\base.py", line 181, in _get_response
    response = wrapped_callback(request, *callback_args, **callback_kwargs)
               ^^^^^^^^^^^^^^^^^^^^^^^^^^^^^^^^^^^^^^^^^^^^^^^^^^^^^^^^^^^^
  File "C:\Users\Nova Akademi\Desktop\oguzhan\oguzhanCrm\django_dashboard\dashboard\views\product_view.py", line 8, in product_list
    return render(request, 'products/product_list.html', {'products': products})
           ^^^^^^^^^^^^^^^^^^^^^^^^^^^^^^^^^^^^^^^^^^^^^^^^^^^^^^^^^^^^^^^^^^^^^
  File "C:\Users\Nova Akademi\Desktop\oguzhan\oguzhanCrm\venv\Lib\site-packages\django\shortcuts.py", line 19, in render
    content = loader.render_to_string(template_name, context, request, using=using)
              ^^^^^^^^^^^^^^^^^^^^^^^^^^^^^^^^^^^^^^^^^^^^^^^^^^^^^^^^^^^^^^^^^^^^^
  File "C:\Users\Nova Akademi\Desktop\oguzhan\oguzhanCrm\venv\Lib\site-packages\django\template\loader.py", line 62, in render_to_string
    return template.render(context, request)
           ^^^^^^^^^^^^^^^^^^^^^^^^^^^^^^^^^
  File "C:\Users\Nova Akademi\Desktop\oguzhan\oguzhanCrm\venv\Lib\site-packages\django\template\backends\django.py", line 61, in render
    return self.template.render(context)
           ^^^^^^^^^^^^^^^^^^^^^^^^^^^^^
  File "C:\Users\Nova Akademi\Desktop\oguzhan\oguzhanCrm\venv\Lib\site-packages\django\template\base.py", line 170, in render
    return self._render(context)
           ^^^^^^^^^^^^^^^^^^^^^
  File "C:\Users\Nova Akademi\Desktop\oguzhan\oguzhanCrm\venv\Lib\site-packages\django\template\base.py", line 162, in _render
    return self.nodelist.render(context)
           ^^^^^^^^^^^^^^^^^^^^^^^^^^^^^
  File "C:\Users\Nova Akademi\Desktop\oguzhan\oguzhanCrm\venv\Lib\site-packages\django\template\base.py", line 938, in render
    bit = node.render_annotated(context)
          ^^^^^^^^^^^^^^^^^^^^^^^^^^^^^^
  File "C:\Users\Nova Akademi\Desktop\oguzhan\oguzhanCrm\venv\Lib\site-packages\django\template\base.py", line 905, in render_annotated
    return self.render(context)
           ^^^^^^^^^^^^^^^^^^^^
  File "C:\Users\Nova Akademi\Desktop\oguzhan\oguzhanCrm\venv\Lib\site-packages\django\template\defaulttags.py", line 211, in render
    nodelist.append(node.render_annotated(context))
                    ^^^^^^^^^^^^^^^^^^^^^^^^^^^^^^
  File "C:\Users\Nova Akademi\Desktop\oguzhan\oguzhanCrm\venv\Lib\site-packages\django\template\base.py", line 905, in render_annotated
    return self.render(context)
           ^^^^^^^^^^^^^^^^^^^^
  File "C:\Users\Nova Akademi\Desktop\oguzhan\oguzhanCrm\venv\Lib\site-packages\django\template\defaulttags.py", line 446, in render
    url = reverse(view_name, args=args, kwargs=kwargs, current_app=current_app)
          ^^^^^^^^^^^^^^^^^^^^^^^^^^^^^^^^^^^^^^^^^^^^^^^^^^^^^^^^^^^^^^^^^^^^^
  File "C:\Users\Nova Akademi\Desktop\oguzhan\oguzhanCrm\venv\Lib\site-packages\django\urls\base.py", line 86, in reverse
    return resolver._reverse_with_prefix(view, prefix, *args, **kwargs)
           ^^^^^^^^^^^^^^^^^^^^^^^^^^^^^^^^^^^^^^^^^^^^^^^^^^^^^^^^^^^^
  File "C:\Users\Nova Akademi\Desktop\oguzhan\oguzhanCrm\venv\Lib\site-packages\django\urls\resolvers.py", line 694, in _reverse_with_prefix
    raise NoReverseMatch(msg)
django.urls.exceptions.NoReverseMatch: Reverse for 'delete_product' not found. 'delete_product' is not a valid view function or pattern name.
ERROR 2025-05-14 18:31:13,857 basehttp "GET /products/ HTTP/1.1" 500 138356
ERROR 2025-05-14 18:53:49,711 log Internal Server Error: /profile/
Traceback (most recent call last):
  File "C:\Users\Nova Akademi\Desktop\oguzhan\oguzhanCrm\venv\Lib\site-packages\django\template\backends\django.py", line 61, in render
    return self.template.render(context)
           ^^^^^^^^^^^^^^^^^^^^^^^^^^^^^
  File "C:\Users\Nova Akademi\Desktop\oguzhan\oguzhanCrm\venv\Lib\site-packages\django\template\base.py", line 170, in render
    return self._render(context)
           ^^^^^^^^^^^^^^^^^^^^^
  File "C:\Users\Nova Akademi\Desktop\oguzhan\oguzhanCrm\venv\Lib\site-packages\django\template\base.py", line 162, in _render
    return self.nodelist.render(context)
           ^^^^^^^^^^^^^^^^^^^^^^^^^^^^^
  File "C:\Users\Nova Akademi\Desktop\oguzhan\oguzhanCrm\venv\Lib\site-packages\django\template\base.py", line 938, in render
    bit = node.render_annotated(context)
          ^^^^^^^^^^^^^^^^^^^^^^^^^^^^^^
  File "C:\Users\Nova Akademi\Desktop\oguzhan\oguzhanCrm\venv\Lib\site-packages\django\template\base.py", line 905, in render_annotated
    return self.render(context)
           ^^^^^^^^^^^^^^^^^^^^
  File "C:\Users\Nova Akademi\Desktop\oguzhan\oguzhanCrm\venv\Lib\site-packages\django\template\loader_tags.py", line 127, in render
    compiled_parent = self.get_parent(context)
                      ^^^^^^^^^^^^^^^^^^^^^^^^
  File "C:\Users\Nova Akademi\Desktop\oguzhan\oguzhanCrm\venv\Lib\site-packages\django\template\loader_tags.py", line 124, in get_parent
    return self.find_template(parent, context)
           ^^^^^^^^^^^^^^^^^^^^^^^^^^^^^^^^^^^
  File "C:\Users\Nova Akademi\Desktop\oguzhan\oguzhanCrm\venv\Lib\site-packages\django\template\loader_tags.py", line 103, in find_template
    template, origin = context.template.engine.find_template(
                       ^^^^^^^^^^^^^^^^^^^^^^^^^^^^^^^^^^^^^^
  File "C:\Users\Nova Akademi\Desktop\oguzhan\oguzhanCrm\venv\Lib\site-packages\django\template\engine.py", line 129, in find_template
    raise TemplateDoesNotExist(name, tried=tried)
django.template.exceptions.TemplateDoesNotExist: base_generic.html

The above exception was the direct cause of the following exception:

Traceback (most recent call last):
  File "C:\Users\Nova Akademi\Desktop\oguzhan\oguzhanCrm\venv\Lib\site-packages\django\core\handlers\exception.py", line 47, in inner
    response = get_response(request)
               ^^^^^^^^^^^^^^^^^^^^^
  File "C:\Users\Nova Akademi\Desktop\oguzhan\oguzhanCrm\venv\Lib\site-packages\django\core\handlers\base.py", line 181, in _get_response
    response = wrapped_callback(request, *callback_args, **callback_kwargs)
               ^^^^^^^^^^^^^^^^^^^^^^^^^^^^^^^^^^^^^^^^^^^^^^^^^^^^^^^^^^^^
  File "C:\Users\Nova Akademi\Desktop\oguzhan\oguzhanCrm\venv\Lib\site-packages\django\contrib\auth\decorators.py", line 21, in _wrapped_view
    return view_func(request, *args, **kwargs)
           ^^^^^^^^^^^^^^^^^^^^^^^^^^^^^^^^^^^
  File "C:\Users\Nova Akademi\Desktop\oguzhan\oguzhanCrm\django_dashboard\dashboard\views\user_views.py", line 17, in profile_view
    return render(request, 'auth/profile.html', {'user': user})
           ^^^^^^^^^^^^^^^^^^^^^^^^^^^^^^^^^^^^^^^^^^^^^^^^^^^^
  File "C:\Users\Nova Akademi\Desktop\oguzhan\oguzhanCrm\venv\Lib\site-packages\django\shortcuts.py", line 19, in render
    content = loader.render_to_string(template_name, context, request, using=using)
              ^^^^^^^^^^^^^^^^^^^^^^^^^^^^^^^^^^^^^^^^^^^^^^^^^^^^^^^^^^^^^^^^^^^^^
  File "C:\Users\Nova Akademi\Desktop\oguzhan\oguzhanCrm\venv\Lib\site-packages\django\template\loader.py", line 62, in render_to_string
    return template.render(context, request)
           ^^^^^^^^^^^^^^^^^^^^^^^^^^^^^^^^^
  File "C:\Users\Nova Akademi\Desktop\oguzhan\oguzhanCrm\venv\Lib\site-packages\django\template\backends\django.py", line 63, in render
    reraise(exc, self.backend)
  File "C:\Users\Nova Akademi\Desktop\oguzhan\oguzhanCrm\venv\Lib\site-packages\django\template\backends\django.py", line 84, in reraise
    raise new from exc
django.template.exceptions.TemplateDoesNotExist: base_generic.html
ERROR 2025-05-14 18:53:49,717 basehttp "GET /profile/ HTTP/1.1" 500 135193
ERROR 2025-05-14 19:40:12,492 log Internal Server Error: /profile/
Traceback (most recent call last):
  File "C:\Users\Nova Akademi\Desktop\oguzhan\oguzhanCrm\venv\Lib\site-packages\django\core\handlers\exception.py", line 47, in inner
    response = get_response(request)
               ^^^^^^^^^^^^^^^^^^^^^
  File "C:\Users\Nova Akademi\Desktop\oguzhan\oguzhanCrm\venv\Lib\site-packages\django\core\handlers\base.py", line 181, in _get_response
    response = wrapped_callback(request, *callback_args, **callback_kwargs)
               ^^^^^^^^^^^^^^^^^^^^^^^^^^^^^^^^^^^^^^^^^^^^^^^^^^^^^^^^^^^^
  File "C:\Users\Nova Akademi\Desktop\oguzhan\oguzhanCrm\venv\Lib\site-packages\django\contrib\auth\decorators.py", line 21, in _wrapped_view
    return view_func(request, *args, **kwargs)
           ^^^^^^^^^^^^^^^^^^^^^^^^^^^^^^^^^^^
  File "C:\Users\Nova Akademi\Desktop\oguzhan\oguzhanCrm\django_dashboard\dashboard\views\user_views.py", line 17, in profile_view
    return render(request, 'auth/profile.html', {'user': user})
           ^^^^^^^^^^^^^^^^^^^^^^^^^^^^^^^^^^^^^^^^^^^^^^^^^^^^
  File "C:\Users\Nova Akademi\Desktop\oguzhan\oguzhanCrm\venv\Lib\site-packages\django\shortcuts.py", line 19, in render
    content = loader.render_to_string(template_name, context, request, using=using)
              ^^^^^^^^^^^^^^^^^^^^^^^^^^^^^^^^^^^^^^^^^^^^^^^^^^^^^^^^^^^^^^^^^^^^^
  File "C:\Users\Nova Akademi\Desktop\oguzhan\oguzhanCrm\venv\Lib\site-packages\django\template\loader.py", line 61, in render_to_string
    template = get_template(template_name, using=using)
               ^^^^^^^^^^^^^^^^^^^^^^^^^^^^^^^^^^^^^^^^
  File "C:\Users\Nova Akademi\Desktop\oguzhan\oguzhanCrm\venv\Lib\site-packages\django\template\loader.py", line 15, in get_template
    return engine.get_template(template_name)
           ^^^^^^^^^^^^^^^^^^^^^^^^^^^^^^^^^^
  File "C:\Users\Nova Akademi\Desktop\oguzhan\oguzhanCrm\venv\Lib\site-packages\django\template\backends\django.py", line 34, in get_template
    return Template(self.engine.get_template(template_name), self)
                    ^^^^^^^^^^^^^^^^^^^^^^^^^^^^^^^^^^^^^^^
  File "C:\Users\Nova Akademi\Desktop\oguzhan\oguzhanCrm\venv\Lib\site-packages\django\template\engine.py", line 143, in get_template
    template, origin = self.find_template(template_name)
                       ^^^^^^^^^^^^^^^^^^^^^^^^^^^^^^^^^
  File "C:\Users\Nova Akademi\Desktop\oguzhan\oguzhanCrm\venv\Lib\site-packages\django\template\engine.py", line 125, in find_template
    template = loader.get_template(name, skip=skip)
               ^^^^^^^^^^^^^^^^^^^^^^^^^^^^^^^^^^^^
  File "C:\Users\Nova Akademi\Desktop\oguzhan\oguzhanCrm\venv\Lib\site-packages\django\template\loaders\base.py", line 29, in get_template
    return Template(
           ^^^^^^^^^
  File "C:\Users\Nova Akademi\Desktop\oguzhan\oguzhanCrm\venv\Lib\site-packages\django\template\base.py", line 155, in __init__
    self.nodelist = self.compile_nodelist()
                    ^^^^^^^^^^^^^^^^^^^^^^^
  File "C:\Users\Nova Akademi\Desktop\oguzhan\oguzhanCrm\venv\Lib\site-packages\django\template\base.py", line 193, in compile_nodelist
    return parser.parse()
           ^^^^^^^^^^^^^^
  File "C:\Users\Nova Akademi\Desktop\oguzhan\oguzhanCrm\venv\Lib\site-packages\django\template\base.py", line 478, in parse
    raise self.error(token, e)
  File "C:\Users\Nova Akademi\Desktop\oguzhan\oguzhanCrm\venv\Lib\site-packages\django\template\base.py", line 476, in parse
    compiled_result = compile_func(self, token)
                      ^^^^^^^^^^^^^^^^^^^^^^^^^
  File "C:\Users\Nova Akademi\Desktop\oguzhan\oguzhanCrm\venv\Lib\site-packages\django\template\loader_tags.py", line 278, in do_extends
    nodelist = parser.parse()
               ^^^^^^^^^^^^^^
  File "C:\Users\Nova Akademi\Desktop\oguzhan\oguzhanCrm\venv\Lib\site-packages\django\template\base.py", line 478, in parse
    raise self.error(token, e)
  File "C:\Users\Nova Akademi\Desktop\oguzhan\oguzhanCrm\venv\Lib\site-packages\django\template\base.py", line 476, in parse
    compiled_result = compile_func(self, token)
                      ^^^^^^^^^^^^^^^^^^^^^^^^^
  File "C:\Users\Nova Akademi\Desktop\oguzhan\oguzhanCrm\venv\Lib\site-packages\django\template\loader_tags.py", line 216, in do_block
    nodelist = parser.parse(('endblock',))
               ^^^^^^^^^^^^^^^^^^^^^^^^^^^
  File "C:\Users\Nova Akademi\Desktop\oguzhan\oguzhanCrm\venv\Lib\site-packages\django\template\base.py", line 483, in parse
    self.unclosed_block_tag(parse_until)
  File "C:\Users\Nova Akademi\Desktop\oguzhan\oguzhanCrm\venv\Lib\site-packages\django\template\base.py", line 544, in unclosed_block_tag
    raise self.error(token, msg)
django.template.exceptions.TemplateSyntaxError: Unclosed tag on line 5: 'block'. Looking for one of: endblock.
ERROR 2025-05-14 19:40:12,507 basehttp "GET /profile/ HTTP/1.1" 500 164923
ERROR 2025-05-14 19:40:13,556 log Internal Server Error: /profile/
Traceback (most recent call last):
  File "C:\Users\Nova Akademi\Desktop\oguzhan\oguzhanCrm\venv\Lib\site-packages\django\core\handlers\exception.py", line 47, in inner
    response = get_response(request)
               ^^^^^^^^^^^^^^^^^^^^^
  File "C:\Users\Nova Akademi\Desktop\oguzhan\oguzhanCrm\venv\Lib\site-packages\django\core\handlers\base.py", line 181, in _get_response
    response = wrapped_callback(request, *callback_args, **callback_kwargs)
               ^^^^^^^^^^^^^^^^^^^^^^^^^^^^^^^^^^^^^^^^^^^^^^^^^^^^^^^^^^^^
  File "C:\Users\Nova Akademi\Desktop\oguzhan\oguzhanCrm\venv\Lib\site-packages\django\contrib\auth\decorators.py", line 21, in _wrapped_view
    return view_func(request, *args, **kwargs)
           ^^^^^^^^^^^^^^^^^^^^^^^^^^^^^^^^^^^
  File "C:\Users\Nova Akademi\Desktop\oguzhan\oguzhanCrm\django_dashboard\dashboard\views\user_views.py", line 17, in profile_view
    return render(request, 'auth/profile.html', {'user': user})
           ^^^^^^^^^^^^^^^^^^^^^^^^^^^^^^^^^^^^^^^^^^^^^^^^^^^^
  File "C:\Users\Nova Akademi\Desktop\oguzhan\oguzhanCrm\venv\Lib\site-packages\django\shortcuts.py", line 19, in render
    content = loader.render_to_string(template_name, context, request, using=using)
              ^^^^^^^^^^^^^^^^^^^^^^^^^^^^^^^^^^^^^^^^^^^^^^^^^^^^^^^^^^^^^^^^^^^^^
  File "C:\Users\Nova Akademi\Desktop\oguzhan\oguzhanCrm\venv\Lib\site-packages\django\template\loader.py", line 61, in render_to_string
    template = get_template(template_name, using=using)
               ^^^^^^^^^^^^^^^^^^^^^^^^^^^^^^^^^^^^^^^^
  File "C:\Users\Nova Akademi\Desktop\oguzhan\oguzhanCrm\venv\Lib\site-packages\django\template\loader.py", line 15, in get_template
    return engine.get_template(template_name)
           ^^^^^^^^^^^^^^^^^^^^^^^^^^^^^^^^^^
  File "C:\Users\Nova Akademi\Desktop\oguzhan\oguzhanCrm\venv\Lib\site-packages\django\template\backends\django.py", line 34, in get_template
    return Template(self.engine.get_template(template_name), self)
                    ^^^^^^^^^^^^^^^^^^^^^^^^^^^^^^^^^^^^^^^
  File "C:\Users\Nova Akademi\Desktop\oguzhan\oguzhanCrm\venv\Lib\site-packages\django\template\engine.py", line 143, in get_template
    template, origin = self.find_template(template_name)
                       ^^^^^^^^^^^^^^^^^^^^^^^^^^^^^^^^^
  File "C:\Users\Nova Akademi\Desktop\oguzhan\oguzhanCrm\venv\Lib\site-packages\django\template\engine.py", line 125, in find_template
    template = loader.get_template(name, skip=skip)
               ^^^^^^^^^^^^^^^^^^^^^^^^^^^^^^^^^^^^
  File "C:\Users\Nova Akademi\Desktop\oguzhan\oguzhanCrm\venv\Lib\site-packages\django\template\loaders\base.py", line 29, in get_template
    return Template(
           ^^^^^^^^^
  File "C:\Users\Nova Akademi\Desktop\oguzhan\oguzhanCrm\venv\Lib\site-packages\django\template\base.py", line 155, in __init__
    self.nodelist = self.compile_nodelist()
                    ^^^^^^^^^^^^^^^^^^^^^^^
  File "C:\Users\Nova Akademi\Desktop\oguzhan\oguzhanCrm\venv\Lib\site-packages\django\template\base.py", line 193, in compile_nodelist
    return parser.parse()
           ^^^^^^^^^^^^^^
  File "C:\Users\Nova Akademi\Desktop\oguzhan\oguzhanCrm\venv\Lib\site-packages\django\template\base.py", line 478, in parse
    raise self.error(token, e)
  File "C:\Users\Nova Akademi\Desktop\oguzhan\oguzhanCrm\venv\Lib\site-packages\django\template\base.py", line 476, in parse
    compiled_result = compile_func(self, token)
                      ^^^^^^^^^^^^^^^^^^^^^^^^^
  File "C:\Users\Nova Akademi\Desktop\oguzhan\oguzhanCrm\venv\Lib\site-packages\django\template\loader_tags.py", line 278, in do_extends
    nodelist = parser.parse()
               ^^^^^^^^^^^^^^
  File "C:\Users\Nova Akademi\Desktop\oguzhan\oguzhanCrm\venv\Lib\site-packages\django\template\base.py", line 478, in parse
    raise self.error(token, e)
  File "C:\Users\Nova Akademi\Desktop\oguzhan\oguzhanCrm\venv\Lib\site-packages\django\template\base.py", line 476, in parse
    compiled_result = compile_func(self, token)
                      ^^^^^^^^^^^^^^^^^^^^^^^^^
  File "C:\Users\Nova Akademi\Desktop\oguzhan\oguzhanCrm\venv\Lib\site-packages\django\template\loader_tags.py", line 216, in do_block
    nodelist = parser.parse(('endblock',))
               ^^^^^^^^^^^^^^^^^^^^^^^^^^^
  File "C:\Users\Nova Akademi\Desktop\oguzhan\oguzhanCrm\venv\Lib\site-packages\django\template\base.py", line 483, in parse
    self.unclosed_block_tag(parse_until)
  File "C:\Users\Nova Akademi\Desktop\oguzhan\oguzhanCrm\venv\Lib\site-packages\django\template\base.py", line 544, in unclosed_block_tag
    raise self.error(token, msg)
django.template.exceptions.TemplateSyntaxError: Unclosed tag on line 5: 'block'. Looking for one of: endblock.
ERROR 2025-05-14 19:40:13,653 basehttp "GET /profile/ HTTP/1.1" 500 164923
ERROR 2025-05-14 19:40:14,169 log Internal Server Error: /profile/
Traceback (most recent call last):
  File "C:\Users\Nova Akademi\Desktop\oguzhan\oguzhanCrm\venv\Lib\site-packages\django\core\handlers\exception.py", line 47, in inner
    response = get_response(request)
               ^^^^^^^^^^^^^^^^^^^^^
  File "C:\Users\Nova Akademi\Desktop\oguzhan\oguzhanCrm\venv\Lib\site-packages\django\core\handlers\base.py", line 181, in _get_response
    response = wrapped_callback(request, *callback_args, **callback_kwargs)
               ^^^^^^^^^^^^^^^^^^^^^^^^^^^^^^^^^^^^^^^^^^^^^^^^^^^^^^^^^^^^
  File "C:\Users\Nova Akademi\Desktop\oguzhan\oguzhanCrm\venv\Lib\site-packages\django\contrib\auth\decorators.py", line 21, in _wrapped_view
    return view_func(request, *args, **kwargs)
           ^^^^^^^^^^^^^^^^^^^^^^^^^^^^^^^^^^^
  File "C:\Users\Nova Akademi\Desktop\oguzhan\oguzhanCrm\django_dashboard\dashboard\views\user_views.py", line 17, in profile_view
    return render(request, 'auth/profile.html', {'user': user})
           ^^^^^^^^^^^^^^^^^^^^^^^^^^^^^^^^^^^^^^^^^^^^^^^^^^^^
  File "C:\Users\Nova Akademi\Desktop\oguzhan\oguzhanCrm\venv\Lib\site-packages\django\shortcuts.py", line 19, in render
    content = loader.render_to_string(template_name, context, request, using=using)
              ^^^^^^^^^^^^^^^^^^^^^^^^^^^^^^^^^^^^^^^^^^^^^^^^^^^^^^^^^^^^^^^^^^^^^
  File "C:\Users\Nova Akademi\Desktop\oguzhan\oguzhanCrm\venv\Lib\site-packages\django\template\loader.py", line 61, in render_to_string
    template = get_template(template_name, using=using)
               ^^^^^^^^^^^^^^^^^^^^^^^^^^^^^^^^^^^^^^^^
  File "C:\Users\Nova Akademi\Desktop\oguzhan\oguzhanCrm\venv\Lib\site-packages\django\template\loader.py", line 15, in get_template
    return engine.get_template(template_name)
           ^^^^^^^^^^^^^^^^^^^^^^^^^^^^^^^^^^
  File "C:\Users\Nova Akademi\Desktop\oguzhan\oguzhanCrm\venv\Lib\site-packages\django\template\backends\django.py", line 34, in get_template
    return Template(self.engine.get_template(template_name), self)
                    ^^^^^^^^^^^^^^^^^^^^^^^^^^^^^^^^^^^^^^^
  File "C:\Users\Nova Akademi\Desktop\oguzhan\oguzhanCrm\venv\Lib\site-packages\django\template\engine.py", line 143, in get_template
    template, origin = self.find_template(template_name)
                       ^^^^^^^^^^^^^^^^^^^^^^^^^^^^^^^^^
  File "C:\Users\Nova Akademi\Desktop\oguzhan\oguzhanCrm\venv\Lib\site-packages\django\template\engine.py", line 125, in find_template
    template = loader.get_template(name, skip=skip)
               ^^^^^^^^^^^^^^^^^^^^^^^^^^^^^^^^^^^^
  File "C:\Users\Nova Akademi\Desktop\oguzhan\oguzhanCrm\venv\Lib\site-packages\django\template\loaders\base.py", line 29, in get_template
    return Template(
           ^^^^^^^^^
  File "C:\Users\Nova Akademi\Desktop\oguzhan\oguzhanCrm\venv\Lib\site-packages\django\template\base.py", line 155, in __init__
    self.nodelist = self.compile_nodelist()
                    ^^^^^^^^^^^^^^^^^^^^^^^
  File "C:\Users\Nova Akademi\Desktop\oguzhan\oguzhanCrm\venv\Lib\site-packages\django\template\base.py", line 193, in compile_nodelist
    return parser.parse()
           ^^^^^^^^^^^^^^
  File "C:\Users\Nova Akademi\Desktop\oguzhan\oguzhanCrm\venv\Lib\site-packages\django\template\base.py", line 478, in parse
    raise self.error(token, e)
  File "C:\Users\Nova Akademi\Desktop\oguzhan\oguzhanCrm\venv\Lib\site-packages\django\template\base.py", line 476, in parse
    compiled_result = compile_func(self, token)
                      ^^^^^^^^^^^^^^^^^^^^^^^^^
  File "C:\Users\Nova Akademi\Desktop\oguzhan\oguzhanCrm\venv\Lib\site-packages\django\template\loader_tags.py", line 278, in do_extends
    nodelist = parser.parse()
               ^^^^^^^^^^^^^^
  File "C:\Users\Nova Akademi\Desktop\oguzhan\oguzhanCrm\venv\Lib\site-packages\django\template\base.py", line 478, in parse
    raise self.error(token, e)
  File "C:\Users\Nova Akademi\Desktop\oguzhan\oguzhanCrm\venv\Lib\site-packages\django\template\base.py", line 476, in parse
    compiled_result = compile_func(self, token)
                      ^^^^^^^^^^^^^^^^^^^^^^^^^
  File "C:\Users\Nova Akademi\Desktop\oguzhan\oguzhanCrm\venv\Lib\site-packages\django\template\loader_tags.py", line 216, in do_block
    nodelist = parser.parse(('endblock',))
               ^^^^^^^^^^^^^^^^^^^^^^^^^^^
  File "C:\Users\Nova Akademi\Desktop\oguzhan\oguzhanCrm\venv\Lib\site-packages\django\template\base.py", line 483, in parse
    self.unclosed_block_tag(parse_until)
  File "C:\Users\Nova Akademi\Desktop\oguzhan\oguzhanCrm\venv\Lib\site-packages\django\template\base.py", line 544, in unclosed_block_tag
    raise self.error(token, msg)
django.template.exceptions.TemplateSyntaxError: Unclosed tag on line 5: 'block'. Looking for one of: endblock.
ERROR 2025-05-14 19:40:14,178 basehttp "GET /profile/ HTTP/1.1" 500 164923
ERROR 2025-05-14 19:53:40,958 log Internal Server Error: /profile/change-password/
Traceback (most recent call last):
  File "C:\Users\Nova Akademi\Desktop\oguzhan\oguzhanCrm\venv\Lib\site-packages\django\core\handlers\exception.py", line 47, in inner
    response = get_response(request)
               ^^^^^^^^^^^^^^^^^^^^^
  File "C:\Users\Nova Akademi\Desktop\oguzhan\oguzhanCrm\venv\Lib\site-packages\django\core\handlers\base.py", line 181, in _get_response
    response = wrapped_callback(request, *callback_args, **callback_kwargs)
               ^^^^^^^^^^^^^^^^^^^^^^^^^^^^^^^^^^^^^^^^^^^^^^^^^^^^^^^^^^^^
  File "C:\Users\Nova Akademi\Desktop\oguzhan\oguzhanCrm\venv\Lib\site-packages\django\contrib\auth\decorators.py", line 21, in _wrapped_view
    return view_func(request, *args, **kwargs)
           ^^^^^^^^^^^^^^^^^^^^^^^^^^^^^^^^^^^
  File "C:\Users\Nova Akademi\Desktop\oguzhan\oguzhanCrm\django_dashboard\dashboard\views\user_views.py", line 36, in change_password
    return render(request, 'profile/change_password.html', {'form': form})
           ^^^^^^^^^^^^^^^^^^^^^^^^^^^^^^^^^^^^^^^^^^^^^^^^^^^^^^^^^^^^^^^
  File "C:\Users\Nova Akademi\Desktop\oguzhan\oguzhanCrm\venv\Lib\site-packages\django\shortcuts.py", line 19, in render
    content = loader.render_to_string(template_name, context, request, using=using)
              ^^^^^^^^^^^^^^^^^^^^^^^^^^^^^^^^^^^^^^^^^^^^^^^^^^^^^^^^^^^^^^^^^^^^^
  File "C:\Users\Nova Akademi\Desktop\oguzhan\oguzhanCrm\venv\Lib\site-packages\django\template\loader.py", line 61, in render_to_string
    template = get_template(template_name, using=using)
               ^^^^^^^^^^^^^^^^^^^^^^^^^^^^^^^^^^^^^^^^
  File "C:\Users\Nova Akademi\Desktop\oguzhan\oguzhanCrm\venv\Lib\site-packages\django\template\loader.py", line 19, in get_template
    raise TemplateDoesNotExist(template_name, chain=chain)
django.template.exceptions.TemplateDoesNotExist: profile/change_password.html
ERROR 2025-05-14 19:53:40,964 basehttp "POST /profile/change-password/ HTTP/1.1" 500 91280
ERROR 2025-05-14 19:55:06,895 log Internal Server Error: /profile/change-password/
Traceback (most recent call last):
  File "C:\Users\Nova Akademi\Desktop\oguzhan\oguzhanCrm\venv\Lib\site-packages\django\core\handlers\exception.py", line 47, in inner
    response = get_response(request)
               ^^^^^^^^^^^^^^^^^^^^^
  File "C:\Users\Nova Akademi\Desktop\oguzhan\oguzhanCrm\venv\Lib\site-packages\django\core\handlers\base.py", line 181, in _get_response
    response = wrapped_callback(request, *callback_args, **callback_kwargs)
               ^^^^^^^^^^^^^^^^^^^^^^^^^^^^^^^^^^^^^^^^^^^^^^^^^^^^^^^^^^^^
  File "C:\Users\Nova Akademi\Desktop\oguzhan\oguzhanCrm\venv\Lib\site-packages\django\contrib\auth\decorators.py", line 21, in _wrapped_view
    return view_func(request, *args, **kwargs)
           ^^^^^^^^^^^^^^^^^^^^^^^^^^^^^^^^^^^
  File "C:\Users\Nova Akademi\Desktop\oguzhan\oguzhanCrm\django_dashboard\dashboard\views\user_views.py", line 34, in change_password
    return render(request, 'profile/change_password.html', {'form': form})
           ^^^^^^^^^^^^^^^^^^^^^^^^^^^^^^^^^^^^^^^^^^^^^^^^^^^^^^^^^^^^^^^
  File "C:\Users\Nova Akademi\Desktop\oguzhan\oguzhanCrm\venv\Lib\site-packages\django\shortcuts.py", line 19, in render
    content = loader.render_to_string(template_name, context, request, using=using)
              ^^^^^^^^^^^^^^^^^^^^^^^^^^^^^^^^^^^^^^^^^^^^^^^^^^^^^^^^^^^^^^^^^^^^^
  File "C:\Users\Nova Akademi\Desktop\oguzhan\oguzhanCrm\venv\Lib\site-packages\django\template\loader.py", line 61, in render_to_string
    template = get_template(template_name, using=using)
               ^^^^^^^^^^^^^^^^^^^^^^^^^^^^^^^^^^^^^^^^
  File "C:\Users\Nova Akademi\Desktop\oguzhan\oguzhanCrm\venv\Lib\site-packages\django\template\loader.py", line 19, in get_template
    raise TemplateDoesNotExist(template_name, chain=chain)
django.template.exceptions.TemplateDoesNotExist: profile/change_password.html
ERROR 2025-05-14 19:55:06,899 basehttp "POST /profile/change-password/ HTTP/1.1" 500 91306
ERROR 2025-05-14 19:56:08,190 log Internal Server Error: /profile/
Traceback (most recent call last):
  File "C:\Users\Nova Akademi\Desktop\oguzhan\oguzhanCrm\venv\Lib\site-packages\django\core\handlers\exception.py", line 47, in inner
    response = get_response(request)
               ^^^^^^^^^^^^^^^^^^^^^
  File "C:\Users\Nova Akademi\Desktop\oguzhan\oguzhanCrm\venv\Lib\site-packages\django\core\handlers\base.py", line 181, in _get_response
    response = wrapped_callback(request, *callback_args, **callback_kwargs)
               ^^^^^^^^^^^^^^^^^^^^^^^^^^^^^^^^^^^^^^^^^^^^^^^^^^^^^^^^^^^^
  File "C:\Users\Nova Akademi\Desktop\oguzhan\oguzhanCrm\venv\Lib\site-packages\django\contrib\auth\decorators.py", line 21, in _wrapped_view
    return view_func(request, *args, **kwargs)
           ^^^^^^^^^^^^^^^^^^^^^^^^^^^^^^^^^^^
  File "C:\Users\Nova Akademi\Desktop\oguzhan\oguzhanCrm\django_dashboard\dashboard\views\user_views.py", line 17, in profile_view
    return render(request, 'auth/profile.html', {'user': user})
           ^^^^^^^^^^^^^^^^^^^^^^^^^^^^^^^^^^^^^^^^^^^^^^^^^^^^
  File "C:\Users\Nova Akademi\Desktop\oguzhan\oguzhanCrm\venv\Lib\site-packages\django\shortcuts.py", line 19, in render
    content = loader.render_to_string(template_name, context, request, using=using)
              ^^^^^^^^^^^^^^^^^^^^^^^^^^^^^^^^^^^^^^^^^^^^^^^^^^^^^^^^^^^^^^^^^^^^^
  File "C:\Users\Nova Akademi\Desktop\oguzhan\oguzhanCrm\venv\Lib\site-packages\django\template\loader.py", line 61, in render_to_string
    template = get_template(template_name, using=using)
               ^^^^^^^^^^^^^^^^^^^^^^^^^^^^^^^^^^^^^^^^
  File "C:\Users\Nova Akademi\Desktop\oguzhan\oguzhanCrm\venv\Lib\site-packages\django\template\loader.py", line 19, in get_template
    raise TemplateDoesNotExist(template_name, chain=chain)
django.template.exceptions.TemplateDoesNotExist: auth/profile.html
ERROR 2025-05-14 19:56:08,192 basehttp "GET /profile/ HTTP/1.1" 500 90533
ERROR 2025-05-15 20:53:18,231 log Internal Server Error: /profile/change-password/
Traceback (most recent call last):
  File "C:\Users\ozifi\OneDrive\Masaüstü\django\venv\lib\site-packages\django\core\handlers\exception.py", line 47, in inner
    response = get_response(request)
  File "C:\Users\ozifi\OneDrive\Masaüstü\django\venv\lib\site-packages\django\core\handlers\base.py", line 181, in _get_response
    response = wrapped_callback(request, *callback_args, **callback_kwargs)
  File "C:\Users\ozifi\OneDrive\Masaüstü\django\venv\lib\site-packages\django\contrib\auth\decorators.py", line 21, in _wrapped_view
    return view_func(request, *args, **kwargs)
  File "C:\Users\ozifi\OneDrive\Masaüstü\django\django_dashboard\dashboard\views\user_views.py", line 51, in change_password
    return render(request, 'change_password.html')
  File "C:\Users\ozifi\OneDrive\Masaüstü\django\venv\lib\site-packages\django\shortcuts.py", line 19, in render
    content = loader.render_to_string(template_name, context, request, using=using)
  File "C:\Users\ozifi\OneDrive\Masaüstü\django\venv\lib\site-packages\django\template\loader.py", line 61, in render_to_string
    template = get_template(template_name, using=using)
  File "C:\Users\ozifi\OneDrive\Masaüstü\django\venv\lib\site-packages\django\template\loader.py", line 19, in get_template
    raise TemplateDoesNotExist(template_name, chain=chain)
django.template.exceptions.TemplateDoesNotExist: change_password.html
ERROR 2025-05-15 20:53:18,233 basehttp "GET /profile/change-password/ HTTP/1.1" 500 88824
ERROR 2025-05-15 21:13:49,272 log Internal Server Error: /profile/change-password/
Traceback (most recent call last):
  File "C:\Users\ozifi\OneDrive\Masaüstü\django\venv\lib\site-packages\django\contrib\sessions\backends\base.py", line 233, in _get_session
    return self._session_cache
AttributeError: 'SessionStore' object has no attribute '_session_cache'

During handling of the above exception, another exception occurred:

Traceback (most recent call last):
  File "C:\Users\ozifi\OneDrive\Masaüstü\django\venv\lib\site-packages\django\db\backends\base\base.py", line 219, in ensure_connection
    self.connect()
  File "C:\Users\ozifi\OneDrive\Masaüstü\django\venv\lib\site-packages\django\utils\asyncio.py", line 26, in inner
    return func(*args, **kwargs)
  File "C:\Users\ozifi\OneDrive\Masaüstü\django\venv\lib\site-packages\django\db\backends\base\base.py", line 200, in connect
    self.connection = self.get_new_connection(conn_params)
  File "C:\Users\ozifi\OneDrive\Masaüstü\django\venv\lib\site-packages\django\utils\asyncio.py", line 26, in inner
    return func(*args, **kwargs)
  File "C:\Users\ozifi\OneDrive\Masaüstü\django\venv\lib\site-packages\django\db\backends\mysql\base.py", line 234, in get_new_connection
    connection = Database.connect(**conn_params)
  File "C:\Users\ozifi\OneDrive\Masaüstü\django\venv\lib\site-packages\MySQLdb\__init__.py", line 121, in Connect
    return Connection(*args, **kwargs)
  File "C:\Users\ozifi\OneDrive\Masaüstü\django\venv\lib\site-packages\MySQLdb\connections.py", line 200, in __init__
    super().__init__(*args, **kwargs2)
MySQLdb.OperationalError: (2002, "Can't connect to server on '127.0.0.1' (10061)")

The above exception was the direct cause of the following exception:

Traceback (most recent call last):
  File "C:\Users\ozifi\OneDrive\Masaüstü\django\venv\lib\site-packages\django\core\handlers\exception.py", line 47, in inner
    response = get_response(request)
  File "C:\Users\ozifi\OneDrive\Masaüstü\django\venv\lib\site-packages\django\core\handlers\base.py", line 181, in _get_response
    response = wrapped_callback(request, *callback_args, **callback_kwargs)
  File "C:\Users\ozifi\OneDrive\Masaüstü\django\venv\lib\site-packages\django\contrib\auth\decorators.py", line 20, in _wrapped_view
    if test_func(request.user):
  File "C:\Users\ozifi\OneDrive\Masaüstü\django\venv\lib\site-packages\django\contrib\auth\decorators.py", line 44, in <lambda>
    lambda u: u.is_authenticated,
  File "C:\Users\ozifi\OneDrive\Masaüstü\django\venv\lib\site-packages\django\utils\functional.py", line 246, in inner
    self._setup()
  File "C:\Users\ozifi\OneDrive\Masaüstü\django\venv\lib\site-packages\django\utils\functional.py", line 382, in _setup
    self._wrapped = self._setupfunc()
  File "C:\Users\ozifi\OneDrive\Masaüstü\django\venv\lib\site-packages\django\contrib\auth\middleware.py", line 23, in <lambda>
    request.user = SimpleLazyObject(lambda: get_user(request))
  File "C:\Users\ozifi\OneDrive\Masaüstü\django\venv\lib\site-packages\django\contrib\auth\middleware.py", line 11, in get_user
    request._cached_user = auth.get_user(request)
  File "C:\Users\ozifi\OneDrive\Masaüstü\django\venv\lib\site-packages\django\contrib\auth\__init__.py", line 177, in get_user
    user_id = _get_user_session_key(request)
  File "C:\Users\ozifi\OneDrive\Masaüstü\django\venv\lib\site-packages\django\contrib\auth\__init__.py", line 60, in _get_user_session_key
    return get_user_model()._meta.pk.to_python(request.session[SESSION_KEY])
  File "C:\Users\ozifi\OneDrive\Masaüstü\django\venv\lib\site-packages\django\contrib\sessions\backends\base.py", line 65, in __getitem__
    return self._session[key]
  File "C:\Users\ozifi\OneDrive\Masaüstü\django\venv\lib\site-packages\django\contrib\sessions\backends\base.py", line 238, in _get_session
    self._session_cache = self.load()
  File "C:\Users\ozifi\OneDrive\Masaüstü\django\venv\lib\site-packages\django\contrib\sessions\backends\db.py", line 43, in load
    s = self._get_session_from_db()
  File "C:\Users\ozifi\OneDrive\Masaüstü\django\venv\lib\site-packages\django\contrib\sessions\backends\db.py", line 32, in _get_session_from_db
    return self.model.objects.get(
  File "C:\Users\ozifi\OneDrive\Masaüstü\django\venv\lib\site-packages\django\db\models\manager.py", line 85, in manager_method
    return getattr(self.get_queryset(), name)(*args, **kwargs)
  File "C:\Users\ozifi\OneDrive\Masaüstü\django\venv\lib\site-packages\django\db\models\query.py", line 431, in get
    num = len(clone)
  File "C:\Users\ozifi\OneDrive\Masaüstü\django\venv\lib\site-packages\django\db\models\query.py", line 262, in __len__
    self._fetch_all()
  File "C:\Users\ozifi\OneDrive\Masaüstü\django\venv\lib\site-packages\django\db\models\query.py", line 1324, in _fetch_all
    self._result_cache = list(self._iterable_class(self))
  File "C:\Users\ozifi\OneDrive\Masaüstü\django\venv\lib\site-packages\django\db\models\query.py", line 51, in __iter__
    results = compiler.execute_sql(chunked_fetch=self.chunked_fetch, chunk_size=self.chunk_size)
  File "C:\Users\ozifi\OneDrive\Masaüstü\django\venv\lib\site-packages\django\db\models\sql\compiler.py", line 1167, in execute_sql
    cursor = self.connection.cursor()
  File "C:\Users\ozifi\OneDrive\Masaüstü\django\venv\lib\site-packages\django\utils\asyncio.py", line 26, in inner
    return func(*args, **kwargs)
  File "C:\Users\ozifi\OneDrive\Masaüstü\django\venv\lib\site-packages\django\db\backends\base\base.py", line 259, in cursor
    return self._cursor()
  File "C:\Users\ozifi\OneDrive\Masaüstü\django\venv\lib\site-packages\django\db\backends\base\base.py", line 235, in _cursor
    self.ensure_connection()
  File "C:\Users\ozifi\OneDrive\Masaüstü\django\venv\lib\site-packages\django\utils\asyncio.py", line 26, in inner
    return func(*args, **kwargs)
  File "C:\Users\ozifi\OneDrive\Masaüstü\django\venv\lib\site-packages\django\db\backends\base\base.py", line 218, in ensure_connection
    with self.wrap_database_errors:
  File "C:\Users\ozifi\OneDrive\Masaüstü\django\venv\lib\site-packages\django\db\utils.py", line 90, in __exit__
    raise dj_exc_value.with_traceback(traceback) from exc_value
  File "C:\Users\ozifi\OneDrive\Masaüstü\django\venv\lib\site-packages\django\db\backends\base\base.py", line 219, in ensure_connection
    self.connect()
  File "C:\Users\ozifi\OneDrive\Masaüstü\django\venv\lib\site-packages\django\utils\asyncio.py", line 26, in inner
    return func(*args, **kwargs)
  File "C:\Users\ozifi\OneDrive\Masaüstü\django\venv\lib\site-packages\django\db\backends\base\base.py", line 200, in connect
    self.connection = self.get_new_connection(conn_params)
  File "C:\Users\ozifi\OneDrive\Masaüstü\django\venv\lib\site-packages\django\utils\asyncio.py", line 26, in inner
    return func(*args, **kwargs)
  File "C:\Users\ozifi\OneDrive\Masaüstü\django\venv\lib\site-packages\django\db\backends\mysql\base.py", line 234, in get_new_connection
    connection = Database.connect(**conn_params)
  File "C:\Users\ozifi\OneDrive\Masaüstü\django\venv\lib\site-packages\MySQLdb\__init__.py", line 121, in Connect
    return Connection(*args, **kwargs)
  File "C:\Users\ozifi\OneDrive\Masaüstü\django\venv\lib\site-packages\MySQLdb\connections.py", line 200, in __init__
    super().__init__(*args, **kwargs2)
django.db.utils.OperationalError: (2002, "Can't connect to server on '127.0.0.1' (10061)")
ERROR 2025-05-15 21:13:49,280 basehttp "GET /profile/change-password/ HTTP/1.1" 500 272836
ERROR 2025-05-15 21:13:52,331 log Internal Server Error: /profile/change-password/
Traceback (most recent call last):
  File "C:\Users\ozifi\OneDrive\Masaüstü\django\venv\lib\site-packages\django\contrib\sessions\backends\base.py", line 233, in _get_session
    return self._session_cache
AttributeError: 'SessionStore' object has no attribute '_session_cache'

During handling of the above exception, another exception occurred:

Traceback (most recent call last):
  File "C:\Users\ozifi\OneDrive\Masaüstü\django\venv\lib\site-packages\django\db\backends\base\base.py", line 219, in ensure_connection
    self.connect()
  File "C:\Users\ozifi\OneDrive\Masaüstü\django\venv\lib\site-packages\django\utils\asyncio.py", line 26, in inner
    return func(*args, **kwargs)
  File "C:\Users\ozifi\OneDrive\Masaüstü\django\venv\lib\site-packages\django\db\backends\base\base.py", line 200, in connect
    self.connection = self.get_new_connection(conn_params)
  File "C:\Users\ozifi\OneDrive\Masaüstü\django\venv\lib\site-packages\django\utils\asyncio.py", line 26, in inner
    return func(*args, **kwargs)
  File "C:\Users\ozifi\OneDrive\Masaüstü\django\venv\lib\site-packages\django\db\backends\mysql\base.py", line 234, in get_new_connection
    connection = Database.connect(**conn_params)
  File "C:\Users\ozifi\OneDrive\Masaüstü\django\venv\lib\site-packages\MySQLdb\__init__.py", line 121, in Connect
    return Connection(*args, **kwargs)
  File "C:\Users\ozifi\OneDrive\Masaüstü\django\venv\lib\site-packages\MySQLdb\connections.py", line 200, in __init__
    super().__init__(*args, **kwargs2)
MySQLdb.OperationalError: (2002, "Can't connect to server on '127.0.0.1' (10061)")

The above exception was the direct cause of the following exception:

Traceback (most recent call last):
  File "C:\Users\ozifi\OneDrive\Masaüstü\django\venv\lib\site-packages\django\core\handlers\exception.py", line 47, in inner
    response = get_response(request)
  File "C:\Users\ozifi\OneDrive\Masaüstü\django\venv\lib\site-packages\django\core\handlers\base.py", line 181, in _get_response
    response = wrapped_callback(request, *callback_args, **callback_kwargs)
  File "C:\Users\ozifi\OneDrive\Masaüstü\django\venv\lib\site-packages\django\contrib\auth\decorators.py", line 20, in _wrapped_view
    if test_func(request.user):
  File "C:\Users\ozifi\OneDrive\Masaüstü\django\venv\lib\site-packages\django\contrib\auth\decorators.py", line 44, in <lambda>
    lambda u: u.is_authenticated,
  File "C:\Users\ozifi\OneDrive\Masaüstü\django\venv\lib\site-packages\django\utils\functional.py", line 246, in inner
    self._setup()
  File "C:\Users\ozifi\OneDrive\Masaüstü\django\venv\lib\site-packages\django\utils\functional.py", line 382, in _setup
    self._wrapped = self._setupfunc()
  File "C:\Users\ozifi\OneDrive\Masaüstü\django\venv\lib\site-packages\django\contrib\auth\middleware.py", line 23, in <lambda>
    request.user = SimpleLazyObject(lambda: get_user(request))
  File "C:\Users\ozifi\OneDrive\Masaüstü\django\venv\lib\site-packages\django\contrib\auth\middleware.py", line 11, in get_user
    request._cached_user = auth.get_user(request)
  File "C:\Users\ozifi\OneDrive\Masaüstü\django\venv\lib\site-packages\django\contrib\auth\__init__.py", line 177, in get_user
    user_id = _get_user_session_key(request)
  File "C:\Users\ozifi\OneDrive\Masaüstü\django\venv\lib\site-packages\django\contrib\auth\__init__.py", line 60, in _get_user_session_key
    return get_user_model()._meta.pk.to_python(request.session[SESSION_KEY])
  File "C:\Users\ozifi\OneDrive\Masaüstü\django\venv\lib\site-packages\django\contrib\sessions\backends\base.py", line 65, in __getitem__
    return self._session[key]
  File "C:\Users\ozifi\OneDrive\Masaüstü\django\venv\lib\site-packages\django\contrib\sessions\backends\base.py", line 238, in _get_session
    self._session_cache = self.load()
  File "C:\Users\ozifi\OneDrive\Masaüstü\django\venv\lib\site-packages\django\contrib\sessions\backends\db.py", line 43, in load
    s = self._get_session_from_db()
  File "C:\Users\ozifi\OneDrive\Masaüstü\django\venv\lib\site-packages\django\contrib\sessions\backends\db.py", line 32, in _get_session_from_db
    return self.model.objects.get(
  File "C:\Users\ozifi\OneDrive\Masaüstü\django\venv\lib\site-packages\django\db\models\manager.py", line 85, in manager_method
    return getattr(self.get_queryset(), name)(*args, **kwargs)
  File "C:\Users\ozifi\OneDrive\Masaüstü\django\venv\lib\site-packages\django\db\models\query.py", line 431, in get
    num = len(clone)
  File "C:\Users\ozifi\OneDrive\Masaüstü\django\venv\lib\site-packages\django\db\models\query.py", line 262, in __len__
    self._fetch_all()
  File "C:\Users\ozifi\OneDrive\Masaüstü\django\venv\lib\site-packages\django\db\models\query.py", line 1324, in _fetch_all
    self._result_cache = list(self._iterable_class(self))
  File "C:\Users\ozifi\OneDrive\Masaüstü\django\venv\lib\site-packages\django\db\models\query.py", line 51, in __iter__
    results = compiler.execute_sql(chunked_fetch=self.chunked_fetch, chunk_size=self.chunk_size)
  File "C:\Users\ozifi\OneDrive\Masaüstü\django\venv\lib\site-packages\django\db\models\sql\compiler.py", line 1167, in execute_sql
    cursor = self.connection.cursor()
  File "C:\Users\ozifi\OneDrive\Masaüstü\django\venv\lib\site-packages\django\utils\asyncio.py", line 26, in inner
    return func(*args, **kwargs)
  File "C:\Users\ozifi\OneDrive\Masaüstü\django\venv\lib\site-packages\django\db\backends\base\base.py", line 259, in cursor
    return self._cursor()
  File "C:\Users\ozifi\OneDrive\Masaüstü\django\venv\lib\site-packages\django\db\backends\base\base.py", line 235, in _cursor
    self.ensure_connection()
  File "C:\Users\ozifi\OneDrive\Masaüstü\django\venv\lib\site-packages\django\utils\asyncio.py", line 26, in inner
    return func(*args, **kwargs)
  File "C:\Users\ozifi\OneDrive\Masaüstü\django\venv\lib\site-packages\django\db\backends\base\base.py", line 218, in ensure_connection
    with self.wrap_database_errors:
  File "C:\Users\ozifi\OneDrive\Masaüstü\django\venv\lib\site-packages\django\db\utils.py", line 90, in __exit__
    raise dj_exc_value.with_traceback(traceback) from exc_value
  File "C:\Users\ozifi\OneDrive\Masaüstü\django\venv\lib\site-packages\django\db\backends\base\base.py", line 219, in ensure_connection
    self.connect()
  File "C:\Users\ozifi\OneDrive\Masaüstü\django\venv\lib\site-packages\django\utils\asyncio.py", line 26, in inner
    return func(*args, **kwargs)
  File "C:\Users\ozifi\OneDrive\Masaüstü\django\venv\lib\site-packages\django\db\backends\base\base.py", line 200, in connect
    self.connection = self.get_new_connection(conn_params)
  File "C:\Users\ozifi\OneDrive\Masaüstü\django\venv\lib\site-packages\django\utils\asyncio.py", line 26, in inner
    return func(*args, **kwargs)
  File "C:\Users\ozifi\OneDrive\Masaüstü\django\venv\lib\site-packages\django\db\backends\mysql\base.py", line 234, in get_new_connection
    connection = Database.connect(**conn_params)
  File "C:\Users\ozifi\OneDrive\Masaüstü\django\venv\lib\site-packages\MySQLdb\__init__.py", line 121, in Connect
    return Connection(*args, **kwargs)
  File "C:\Users\ozifi\OneDrive\Masaüstü\django\venv\lib\site-packages\MySQLdb\connections.py", line 200, in __init__
    super().__init__(*args, **kwargs2)
django.db.utils.OperationalError: (2002, "Can't connect to server on '127.0.0.1' (10061)")
ERROR 2025-05-15 21:13:52,346 basehttp "GET /profile/change-password/ HTTP/1.1" 500 272820
ERROR 2025-05-15 21:13:57,243 log Internal Server Error: /profile/change-password/
Traceback (most recent call last):
  File "C:\Users\ozifi\OneDrive\Masaüstü\django\venv\lib\site-packages\django\contrib\sessions\backends\base.py", line 233, in _get_session
    return self._session_cache
AttributeError: 'SessionStore' object has no attribute '_session_cache'

During handling of the above exception, another exception occurred:

Traceback (most recent call last):
  File "C:\Users\ozifi\OneDrive\Masaüstü\django\venv\lib\site-packages\django\db\backends\base\base.py", line 219, in ensure_connection
    self.connect()
  File "C:\Users\ozifi\OneDrive\Masaüstü\django\venv\lib\site-packages\django\utils\asyncio.py", line 26, in inner
    return func(*args, **kwargs)
  File "C:\Users\ozifi\OneDrive\Masaüstü\django\venv\lib\site-packages\django\db\backends\base\base.py", line 200, in connect
    self.connection = self.get_new_connection(conn_params)
  File "C:\Users\ozifi\OneDrive\Masaüstü\django\venv\lib\site-packages\django\utils\asyncio.py", line 26, in inner
    return func(*args, **kwargs)
  File "C:\Users\ozifi\OneDrive\Masaüstü\django\venv\lib\site-packages\django\db\backends\mysql\base.py", line 234, in get_new_connection
    connection = Database.connect(**conn_params)
  File "C:\Users\ozifi\OneDrive\Masaüstü\django\venv\lib\site-packages\MySQLdb\__init__.py", line 121, in Connect
    return Connection(*args, **kwargs)
  File "C:\Users\ozifi\OneDrive\Masaüstü\django\venv\lib\site-packages\MySQLdb\connections.py", line 200, in __init__
    super().__init__(*args, **kwargs2)
MySQLdb.OperationalError: (2002, "Can't connect to server on '127.0.0.1' (10061)")

The above exception was the direct cause of the following exception:

Traceback (most recent call last):
  File "C:\Users\ozifi\OneDrive\Masaüstü\django\venv\lib\site-packages\django\core\handlers\exception.py", line 47, in inner
    response = get_response(request)
  File "C:\Users\ozifi\OneDrive\Masaüstü\django\venv\lib\site-packages\django\core\handlers\base.py", line 181, in _get_response
    response = wrapped_callback(request, *callback_args, **callback_kwargs)
  File "C:\Users\ozifi\OneDrive\Masaüstü\django\venv\lib\site-packages\django\contrib\auth\decorators.py", line 20, in _wrapped_view
    if test_func(request.user):
  File "C:\Users\ozifi\OneDrive\Masaüstü\django\venv\lib\site-packages\django\contrib\auth\decorators.py", line 44, in <lambda>
    lambda u: u.is_authenticated,
  File "C:\Users\ozifi\OneDrive\Masaüstü\django\venv\lib\site-packages\django\utils\functional.py", line 246, in inner
    self._setup()
  File "C:\Users\ozifi\OneDrive\Masaüstü\django\venv\lib\site-packages\django\utils\functional.py", line 382, in _setup
    self._wrapped = self._setupfunc()
  File "C:\Users\ozifi\OneDrive\Masaüstü\django\venv\lib\site-packages\django\contrib\auth\middleware.py", line 23, in <lambda>
    request.user = SimpleLazyObject(lambda: get_user(request))
  File "C:\Users\ozifi\OneDrive\Masaüstü\django\venv\lib\site-packages\django\contrib\auth\middleware.py", line 11, in get_user
    request._cached_user = auth.get_user(request)
  File "C:\Users\ozifi\OneDrive\Masaüstü\django\venv\lib\site-packages\django\contrib\auth\__init__.py", line 177, in get_user
    user_id = _get_user_session_key(request)
  File "C:\Users\ozifi\OneDrive\Masaüstü\django\venv\lib\site-packages\django\contrib\auth\__init__.py", line 60, in _get_user_session_key
    return get_user_model()._meta.pk.to_python(request.session[SESSION_KEY])
  File "C:\Users\ozifi\OneDrive\Masaüstü\django\venv\lib\site-packages\django\contrib\sessions\backends\base.py", line 65, in __getitem__
    return self._session[key]
  File "C:\Users\ozifi\OneDrive\Masaüstü\django\venv\lib\site-packages\django\contrib\sessions\backends\base.py", line 238, in _get_session
    self._session_cache = self.load()
  File "C:\Users\ozifi\OneDrive\Masaüstü\django\venv\lib\site-packages\django\contrib\sessions\backends\db.py", line 43, in load
    s = self._get_session_from_db()
  File "C:\Users\ozifi\OneDrive\Masaüstü\django\venv\lib\site-packages\django\contrib\sessions\backends\db.py", line 32, in _get_session_from_db
    return self.model.objects.get(
  File "C:\Users\ozifi\OneDrive\Masaüstü\django\venv\lib\site-packages\django\db\models\manager.py", line 85, in manager_method
    return getattr(self.get_queryset(), name)(*args, **kwargs)
  File "C:\Users\ozifi\OneDrive\Masaüstü\django\venv\lib\site-packages\django\db\models\query.py", line 431, in get
    num = len(clone)
  File "C:\Users\ozifi\OneDrive\Masaüstü\django\venv\lib\site-packages\django\db\models\query.py", line 262, in __len__
    self._fetch_all()
  File "C:\Users\ozifi\OneDrive\Masaüstü\django\venv\lib\site-packages\django\db\models\query.py", line 1324, in _fetch_all
    self._result_cache = list(self._iterable_class(self))
  File "C:\Users\ozifi\OneDrive\Masaüstü\django\venv\lib\site-packages\django\db\models\query.py", line 51, in __iter__
    results = compiler.execute_sql(chunked_fetch=self.chunked_fetch, chunk_size=self.chunk_size)
  File "C:\Users\ozifi\OneDrive\Masaüstü\django\venv\lib\site-packages\django\db\models\sql\compiler.py", line 1167, in execute_sql
    cursor = self.connection.cursor()
  File "C:\Users\ozifi\OneDrive\Masaüstü\django\venv\lib\site-packages\django\utils\asyncio.py", line 26, in inner
    return func(*args, **kwargs)
  File "C:\Users\ozifi\OneDrive\Masaüstü\django\venv\lib\site-packages\django\db\backends\base\base.py", line 259, in cursor
    return self._cursor()
  File "C:\Users\ozifi\OneDrive\Masaüstü\django\venv\lib\site-packages\django\db\backends\base\base.py", line 235, in _cursor
    self.ensure_connection()
  File "C:\Users\ozifi\OneDrive\Masaüstü\django\venv\lib\site-packages\django\utils\asyncio.py", line 26, in inner
    return func(*args, **kwargs)
  File "C:\Users\ozifi\OneDrive\Masaüstü\django\venv\lib\site-packages\django\db\backends\base\base.py", line 218, in ensure_connection
    with self.wrap_database_errors:
  File "C:\Users\ozifi\OneDrive\Masaüstü\django\venv\lib\site-packages\django\db\utils.py", line 90, in __exit__
    raise dj_exc_value.with_traceback(traceback) from exc_value
  File "C:\Users\ozifi\OneDrive\Masaüstü\django\venv\lib\site-packages\django\db\backends\base\base.py", line 219, in ensure_connection
    self.connect()
  File "C:\Users\ozifi\OneDrive\Masaüstü\django\venv\lib\site-packages\django\utils\asyncio.py", line 26, in inner
    return func(*args, **kwargs)
  File "C:\Users\ozifi\OneDrive\Masaüstü\django\venv\lib\site-packages\django\db\backends\base\base.py", line 200, in connect
    self.connection = self.get_new_connection(conn_params)
  File "C:\Users\ozifi\OneDrive\Masaüstü\django\venv\lib\site-packages\django\utils\asyncio.py", line 26, in inner
    return func(*args, **kwargs)
  File "C:\Users\ozifi\OneDrive\Masaüstü\django\venv\lib\site-packages\django\db\backends\mysql\base.py", line 234, in get_new_connection
    connection = Database.connect(**conn_params)
  File "C:\Users\ozifi\OneDrive\Masaüstü\django\venv\lib\site-packages\MySQLdb\__init__.py", line 121, in Connect
    return Connection(*args, **kwargs)
  File "C:\Users\ozifi\OneDrive\Masaüstü\django\venv\lib\site-packages\MySQLdb\connections.py", line 200, in __init__
    super().__init__(*args, **kwargs2)
django.db.utils.OperationalError: (2002, "Can't connect to server on '127.0.0.1' (10061)")
ERROR 2025-05-15 21:13:57,246 basehttp "POST /profile/change-password/ HTTP/1.1" 500 274052
ERROR 2025-05-15 21:14:05,313 log Internal Server Error: /
Traceback (most recent call last):
  File "C:\Users\ozifi\OneDrive\Masaüstü\django\venv\lib\site-packages\django\contrib\sessions\backends\base.py", line 233, in _get_session
    return self._session_cache
AttributeError: 'SessionStore' object has no attribute '_session_cache'

During handling of the above exception, another exception occurred:

Traceback (most recent call last):
  File "C:\Users\ozifi\OneDrive\Masaüstü\django\venv\lib\site-packages\django\db\backends\base\base.py", line 219, in ensure_connection
    self.connect()
  File "C:\Users\ozifi\OneDrive\Masaüstü\django\venv\lib\site-packages\django\utils\asyncio.py", line 26, in inner
    return func(*args, **kwargs)
  File "C:\Users\ozifi\OneDrive\Masaüstü\django\venv\lib\site-packages\django\db\backends\base\base.py", line 200, in connect
    self.connection = self.get_new_connection(conn_params)
  File "C:\Users\ozifi\OneDrive\Masaüstü\django\venv\lib\site-packages\django\utils\asyncio.py", line 26, in inner
    return func(*args, **kwargs)
  File "C:\Users\ozifi\OneDrive\Masaüstü\django\venv\lib\site-packages\django\db\backends\mysql\base.py", line 234, in get_new_connection
    connection = Database.connect(**conn_params)
  File "C:\Users\ozifi\OneDrive\Masaüstü\django\venv\lib\site-packages\MySQLdb\__init__.py", line 121, in Connect
    return Connection(*args, **kwargs)
  File "C:\Users\ozifi\OneDrive\Masaüstü\django\venv\lib\site-packages\MySQLdb\connections.py", line 200, in __init__
    super().__init__(*args, **kwargs2)
MySQLdb.OperationalError: (2002, "Can't connect to server on '127.0.0.1' (10061)")

The above exception was the direct cause of the following exception:

Traceback (most recent call last):
  File "C:\Users\ozifi\OneDrive\Masaüstü\django\venv\lib\site-packages\django\core\handlers\exception.py", line 47, in inner
    response = get_response(request)
  File "C:\Users\ozifi\OneDrive\Masaüstü\django\venv\lib\site-packages\django\core\handlers\base.py", line 181, in _get_response
    response = wrapped_callback(request, *callback_args, **callback_kwargs)
  File "C:\Users\ozifi\OneDrive\Masaüstü\django\venv\lib\site-packages\django\contrib\auth\decorators.py", line 20, in _wrapped_view
    if test_func(request.user):
  File "C:\Users\ozifi\OneDrive\Masaüstü\django\venv\lib\site-packages\django\contrib\auth\decorators.py", line 44, in <lambda>
    lambda u: u.is_authenticated,
  File "C:\Users\ozifi\OneDrive\Masaüstü\django\venv\lib\site-packages\django\utils\functional.py", line 246, in inner
    self._setup()
  File "C:\Users\ozifi\OneDrive\Masaüstü\django\venv\lib\site-packages\django\utils\functional.py", line 382, in _setup
    self._wrapped = self._setupfunc()
  File "C:\Users\ozifi\OneDrive\Masaüstü\django\venv\lib\site-packages\django\contrib\auth\middleware.py", line 23, in <lambda>
    request.user = SimpleLazyObject(lambda: get_user(request))
  File "C:\Users\ozifi\OneDrive\Masaüstü\django\venv\lib\site-packages\django\contrib\auth\middleware.py", line 11, in get_user
    request._cached_user = auth.get_user(request)
  File "C:\Users\ozifi\OneDrive\Masaüstü\django\venv\lib\site-packages\django\contrib\auth\__init__.py", line 177, in get_user
    user_id = _get_user_session_key(request)
  File "C:\Users\ozifi\OneDrive\Masaüstü\django\venv\lib\site-packages\django\contrib\auth\__init__.py", line 60, in _get_user_session_key
    return get_user_model()._meta.pk.to_python(request.session[SESSION_KEY])
  File "C:\Users\ozifi\OneDrive\Masaüstü\django\venv\lib\site-packages\django\contrib\sessions\backends\base.py", line 65, in __getitem__
    return self._session[key]
  File "C:\Users\ozifi\OneDrive\Masaüstü\django\venv\lib\site-packages\django\contrib\sessions\backends\base.py", line 238, in _get_session
    self._session_cache = self.load()
  File "C:\Users\ozifi\OneDrive\Masaüstü\django\venv\lib\site-packages\django\contrib\sessions\backends\db.py", line 43, in load
    s = self._get_session_from_db()
  File "C:\Users\ozifi\OneDrive\Masaüstü\django\venv\lib\site-packages\django\contrib\sessions\backends\db.py", line 32, in _get_session_from_db
    return self.model.objects.get(
  File "C:\Users\ozifi\OneDrive\Masaüstü\django\venv\lib\site-packages\django\db\models\manager.py", line 85, in manager_method
    return getattr(self.get_queryset(), name)(*args, **kwargs)
  File "C:\Users\ozifi\OneDrive\Masaüstü\django\venv\lib\site-packages\django\db\models\query.py", line 431, in get
    num = len(clone)
  File "C:\Users\ozifi\OneDrive\Masaüstü\django\venv\lib\site-packages\django\db\models\query.py", line 262, in __len__
    self._fetch_all()
  File "C:\Users\ozifi\OneDrive\Masaüstü\django\venv\lib\site-packages\django\db\models\query.py", line 1324, in _fetch_all
    self._result_cache = list(self._iterable_class(self))
  File "C:\Users\ozifi\OneDrive\Masaüstü\django\venv\lib\site-packages\django\db\models\query.py", line 51, in __iter__
    results = compiler.execute_sql(chunked_fetch=self.chunked_fetch, chunk_size=self.chunk_size)
  File "C:\Users\ozifi\OneDrive\Masaüstü\django\venv\lib\site-packages\django\db\models\sql\compiler.py", line 1167, in execute_sql
    cursor = self.connection.cursor()
  File "C:\Users\ozifi\OneDrive\Masaüstü\django\venv\lib\site-packages\django\utils\asyncio.py", line 26, in inner
    return func(*args, **kwargs)
  File "C:\Users\ozifi\OneDrive\Masaüstü\django\venv\lib\site-packages\django\db\backends\base\base.py", line 259, in cursor
    return self._cursor()
  File "C:\Users\ozifi\OneDrive\Masaüstü\django\venv\lib\site-packages\django\db\backends\base\base.py", line 235, in _cursor
    self.ensure_connection()
  File "C:\Users\ozifi\OneDrive\Masaüstü\django\venv\lib\site-packages\django\utils\asyncio.py", line 26, in inner
    return func(*args, **kwargs)
  File "C:\Users\ozifi\OneDrive\Masaüstü\django\venv\lib\site-packages\django\db\backends\base\base.py", line 218, in ensure_connection
    with self.wrap_database_errors:
  File "C:\Users\ozifi\OneDrive\Masaüstü\django\venv\lib\site-packages\django\db\utils.py", line 90, in __exit__
    raise dj_exc_value.with_traceback(traceback) from exc_value
  File "C:\Users\ozifi\OneDrive\Masaüstü\django\venv\lib\site-packages\django\db\backends\base\base.py", line 219, in ensure_connection
    self.connect()
  File "C:\Users\ozifi\OneDrive\Masaüstü\django\venv\lib\site-packages\django\utils\asyncio.py", line 26, in inner
    return func(*args, **kwargs)
  File "C:\Users\ozifi\OneDrive\Masaüstü\django\venv\lib\site-packages\django\db\backends\base\base.py", line 200, in connect
    self.connection = self.get_new_connection(conn_params)
  File "C:\Users\ozifi\OneDrive\Masaüstü\django\venv\lib\site-packages\django\utils\asyncio.py", line 26, in inner
    return func(*args, **kwargs)
  File "C:\Users\ozifi\OneDrive\Masaüstü\django\venv\lib\site-packages\django\db\backends\mysql\base.py", line 234, in get_new_connection
    connection = Database.connect(**conn_params)
  File "C:\Users\ozifi\OneDrive\Masaüstü\django\venv\lib\site-packages\MySQLdb\__init__.py", line 121, in Connect
    return Connection(*args, **kwargs)
  File "C:\Users\ozifi\OneDrive\Masaüstü\django\venv\lib\site-packages\MySQLdb\connections.py", line 200, in __init__
    super().__init__(*args, **kwargs2)
django.db.utils.OperationalError: (2002, "Can't connect to server on '127.0.0.1' (10061)")
ERROR 2025-05-15 21:14:05,325 basehttp "GET / HTTP/1.1" 500 272625
ERROR 2025-05-15 21:14:09,500 log Internal Server Error: /profile/
Traceback (most recent call last):
  File "C:\Users\ozifi\OneDrive\Masaüstü\django\venv\lib\site-packages\django\contrib\sessions\backends\base.py", line 233, in _get_session
    return self._session_cache
AttributeError: 'SessionStore' object has no attribute '_session_cache'

During handling of the above exception, another exception occurred:

Traceback (most recent call last):
  File "C:\Users\ozifi\OneDrive\Masaüstü\django\venv\lib\site-packages\django\db\backends\base\base.py", line 219, in ensure_connection
    self.connect()
  File "C:\Users\ozifi\OneDrive\Masaüstü\django\venv\lib\site-packages\django\utils\asyncio.py", line 26, in inner
    return func(*args, **kwargs)
  File "C:\Users\ozifi\OneDrive\Masaüstü\django\venv\lib\site-packages\django\db\backends\base\base.py", line 200, in connect
    self.connection = self.get_new_connection(conn_params)
  File "C:\Users\ozifi\OneDrive\Masaüstü\django\venv\lib\site-packages\django\utils\asyncio.py", line 26, in inner
    return func(*args, **kwargs)
  File "C:\Users\ozifi\OneDrive\Masaüstü\django\venv\lib\site-packages\django\db\backends\mysql\base.py", line 234, in get_new_connection
    connection = Database.connect(**conn_params)
  File "C:\Users\ozifi\OneDrive\Masaüstü\django\venv\lib\site-packages\MySQLdb\__init__.py", line 121, in Connect
    return Connection(*args, **kwargs)
  File "C:\Users\ozifi\OneDrive\Masaüstü\django\venv\lib\site-packages\MySQLdb\connections.py", line 200, in __init__
    super().__init__(*args, **kwargs2)
MySQLdb.OperationalError: (2002, "Can't connect to server on '127.0.0.1' (10061)")

The above exception was the direct cause of the following exception:

Traceback (most recent call last):
  File "C:\Users\ozifi\OneDrive\Masaüstü\django\venv\lib\site-packages\django\core\handlers\exception.py", line 47, in inner
    response = get_response(request)
  File "C:\Users\ozifi\OneDrive\Masaüstü\django\venv\lib\site-packages\django\core\handlers\base.py", line 181, in _get_response
    response = wrapped_callback(request, *callback_args, **callback_kwargs)
  File "C:\Users\ozifi\OneDrive\Masaüstü\django\venv\lib\site-packages\django\contrib\auth\decorators.py", line 20, in _wrapped_view
    if test_func(request.user):
  File "C:\Users\ozifi\OneDrive\Masaüstü\django\venv\lib\site-packages\django\contrib\auth\decorators.py", line 44, in <lambda>
    lambda u: u.is_authenticated,
  File "C:\Users\ozifi\OneDrive\Masaüstü\django\venv\lib\site-packages\django\utils\functional.py", line 246, in inner
    self._setup()
  File "C:\Users\ozifi\OneDrive\Masaüstü\django\venv\lib\site-packages\django\utils\functional.py", line 382, in _setup
    self._wrapped = self._setupfunc()
  File "C:\Users\ozifi\OneDrive\Masaüstü\django\venv\lib\site-packages\django\contrib\auth\middleware.py", line 23, in <lambda>
    request.user = SimpleLazyObject(lambda: get_user(request))
  File "C:\Users\ozifi\OneDrive\Masaüstü\django\venv\lib\site-packages\django\contrib\auth\middleware.py", line 11, in get_user
    request._cached_user = auth.get_user(request)
  File "C:\Users\ozifi\OneDrive\Masaüstü\django\venv\lib\site-packages\django\contrib\auth\__init__.py", line 177, in get_user
    user_id = _get_user_session_key(request)
  File "C:\Users\ozifi\OneDrive\Masaüstü\django\venv\lib\site-packages\django\contrib\auth\__init__.py", line 60, in _get_user_session_key
    return get_user_model()._meta.pk.to_python(request.session[SESSION_KEY])
  File "C:\Users\ozifi\OneDrive\Masaüstü\django\venv\lib\site-packages\django\contrib\sessions\backends\base.py", line 65, in __getitem__
    return self._session[key]
  File "C:\Users\ozifi\OneDrive\Masaüstü\django\venv\lib\site-packages\django\contrib\sessions\backends\base.py", line 238, in _get_session
    self._session_cache = self.load()
  File "C:\Users\ozifi\OneDrive\Masaüstü\django\venv\lib\site-packages\django\contrib\sessions\backends\db.py", line 43, in load
    s = self._get_session_from_db()
  File "C:\Users\ozifi\OneDrive\Masaüstü\django\venv\lib\site-packages\django\contrib\sessions\backends\db.py", line 32, in _get_session_from_db
    return self.model.objects.get(
  File "C:\Users\ozifi\OneDrive\Masaüstü\django\venv\lib\site-packages\django\db\models\manager.py", line 85, in manager_method
    return getattr(self.get_queryset(), name)(*args, **kwargs)
  File "C:\Users\ozifi\OneDrive\Masaüstü\django\venv\lib\site-packages\django\db\models\query.py", line 431, in get
    num = len(clone)
  File "C:\Users\ozifi\OneDrive\Masaüstü\django\venv\lib\site-packages\django\db\models\query.py", line 262, in __len__
    self._fetch_all()
  File "C:\Users\ozifi\OneDrive\Masaüstü\django\venv\lib\site-packages\django\db\models\query.py", line 1324, in _fetch_all
    self._result_cache = list(self._iterable_class(self))
  File "C:\Users\ozifi\OneDrive\Masaüstü\django\venv\lib\site-packages\django\db\models\query.py", line 51, in __iter__
    results = compiler.execute_sql(chunked_fetch=self.chunked_fetch, chunk_size=self.chunk_size)
  File "C:\Users\ozifi\OneDrive\Masaüstü\django\venv\lib\site-packages\django\db\models\sql\compiler.py", line 1167, in execute_sql
    cursor = self.connection.cursor()
  File "C:\Users\ozifi\OneDrive\Masaüstü\django\venv\lib\site-packages\django\utils\asyncio.py", line 26, in inner
    return func(*args, **kwargs)
  File "C:\Users\ozifi\OneDrive\Masaüstü\django\venv\lib\site-packages\django\db\backends\base\base.py", line 259, in cursor
    return self._cursor()
  File "C:\Users\ozifi\OneDrive\Masaüstü\django\venv\lib\site-packages\django\db\backends\base\base.py", line 235, in _cursor
    self.ensure_connection()
  File "C:\Users\ozifi\OneDrive\Masaüstü\django\venv\lib\site-packages\django\utils\asyncio.py", line 26, in inner
    return func(*args, **kwargs)
  File "C:\Users\ozifi\OneDrive\Masaüstü\django\venv\lib\site-packages\django\db\backends\base\base.py", line 218, in ensure_connection
    with self.wrap_database_errors:
  File "C:\Users\ozifi\OneDrive\Masaüstü\django\venv\lib\site-packages\django\db\utils.py", line 90, in __exit__
    raise dj_exc_value.with_traceback(traceback) from exc_value
  File "C:\Users\ozifi\OneDrive\Masaüstü\django\venv\lib\site-packages\django\db\backends\base\base.py", line 219, in ensure_connection
    self.connect()
  File "C:\Users\ozifi\OneDrive\Masaüstü\django\venv\lib\site-packages\django\utils\asyncio.py", line 26, in inner
    return func(*args, **kwargs)
  File "C:\Users\ozifi\OneDrive\Masaüstü\django\venv\lib\site-packages\django\db\backends\base\base.py", line 200, in connect
    self.connection = self.get_new_connection(conn_params)
  File "C:\Users\ozifi\OneDrive\Masaüstü\django\venv\lib\site-packages\django\utils\asyncio.py", line 26, in inner
    return func(*args, **kwargs)
  File "C:\Users\ozifi\OneDrive\Masaüstü\django\venv\lib\site-packages\django\db\backends\mysql\base.py", line 234, in get_new_connection
    connection = Database.connect(**conn_params)
  File "C:\Users\ozifi\OneDrive\Masaüstü\django\venv\lib\site-packages\MySQLdb\__init__.py", line 121, in Connect
    return Connection(*args, **kwargs)
  File "C:\Users\ozifi\OneDrive\Masaüstü\django\venv\lib\site-packages\MySQLdb\connections.py", line 200, in __init__
    super().__init__(*args, **kwargs2)
django.db.utils.OperationalError: (2002, "Can't connect to server on '127.0.0.1' (10061)")
ERROR 2025-05-15 21:14:09,506 basehttp "GET /profile/ HTTP/1.1" 500 272871
ERROR 2025-05-15 21:14:09,758 log Internal Server Error: /profile/
Traceback (most recent call last):
  File "C:\Users\ozifi\OneDrive\Masaüstü\django\venv\lib\site-packages\django\contrib\sessions\backends\base.py", line 233, in _get_session
    return self._session_cache
AttributeError: 'SessionStore' object has no attribute '_session_cache'

During handling of the above exception, another exception occurred:

Traceback (most recent call last):
  File "C:\Users\ozifi\OneDrive\Masaüstü\django\venv\lib\site-packages\django\db\backends\base\base.py", line 219, in ensure_connection
    self.connect()
  File "C:\Users\ozifi\OneDrive\Masaüstü\django\venv\lib\site-packages\django\utils\asyncio.py", line 26, in inner
    return func(*args, **kwargs)
  File "C:\Users\ozifi\OneDrive\Masaüstü\django\venv\lib\site-packages\django\db\backends\base\base.py", line 200, in connect
    self.connection = self.get_new_connection(conn_params)
  File "C:\Users\ozifi\OneDrive\Masaüstü\django\venv\lib\site-packages\django\utils\asyncio.py", line 26, in inner
    return func(*args, **kwargs)
  File "C:\Users\ozifi\OneDrive\Masaüstü\django\venv\lib\site-packages\django\db\backends\mysql\base.py", line 234, in get_new_connection
    connection = Database.connect(**conn_params)
  File "C:\Users\ozifi\OneDrive\Masaüstü\django\venv\lib\site-packages\MySQLdb\__init__.py", line 121, in Connect
    return Connection(*args, **kwargs)
  File "C:\Users\ozifi\OneDrive\Masaüstü\django\venv\lib\site-packages\MySQLdb\connections.py", line 200, in __init__
    super().__init__(*args, **kwargs2)
MySQLdb.OperationalError: (2002, "Can't connect to server on '127.0.0.1' (10061)")

The above exception was the direct cause of the following exception:

Traceback (most recent call last):
  File "C:\Users\ozifi\OneDrive\Masaüstü\django\venv\lib\site-packages\django\core\handlers\exception.py", line 47, in inner
    response = get_response(request)
  File "C:\Users\ozifi\OneDrive\Masaüstü\django\venv\lib\site-packages\django\core\handlers\base.py", line 181, in _get_response
    response = wrapped_callback(request, *callback_args, **callback_kwargs)
  File "C:\Users\ozifi\OneDrive\Masaüstü\django\venv\lib\site-packages\django\contrib\auth\decorators.py", line 20, in _wrapped_view
    if test_func(request.user):
  File "C:\Users\ozifi\OneDrive\Masaüstü\django\venv\lib\site-packages\django\contrib\auth\decorators.py", line 44, in <lambda>
    lambda u: u.is_authenticated,
  File "C:\Users\ozifi\OneDrive\Masaüstü\django\venv\lib\site-packages\django\utils\functional.py", line 246, in inner
    self._setup()
  File "C:\Users\ozifi\OneDrive\Masaüstü\django\venv\lib\site-packages\django\utils\functional.py", line 382, in _setup
    self._wrapped = self._setupfunc()
  File "C:\Users\ozifi\OneDrive\Masaüstü\django\venv\lib\site-packages\django\contrib\auth\middleware.py", line 23, in <lambda>
    request.user = SimpleLazyObject(lambda: get_user(request))
  File "C:\Users\ozifi\OneDrive\Masaüstü\django\venv\lib\site-packages\django\contrib\auth\middleware.py", line 11, in get_user
    request._cached_user = auth.get_user(request)
  File "C:\Users\ozifi\OneDrive\Masaüstü\django\venv\lib\site-packages\django\contrib\auth\__init__.py", line 177, in get_user
    user_id = _get_user_session_key(request)
  File "C:\Users\ozifi\OneDrive\Masaüstü\django\venv\lib\site-packages\django\contrib\auth\__init__.py", line 60, in _get_user_session_key
    return get_user_model()._meta.pk.to_python(request.session[SESSION_KEY])
  File "C:\Users\ozifi\OneDrive\Masaüstü\django\venv\lib\site-packages\django\contrib\sessions\backends\base.py", line 65, in __getitem__
    return self._session[key]
  File "C:\Users\ozifi\OneDrive\Masaüstü\django\venv\lib\site-packages\django\contrib\sessions\backends\base.py", line 238, in _get_session
    self._session_cache = self.load()
  File "C:\Users\ozifi\OneDrive\Masaüstü\django\venv\lib\site-packages\django\contrib\sessions\backends\db.py", line 43, in load
    s = self._get_session_from_db()
  File "C:\Users\ozifi\OneDrive\Masaüstü\django\venv\lib\site-packages\django\contrib\sessions\backends\db.py", line 32, in _get_session_from_db
    return self.model.objects.get(
  File "C:\Users\ozifi\OneDrive\Masaüstü\django\venv\lib\site-packages\django\db\models\manager.py", line 85, in manager_method
    return getattr(self.get_queryset(), name)(*args, **kwargs)
  File "C:\Users\ozifi\OneDrive\Masaüstü\django\venv\lib\site-packages\django\db\models\query.py", line 431, in get
    num = len(clone)
  File "C:\Users\ozifi\OneDrive\Masaüstü\django\venv\lib\site-packages\django\db\models\query.py", line 262, in __len__
    self._fetch_all()
  File "C:\Users\ozifi\OneDrive\Masaüstü\django\venv\lib\site-packages\django\db\models\query.py", line 1324, in _fetch_all
    self._result_cache = list(self._iterable_class(self))
  File "C:\Users\ozifi\OneDrive\Masaüstü\django\venv\lib\site-packages\django\db\models\query.py", line 51, in __iter__
    results = compiler.execute_sql(chunked_fetch=self.chunked_fetch, chunk_size=self.chunk_size)
  File "C:\Users\ozifi\OneDrive\Masaüstü\django\venv\lib\site-packages\django\db\models\sql\compiler.py", line 1167, in execute_sql
    cursor = self.connection.cursor()
  File "C:\Users\ozifi\OneDrive\Masaüstü\django\venv\lib\site-packages\django\utils\asyncio.py", line 26, in inner
    return func(*args, **kwargs)
  File "C:\Users\ozifi\OneDrive\Masaüstü\django\venv\lib\site-packages\django\db\backends\base\base.py", line 259, in cursor
    return self._cursor()
  File "C:\Users\ozifi\OneDrive\Masaüstü\django\venv\lib\site-packages\django\db\backends\base\base.py", line 235, in _cursor
    self.ensure_connection()
  File "C:\Users\ozifi\OneDrive\Masaüstü\django\venv\lib\site-packages\django\utils\asyncio.py", line 26, in inner
    return func(*args, **kwargs)
  File "C:\Users\ozifi\OneDrive\Masaüstü\django\venv\lib\site-packages\django\db\backends\base\base.py", line 218, in ensure_connection
    with self.wrap_database_errors:
  File "C:\Users\ozifi\OneDrive\Masaüstü\django\venv\lib\site-packages\django\db\utils.py", line 90, in __exit__
    raise dj_exc_value.with_traceback(traceback) from exc_value
  File "C:\Users\ozifi\OneDrive\Masaüstü\django\venv\lib\site-packages\django\db\backends\base\base.py", line 219, in ensure_connection
    self.connect()
  File "C:\Users\ozifi\OneDrive\Masaüstü\django\venv\lib\site-packages\django\utils\asyncio.py", line 26, in inner
    return func(*args, **kwargs)
  File "C:\Users\ozifi\OneDrive\Masaüstü\django\venv\lib\site-packages\django\db\backends\base\base.py", line 200, in connect
    self.connection = self.get_new_connection(conn_params)
  File "C:\Users\ozifi\OneDrive\Masaüstü\django\venv\lib\site-packages\django\utils\asyncio.py", line 26, in inner
    return func(*args, **kwargs)
  File "C:\Users\ozifi\OneDrive\Masaüstü\django\venv\lib\site-packages\django\db\backends\mysql\base.py", line 234, in get_new_connection
    connection = Database.connect(**conn_params)
  File "C:\Users\ozifi\OneDrive\Masaüstü\django\venv\lib\site-packages\MySQLdb\__init__.py", line 121, in Connect
    return Connection(*args, **kwargs)
  File "C:\Users\ozifi\OneDrive\Masaüstü\django\venv\lib\site-packages\MySQLdb\connections.py", line 200, in __init__
    super().__init__(*args, **kwargs2)
django.db.utils.OperationalError: (2002, "Can't connect to server on '127.0.0.1' (10061)")
ERROR 2025-05-15 21:14:09,764 basehttp "GET /profile/ HTTP/1.1" 500 272871
ERROR 2025-05-15 21:14:10,081 log Internal Server Error: /profile/
Traceback (most recent call last):
  File "C:\Users\ozifi\OneDrive\Masaüstü\django\venv\lib\site-packages\django\contrib\sessions\backends\base.py", line 233, in _get_session
    return self._session_cache
AttributeError: 'SessionStore' object has no attribute '_session_cache'

During handling of the above exception, another exception occurred:

Traceback (most recent call last):
  File "C:\Users\ozifi\OneDrive\Masaüstü\django\venv\lib\site-packages\django\db\backends\base\base.py", line 219, in ensure_connection
    self.connect()
  File "C:\Users\ozifi\OneDrive\Masaüstü\django\venv\lib\site-packages\django\utils\asyncio.py", line 26, in inner
    return func(*args, **kwargs)
  File "C:\Users\ozifi\OneDrive\Masaüstü\django\venv\lib\site-packages\django\db\backends\base\base.py", line 200, in connect
    self.connection = self.get_new_connection(conn_params)
  File "C:\Users\ozifi\OneDrive\Masaüstü\django\venv\lib\site-packages\django\utils\asyncio.py", line 26, in inner
    return func(*args, **kwargs)
  File "C:\Users\ozifi\OneDrive\Masaüstü\django\venv\lib\site-packages\django\db\backends\mysql\base.py", line 234, in get_new_connection
    connection = Database.connect(**conn_params)
  File "C:\Users\ozifi\OneDrive\Masaüstü\django\venv\lib\site-packages\MySQLdb\__init__.py", line 121, in Connect
    return Connection(*args, **kwargs)
  File "C:\Users\ozifi\OneDrive\Masaüstü\django\venv\lib\site-packages\MySQLdb\connections.py", line 200, in __init__
    super().__init__(*args, **kwargs2)
MySQLdb.OperationalError: (2002, "Can't connect to server on '127.0.0.1' (10061)")

The above exception was the direct cause of the following exception:

Traceback (most recent call last):
  File "C:\Users\ozifi\OneDrive\Masaüstü\django\venv\lib\site-packages\django\core\handlers\exception.py", line 47, in inner
    response = get_response(request)
  File "C:\Users\ozifi\OneDrive\Masaüstü\django\venv\lib\site-packages\django\core\handlers\base.py", line 181, in _get_response
    response = wrapped_callback(request, *callback_args, **callback_kwargs)
  File "C:\Users\ozifi\OneDrive\Masaüstü\django\venv\lib\site-packages\django\contrib\auth\decorators.py", line 20, in _wrapped_view
    if test_func(request.user):
  File "C:\Users\ozifi\OneDrive\Masaüstü\django\venv\lib\site-packages\django\contrib\auth\decorators.py", line 44, in <lambda>
    lambda u: u.is_authenticated,
  File "C:\Users\ozifi\OneDrive\Masaüstü\django\venv\lib\site-packages\django\utils\functional.py", line 246, in inner
    self._setup()
  File "C:\Users\ozifi\OneDrive\Masaüstü\django\venv\lib\site-packages\django\utils\functional.py", line 382, in _setup
    self._wrapped = self._setupfunc()
  File "C:\Users\ozifi\OneDrive\Masaüstü\django\venv\lib\site-packages\django\contrib\auth\middleware.py", line 23, in <lambda>
    request.user = SimpleLazyObject(lambda: get_user(request))
  File "C:\Users\ozifi\OneDrive\Masaüstü\django\venv\lib\site-packages\django\contrib\auth\middleware.py", line 11, in get_user
    request._cached_user = auth.get_user(request)
  File "C:\Users\ozifi\OneDrive\Masaüstü\django\venv\lib\site-packages\django\contrib\auth\__init__.py", line 177, in get_user
    user_id = _get_user_session_key(request)
  File "C:\Users\ozifi\OneDrive\Masaüstü\django\venv\lib\site-packages\django\contrib\auth\__init__.py", line 60, in _get_user_session_key
    return get_user_model()._meta.pk.to_python(request.session[SESSION_KEY])
  File "C:\Users\ozifi\OneDrive\Masaüstü\django\venv\lib\site-packages\django\contrib\sessions\backends\base.py", line 65, in __getitem__
    return self._session[key]
  File "C:\Users\ozifi\OneDrive\Masaüstü\django\venv\lib\site-packages\django\contrib\sessions\backends\base.py", line 238, in _get_session
    self._session_cache = self.load()
  File "C:\Users\ozifi\OneDrive\Masaüstü\django\venv\lib\site-packages\django\contrib\sessions\backends\db.py", line 43, in load
    s = self._get_session_from_db()
  File "C:\Users\ozifi\OneDrive\Masaüstü\django\venv\lib\site-packages\django\contrib\sessions\backends\db.py", line 32, in _get_session_from_db
    return self.model.objects.get(
  File "C:\Users\ozifi\OneDrive\Masaüstü\django\venv\lib\site-packages\django\db\models\manager.py", line 85, in manager_method
    return getattr(self.get_queryset(), name)(*args, **kwargs)
  File "C:\Users\ozifi\OneDrive\Masaüstü\django\venv\lib\site-packages\django\db\models\query.py", line 431, in get
    num = len(clone)
  File "C:\Users\ozifi\OneDrive\Masaüstü\django\venv\lib\site-packages\django\db\models\query.py", line 262, in __len__
    self._fetch_all()
  File "C:\Users\ozifi\OneDrive\Masaüstü\django\venv\lib\site-packages\django\db\models\query.py", line 1324, in _fetch_all
    self._result_cache = list(self._iterable_class(self))
  File "C:\Users\ozifi\OneDrive\Masaüstü\django\venv\lib\site-packages\django\db\models\query.py", line 51, in __iter__
    results = compiler.execute_sql(chunked_fetch=self.chunked_fetch, chunk_size=self.chunk_size)
  File "C:\Users\ozifi\OneDrive\Masaüstü\django\venv\lib\site-packages\django\db\models\sql\compiler.py", line 1167, in execute_sql
    cursor = self.connection.cursor()
  File "C:\Users\ozifi\OneDrive\Masaüstü\django\venv\lib\site-packages\django\utils\asyncio.py", line 26, in inner
    return func(*args, **kwargs)
  File "C:\Users\ozifi\OneDrive\Masaüstü\django\venv\lib\site-packages\django\db\backends\base\base.py", line 259, in cursor
    return self._cursor()
  File "C:\Users\ozifi\OneDrive\Masaüstü\django\venv\lib\site-packages\django\db\backends\base\base.py", line 235, in _cursor
    self.ensure_connection()
  File "C:\Users\ozifi\OneDrive\Masaüstü\django\venv\lib\site-packages\django\utils\asyncio.py", line 26, in inner
    return func(*args, **kwargs)
  File "C:\Users\ozifi\OneDrive\Masaüstü\django\venv\lib\site-packages\django\db\backends\base\base.py", line 218, in ensure_connection
    with self.wrap_database_errors:
  File "C:\Users\ozifi\OneDrive\Masaüstü\django\venv\lib\site-packages\django\db\utils.py", line 90, in __exit__
    raise dj_exc_value.with_traceback(traceback) from exc_value
  File "C:\Users\ozifi\OneDrive\Masaüstü\django\venv\lib\site-packages\django\db\backends\base\base.py", line 219, in ensure_connection
    self.connect()
  File "C:\Users\ozifi\OneDrive\Masaüstü\django\venv\lib\site-packages\django\utils\asyncio.py", line 26, in inner
    return func(*args, **kwargs)
  File "C:\Users\ozifi\OneDrive\Masaüstü\django\venv\lib\site-packages\django\db\backends\base\base.py", line 200, in connect
    self.connection = self.get_new_connection(conn_params)
  File "C:\Users\ozifi\OneDrive\Masaüstü\django\venv\lib\site-packages\django\utils\asyncio.py", line 26, in inner
    return func(*args, **kwargs)
  File "C:\Users\ozifi\OneDrive\Masaüstü\django\venv\lib\site-packages\django\db\backends\mysql\base.py", line 234, in get_new_connection
    connection = Database.connect(**conn_params)
  File "C:\Users\ozifi\OneDrive\Masaüstü\django\venv\lib\site-packages\MySQLdb\__init__.py", line 121, in Connect
    return Connection(*args, **kwargs)
  File "C:\Users\ozifi\OneDrive\Masaüstü\django\venv\lib\site-packages\MySQLdb\connections.py", line 200, in __init__
    super().__init__(*args, **kwargs2)
django.db.utils.OperationalError: (2002, "Can't connect to server on '127.0.0.1' (10061)")
ERROR 2025-05-15 21:14:10,096 basehttp "GET /profile/ HTTP/1.1" 500 272871
ERROR 2025-05-15 21:14:15,628 log Internal Server Error: /
Traceback (most recent call last):
  File "C:\Users\ozifi\OneDrive\Masaüstü\django\venv\lib\site-packages\django\contrib\sessions\backends\base.py", line 233, in _get_session
    return self._session_cache
AttributeError: 'SessionStore' object has no attribute '_session_cache'

During handling of the above exception, another exception occurred:

Traceback (most recent call last):
  File "C:\Users\ozifi\OneDrive\Masaüstü\django\venv\lib\site-packages\django\db\backends\base\base.py", line 219, in ensure_connection
    self.connect()
  File "C:\Users\ozifi\OneDrive\Masaüstü\django\venv\lib\site-packages\django\utils\asyncio.py", line 26, in inner
    return func(*args, **kwargs)
  File "C:\Users\ozifi\OneDrive\Masaüstü\django\venv\lib\site-packages\django\db\backends\base\base.py", line 200, in connect
    self.connection = self.get_new_connection(conn_params)
  File "C:\Users\ozifi\OneDrive\Masaüstü\django\venv\lib\site-packages\django\utils\asyncio.py", line 26, in inner
    return func(*args, **kwargs)
  File "C:\Users\ozifi\OneDrive\Masaüstü\django\venv\lib\site-packages\django\db\backends\mysql\base.py", line 234, in get_new_connection
    connection = Database.connect(**conn_params)
  File "C:\Users\ozifi\OneDrive\Masaüstü\django\venv\lib\site-packages\MySQLdb\__init__.py", line 121, in Connect
    return Connection(*args, **kwargs)
  File "C:\Users\ozifi\OneDrive\Masaüstü\django\venv\lib\site-packages\MySQLdb\connections.py", line 200, in __init__
    super().__init__(*args, **kwargs2)
MySQLdb.OperationalError: (2002, "Can't connect to server on '127.0.0.1' (10061)")

The above exception was the direct cause of the following exception:

Traceback (most recent call last):
  File "C:\Users\ozifi\OneDrive\Masaüstü\django\venv\lib\site-packages\django\core\handlers\exception.py", line 47, in inner
    response = get_response(request)
  File "C:\Users\ozifi\OneDrive\Masaüstü\django\venv\lib\site-packages\django\core\handlers\base.py", line 181, in _get_response
    response = wrapped_callback(request, *callback_args, **callback_kwargs)
  File "C:\Users\ozifi\OneDrive\Masaüstü\django\venv\lib\site-packages\django\contrib\auth\decorators.py", line 20, in _wrapped_view
    if test_func(request.user):
  File "C:\Users\ozifi\OneDrive\Masaüstü\django\venv\lib\site-packages\django\contrib\auth\decorators.py", line 44, in <lambda>
    lambda u: u.is_authenticated,
  File "C:\Users\ozifi\OneDrive\Masaüstü\django\venv\lib\site-packages\django\utils\functional.py", line 246, in inner
    self._setup()
  File "C:\Users\ozifi\OneDrive\Masaüstü\django\venv\lib\site-packages\django\utils\functional.py", line 382, in _setup
    self._wrapped = self._setupfunc()
  File "C:\Users\ozifi\OneDrive\Masaüstü\django\venv\lib\site-packages\django\contrib\auth\middleware.py", line 23, in <lambda>
    request.user = SimpleLazyObject(lambda: get_user(request))
  File "C:\Users\ozifi\OneDrive\Masaüstü\django\venv\lib\site-packages\django\contrib\auth\middleware.py", line 11, in get_user
    request._cached_user = auth.get_user(request)
  File "C:\Users\ozifi\OneDrive\Masaüstü\django\venv\lib\site-packages\django\contrib\auth\__init__.py", line 177, in get_user
    user_id = _get_user_session_key(request)
  File "C:\Users\ozifi\OneDrive\Masaüstü\django\venv\lib\site-packages\django\contrib\auth\__init__.py", line 60, in _get_user_session_key
    return get_user_model()._meta.pk.to_python(request.session[SESSION_KEY])
  File "C:\Users\ozifi\OneDrive\Masaüstü\django\venv\lib\site-packages\django\contrib\sessions\backends\base.py", line 65, in __getitem__
    return self._session[key]
  File "C:\Users\ozifi\OneDrive\Masaüstü\django\venv\lib\site-packages\django\contrib\sessions\backends\base.py", line 238, in _get_session
    self._session_cache = self.load()
  File "C:\Users\ozifi\OneDrive\Masaüstü\django\venv\lib\site-packages\django\contrib\sessions\backends\db.py", line 43, in load
    s = self._get_session_from_db()
  File "C:\Users\ozifi\OneDrive\Masaüstü\django\venv\lib\site-packages\django\contrib\sessions\backends\db.py", line 32, in _get_session_from_db
    return self.model.objects.get(
  File "C:\Users\ozifi\OneDrive\Masaüstü\django\venv\lib\site-packages\django\db\models\manager.py", line 85, in manager_method
    return getattr(self.get_queryset(), name)(*args, **kwargs)
  File "C:\Users\ozifi\OneDrive\Masaüstü\django\venv\lib\site-packages\django\db\models\query.py", line 431, in get
    num = len(clone)
  File "C:\Users\ozifi\OneDrive\Masaüstü\django\venv\lib\site-packages\django\db\models\query.py", line 262, in __len__
    self._fetch_all()
  File "C:\Users\ozifi\OneDrive\Masaüstü\django\venv\lib\site-packages\django\db\models\query.py", line 1324, in _fetch_all
    self._result_cache = list(self._iterable_class(self))
  File "C:\Users\ozifi\OneDrive\Masaüstü\django\venv\lib\site-packages\django\db\models\query.py", line 51, in __iter__
    results = compiler.execute_sql(chunked_fetch=self.chunked_fetch, chunk_size=self.chunk_size)
  File "C:\Users\ozifi\OneDrive\Masaüstü\django\venv\lib\site-packages\django\db\models\sql\compiler.py", line 1167, in execute_sql
    cursor = self.connection.cursor()
  File "C:\Users\ozifi\OneDrive\Masaüstü\django\venv\lib\site-packages\django\utils\asyncio.py", line 26, in inner
    return func(*args, **kwargs)
  File "C:\Users\ozifi\OneDrive\Masaüstü\django\venv\lib\site-packages\django\db\backends\base\base.py", line 259, in cursor
    return self._cursor()
  File "C:\Users\ozifi\OneDrive\Masaüstü\django\venv\lib\site-packages\django\db\backends\base\base.py", line 235, in _cursor
    self.ensure_connection()
  File "C:\Users\ozifi\OneDrive\Masaüstü\django\venv\lib\site-packages\django\utils\asyncio.py", line 26, in inner
    return func(*args, **kwargs)
  File "C:\Users\ozifi\OneDrive\Masaüstü\django\venv\lib\site-packages\django\db\backends\base\base.py", line 218, in ensure_connection
    with self.wrap_database_errors:
  File "C:\Users\ozifi\OneDrive\Masaüstü\django\venv\lib\site-packages\django\db\utils.py", line 90, in __exit__
    raise dj_exc_value.with_traceback(traceback) from exc_value
  File "C:\Users\ozifi\OneDrive\Masaüstü\django\venv\lib\site-packages\django\db\backends\base\base.py", line 219, in ensure_connection
    self.connect()
  File "C:\Users\ozifi\OneDrive\Masaüstü\django\venv\lib\site-packages\django\utils\asyncio.py", line 26, in inner
    return func(*args, **kwargs)
  File "C:\Users\ozifi\OneDrive\Masaüstü\django\venv\lib\site-packages\django\db\backends\base\base.py", line 200, in connect
    self.connection = self.get_new_connection(conn_params)
  File "C:\Users\ozifi\OneDrive\Masaüstü\django\venv\lib\site-packages\django\utils\asyncio.py", line 26, in inner
    return func(*args, **kwargs)
  File "C:\Users\ozifi\OneDrive\Masaüstü\django\venv\lib\site-packages\django\db\backends\mysql\base.py", line 234, in get_new_connection
    connection = Database.connect(**conn_params)
  File "C:\Users\ozifi\OneDrive\Masaüstü\django\venv\lib\site-packages\MySQLdb\__init__.py", line 121, in Connect
    return Connection(*args, **kwargs)
  File "C:\Users\ozifi\OneDrive\Masaüstü\django\venv\lib\site-packages\MySQLdb\connections.py", line 200, in __init__
    super().__init__(*args, **kwargs2)
django.db.utils.OperationalError: (2002, "Can't connect to server on '127.0.0.1' (10061)")
ERROR 2025-05-15 21:14:15,636 basehttp "GET / HTTP/1.1" 500 272625
ERROR 2025-05-15 21:14:21,426 log Internal Server Error: /
Traceback (most recent call last):
  File "C:\Users\ozifi\OneDrive\Masaüstü\django\venv\lib\site-packages\django\contrib\sessions\backends\base.py", line 233, in _get_session
    return self._session_cache
AttributeError: 'SessionStore' object has no attribute '_session_cache'

During handling of the above exception, another exception occurred:

Traceback (most recent call last):
  File "C:\Users\ozifi\OneDrive\Masaüstü\django\venv\lib\site-packages\django\db\backends\base\base.py", line 219, in ensure_connection
    self.connect()
  File "C:\Users\ozifi\OneDrive\Masaüstü\django\venv\lib\site-packages\django\utils\asyncio.py", line 26, in inner
    return func(*args, **kwargs)
  File "C:\Users\ozifi\OneDrive\Masaüstü\django\venv\lib\site-packages\django\db\backends\base\base.py", line 200, in connect
    self.connection = self.get_new_connection(conn_params)
  File "C:\Users\ozifi\OneDrive\Masaüstü\django\venv\lib\site-packages\django\utils\asyncio.py", line 26, in inner
    return func(*args, **kwargs)
  File "C:\Users\ozifi\OneDrive\Masaüstü\django\venv\lib\site-packages\django\db\backends\mysql\base.py", line 234, in get_new_connection
    connection = Database.connect(**conn_params)
  File "C:\Users\ozifi\OneDrive\Masaüstü\django\venv\lib\site-packages\MySQLdb\__init__.py", line 121, in Connect
    return Connection(*args, **kwargs)
  File "C:\Users\ozifi\OneDrive\Masaüstü\django\venv\lib\site-packages\MySQLdb\connections.py", line 200, in __init__
    super().__init__(*args, **kwargs2)
MySQLdb.OperationalError: (2002, "Can't connect to server on '127.0.0.1' (10061)")

The above exception was the direct cause of the following exception:

Traceback (most recent call last):
  File "C:\Users\ozifi\OneDrive\Masaüstü\django\venv\lib\site-packages\django\core\handlers\exception.py", line 47, in inner
    response = get_response(request)
  File "C:\Users\ozifi\OneDrive\Masaüstü\django\venv\lib\site-packages\django\core\handlers\base.py", line 181, in _get_response
    response = wrapped_callback(request, *callback_args, **callback_kwargs)
  File "C:\Users\ozifi\OneDrive\Masaüstü\django\venv\lib\site-packages\django\contrib\auth\decorators.py", line 20, in _wrapped_view
    if test_func(request.user):
  File "C:\Users\ozifi\OneDrive\Masaüstü\django\venv\lib\site-packages\django\contrib\auth\decorators.py", line 44, in <lambda>
    lambda u: u.is_authenticated,
  File "C:\Users\ozifi\OneDrive\Masaüstü\django\venv\lib\site-packages\django\utils\functional.py", line 246, in inner
    self._setup()
  File "C:\Users\ozifi\OneDrive\Masaüstü\django\venv\lib\site-packages\django\utils\functional.py", line 382, in _setup
    self._wrapped = self._setupfunc()
  File "C:\Users\ozifi\OneDrive\Masaüstü\django\venv\lib\site-packages\django\contrib\auth\middleware.py", line 23, in <lambda>
    request.user = SimpleLazyObject(lambda: get_user(request))
  File "C:\Users\ozifi\OneDrive\Masaüstü\django\venv\lib\site-packages\django\contrib\auth\middleware.py", line 11, in get_user
    request._cached_user = auth.get_user(request)
  File "C:\Users\ozifi\OneDrive\Masaüstü\django\venv\lib\site-packages\django\contrib\auth\__init__.py", line 177, in get_user
    user_id = _get_user_session_key(request)
  File "C:\Users\ozifi\OneDrive\Masaüstü\django\venv\lib\site-packages\django\contrib\auth\__init__.py", line 60, in _get_user_session_key
    return get_user_model()._meta.pk.to_python(request.session[SESSION_KEY])
  File "C:\Users\ozifi\OneDrive\Masaüstü\django\venv\lib\site-packages\django\contrib\sessions\backends\base.py", line 65, in __getitem__
    return self._session[key]
  File "C:\Users\ozifi\OneDrive\Masaüstü\django\venv\lib\site-packages\django\contrib\sessions\backends\base.py", line 238, in _get_session
    self._session_cache = self.load()
  File "C:\Users\ozifi\OneDrive\Masaüstü\django\venv\lib\site-packages\django\contrib\sessions\backends\db.py", line 43, in load
    s = self._get_session_from_db()
  File "C:\Users\ozifi\OneDrive\Masaüstü\django\venv\lib\site-packages\django\contrib\sessions\backends\db.py", line 32, in _get_session_from_db
    return self.model.objects.get(
  File "C:\Users\ozifi\OneDrive\Masaüstü\django\venv\lib\site-packages\django\db\models\manager.py", line 85, in manager_method
    return getattr(self.get_queryset(), name)(*args, **kwargs)
  File "C:\Users\ozifi\OneDrive\Masaüstü\django\venv\lib\site-packages\django\db\models\query.py", line 431, in get
    num = len(clone)
  File "C:\Users\ozifi\OneDrive\Masaüstü\django\venv\lib\site-packages\django\db\models\query.py", line 262, in __len__
    self._fetch_all()
  File "C:\Users\ozifi\OneDrive\Masaüstü\django\venv\lib\site-packages\django\db\models\query.py", line 1324, in _fetch_all
    self._result_cache = list(self._iterable_class(self))
  File "C:\Users\ozifi\OneDrive\Masaüstü\django\venv\lib\site-packages\django\db\models\query.py", line 51, in __iter__
    results = compiler.execute_sql(chunked_fetch=self.chunked_fetch, chunk_size=self.chunk_size)
  File "C:\Users\ozifi\OneDrive\Masaüstü\django\venv\lib\site-packages\django\db\models\sql\compiler.py", line 1167, in execute_sql
    cursor = self.connection.cursor()
  File "C:\Users\ozifi\OneDrive\Masaüstü\django\venv\lib\site-packages\django\utils\asyncio.py", line 26, in inner
    return func(*args, **kwargs)
  File "C:\Users\ozifi\OneDrive\Masaüstü\django\venv\lib\site-packages\django\db\backends\base\base.py", line 259, in cursor
    return self._cursor()
  File "C:\Users\ozifi\OneDrive\Masaüstü\django\venv\lib\site-packages\django\db\backends\base\base.py", line 235, in _cursor
    self.ensure_connection()
  File "C:\Users\ozifi\OneDrive\Masaüstü\django\venv\lib\site-packages\django\utils\asyncio.py", line 26, in inner
    return func(*args, **kwargs)
  File "C:\Users\ozifi\OneDrive\Masaüstü\django\venv\lib\site-packages\django\db\backends\base\base.py", line 218, in ensure_connection
    with self.wrap_database_errors:
  File "C:\Users\ozifi\OneDrive\Masaüstü\django\venv\lib\site-packages\django\db\utils.py", line 90, in __exit__
    raise dj_exc_value.with_traceback(traceback) from exc_value
  File "C:\Users\ozifi\OneDrive\Masaüstü\django\venv\lib\site-packages\django\db\backends\base\base.py", line 219, in ensure_connection
    self.connect()
  File "C:\Users\ozifi\OneDrive\Masaüstü\django\venv\lib\site-packages\django\utils\asyncio.py", line 26, in inner
    return func(*args, **kwargs)
  File "C:\Users\ozifi\OneDrive\Masaüstü\django\venv\lib\site-packages\django\db\backends\base\base.py", line 200, in connect
    self.connection = self.get_new_connection(conn_params)
  File "C:\Users\ozifi\OneDrive\Masaüstü\django\venv\lib\site-packages\django\utils\asyncio.py", line 26, in inner
    return func(*args, **kwargs)
  File "C:\Users\ozifi\OneDrive\Masaüstü\django\venv\lib\site-packages\django\db\backends\mysql\base.py", line 234, in get_new_connection
    connection = Database.connect(**conn_params)
  File "C:\Users\ozifi\OneDrive\Masaüstü\django\venv\lib\site-packages\MySQLdb\__init__.py", line 121, in Connect
    return Connection(*args, **kwargs)
  File "C:\Users\ozifi\OneDrive\Masaüstü\django\venv\lib\site-packages\MySQLdb\connections.py", line 200, in __init__
    super().__init__(*args, **kwargs2)
django.db.utils.OperationalError: (2002, "Can't connect to server on '127.0.0.1' (10061)")
ERROR 2025-05-15 21:14:21,429 basehttp "GET / HTTP/1.1" 500 272623
ERROR 2025-05-24 23:41:58,706 log Internal Server Error: /products/
Traceback (most recent call last):
  File "C:\Users\ozifi\OneDrive\Masaüstü\django\venv\lib\site-packages\django\db\backends\utils.py", line 84, in _execute
    return self.cursor.execute(sql, params)
  File "C:\Users\ozifi\OneDrive\Masaüstü\django\venv\lib\site-packages\django\db\backends\mysql\base.py", line 73, in execute
    return self.cursor.execute(query, args)
  File "C:\Users\ozifi\OneDrive\Masaüstü\django\venv\lib\site-packages\MySQLdb\cursors.py", line 179, in execute
    res = self._query(mogrified_query)
  File "C:\Users\ozifi\OneDrive\Masaüstü\django\venv\lib\site-packages\MySQLdb\cursors.py", line 330, in _query
    db.query(q)
  File "C:\Users\ozifi\OneDrive\Masaüstü\django\venv\lib\site-packages\MySQLdb\connections.py", line 280, in query
    _mysql.connection.query(self, query)
MySQLdb.OperationalError: (1054, "Unknown column 'dashboard_product.is_published' in 'field list'")

The above exception was the direct cause of the following exception:

Traceback (most recent call last):
  File "C:\Users\ozifi\OneDrive\Masaüstü\django\venv\lib\site-packages\django\core\handlers\exception.py", line 47, in inner
    response = get_response(request)
  File "C:\Users\ozifi\OneDrive\Masaüstü\django\venv\lib\site-packages\django\core\handlers\base.py", line 181, in _get_response
    response = wrapped_callback(request, *callback_args, **callback_kwargs)
  File "C:\Users\ozifi\OneDrive\Masaüstü\django\oguzhanCRM\dashboard\views\product_view.py", line 8, in product_list
    return render(request, 'products/product_list.html', {'products': products})
  File "C:\Users\ozifi\OneDrive\Masaüstü\django\venv\lib\site-packages\django\shortcuts.py", line 19, in render
    content = loader.render_to_string(template_name, context, request, using=using)
  File "C:\Users\ozifi\OneDrive\Masaüstü\django\venv\lib\site-packages\django\template\loader.py", line 62, in render_to_string
    return template.render(context, request)
  File "C:\Users\ozifi\OneDrive\Masaüstü\django\venv\lib\site-packages\django\template\backends\django.py", line 61, in render
    return self.template.render(context)
  File "C:\Users\ozifi\OneDrive\Masaüstü\django\venv\lib\site-packages\django\template\base.py", line 170, in render
    return self._render(context)
  File "C:\Users\ozifi\OneDrive\Masaüstü\django\venv\lib\site-packages\django\template\base.py", line 162, in _render
    return self.nodelist.render(context)
  File "C:\Users\ozifi\OneDrive\Masaüstü\django\venv\lib\site-packages\django\template\base.py", line 938, in render
    bit = node.render_annotated(context)
  File "C:\Users\ozifi\OneDrive\Masaüstü\django\venv\lib\site-packages\django\template\base.py", line 905, in render_annotated
    return self.render(context)
  File "C:\Users\ozifi\OneDrive\Masaüstü\django\venv\lib\site-packages\django\template\loader_tags.py", line 150, in render
    return compiled_parent._render(context)
  File "C:\Users\ozifi\OneDrive\Masaüstü\django\venv\lib\site-packages\django\template\base.py", line 162, in _render
    return self.nodelist.render(context)
  File "C:\Users\ozifi\OneDrive\Masaüstü\django\venv\lib\site-packages\django\template\base.py", line 938, in render
    bit = node.render_annotated(context)
  File "C:\Users\ozifi\OneDrive\Masaüstü\django\venv\lib\site-packages\django\template\base.py", line 905, in render_annotated
    return self.render(context)
  File "C:\Users\ozifi\OneDrive\Masaüstü\django\venv\lib\site-packages\django\template\loader_tags.py", line 62, in render
    result = block.nodelist.render(context)
  File "C:\Users\ozifi\OneDrive\Masaüstü\django\venv\lib\site-packages\django\template\base.py", line 938, in render
    bit = node.render_annotated(context)
  File "C:\Users\ozifi\OneDrive\Masaüstü\django\venv\lib\site-packages\django\template\base.py", line 905, in render_annotated
    return self.render(context)
  File "C:\Users\ozifi\OneDrive\Masaüstü\django\venv\lib\site-packages\django\template\defaulttags.py", line 168, in render
    len_values = len(values)
  File "C:\Users\ozifi\OneDrive\Masaüstü\django\venv\lib\site-packages\django\db\models\query.py", line 262, in __len__
    self._fetch_all()
  File "C:\Users\ozifi\OneDrive\Masaüstü\django\venv\lib\site-packages\django\db\models\query.py", line 1324, in _fetch_all
    self._result_cache = list(self._iterable_class(self))
  File "C:\Users\ozifi\OneDrive\Masaüstü\django\venv\lib\site-packages\django\db\models\query.py", line 51, in __iter__
    results = compiler.execute_sql(chunked_fetch=self.chunked_fetch, chunk_size=self.chunk_size)
  File "C:\Users\ozifi\OneDrive\Masaüstü\django\venv\lib\site-packages\django\db\models\sql\compiler.py", line 1169, in execute_sql
    cursor.execute(sql, params)
  File "C:\Users\ozifi\OneDrive\Masaüstü\django\venv\lib\site-packages\django\db\backends\utils.py", line 98, in execute
    return super().execute(sql, params)
  File "C:\Users\ozifi\OneDrive\Masaüstü\django\venv\lib\site-packages\django\db\backends\utils.py", line 66, in execute
    return self._execute_with_wrappers(sql, params, many=False, executor=self._execute)
  File "C:\Users\ozifi\OneDrive\Masaüstü\django\venv\lib\site-packages\django\db\backends\utils.py", line 75, in _execute_with_wrappers
    return executor(sql, params, many, context)
  File "C:\Users\ozifi\OneDrive\Masaüstü\django\venv\lib\site-packages\django\db\backends\utils.py", line 79, in _execute
    with self.db.wrap_database_errors:
  File "C:\Users\ozifi\OneDrive\Masaüstü\django\venv\lib\site-packages\django\db\utils.py", line 90, in __exit__
    raise dj_exc_value.with_traceback(traceback) from exc_value
  File "C:\Users\ozifi\OneDrive\Masaüstü\django\venv\lib\site-packages\django\db\backends\utils.py", line 84, in _execute
    return self.cursor.execute(sql, params)
  File "C:\Users\ozifi\OneDrive\Masaüstü\django\venv\lib\site-packages\django\db\backends\mysql\base.py", line 73, in execute
    return self.cursor.execute(query, args)
  File "C:\Users\ozifi\OneDrive\Masaüstü\django\venv\lib\site-packages\MySQLdb\cursors.py", line 179, in execute
    res = self._query(mogrified_query)
  File "C:\Users\ozifi\OneDrive\Masaüstü\django\venv\lib\site-packages\MySQLdb\cursors.py", line 330, in _query
    db.query(q)
  File "C:\Users\ozifi\OneDrive\Masaüstü\django\venv\lib\site-packages\MySQLdb\connections.py", line 280, in query
    _mysql.connection.query(self, query)
django.db.utils.OperationalError: (1054, "Unknown column 'dashboard_product.is_published' in 'field list'")
ERROR 2025-05-24 23:41:58,712 basehttp "GET /products/ HTTP/1.1" 500 231737
ERROR 2025-05-24 23:42:05,975 log Internal Server Error: /products/
Traceback (most recent call last):
  File "C:\Users\ozifi\OneDrive\Masaüstü\django\venv\lib\site-packages\django\db\backends\utils.py", line 84, in _execute
    return self.cursor.execute(sql, params)
  File "C:\Users\ozifi\OneDrive\Masaüstü\django\venv\lib\site-packages\django\db\backends\mysql\base.py", line 73, in execute
    return self.cursor.execute(query, args)
  File "C:\Users\ozifi\OneDrive\Masaüstü\django\venv\lib\site-packages\MySQLdb\cursors.py", line 179, in execute
    res = self._query(mogrified_query)
  File "C:\Users\ozifi\OneDrive\Masaüstü\django\venv\lib\site-packages\MySQLdb\cursors.py", line 330, in _query
    db.query(q)
  File "C:\Users\ozifi\OneDrive\Masaüstü\django\venv\lib\site-packages\MySQLdb\connections.py", line 280, in query
    _mysql.connection.query(self, query)
MySQLdb.OperationalError: (1054, "Unknown column 'dashboard_product.is_published' in 'field list'")

The above exception was the direct cause of the following exception:

Traceback (most recent call last):
  File "C:\Users\ozifi\OneDrive\Masaüstü\django\venv\lib\site-packages\django\core\handlers\exception.py", line 47, in inner
    response = get_response(request)
  File "C:\Users\ozifi\OneDrive\Masaüstü\django\venv\lib\site-packages\django\core\handlers\base.py", line 181, in _get_response
    response = wrapped_callback(request, *callback_args, **callback_kwargs)
  File "C:\Users\ozifi\OneDrive\Masaüstü\django\oguzhanCRM\dashboard\views\product_view.py", line 8, in product_list
    return render(request, 'products/product_list.html', {'products': products})
  File "C:\Users\ozifi\OneDrive\Masaüstü\django\venv\lib\site-packages\django\shortcuts.py", line 19, in render
    content = loader.render_to_string(template_name, context, request, using=using)
  File "C:\Users\ozifi\OneDrive\Masaüstü\django\venv\lib\site-packages\django\template\loader.py", line 62, in render_to_string
    return template.render(context, request)
  File "C:\Users\ozifi\OneDrive\Masaüstü\django\venv\lib\site-packages\django\template\backends\django.py", line 61, in render
    return self.template.render(context)
  File "C:\Users\ozifi\OneDrive\Masaüstü\django\venv\lib\site-packages\django\template\base.py", line 170, in render
    return self._render(context)
  File "C:\Users\ozifi\OneDrive\Masaüstü\django\venv\lib\site-packages\django\template\base.py", line 162, in _render
    return self.nodelist.render(context)
  File "C:\Users\ozifi\OneDrive\Masaüstü\django\venv\lib\site-packages\django\template\base.py", line 938, in render
    bit = node.render_annotated(context)
  File "C:\Users\ozifi\OneDrive\Masaüstü\django\venv\lib\site-packages\django\template\base.py", line 905, in render_annotated
    return self.render(context)
  File "C:\Users\ozifi\OneDrive\Masaüstü\django\venv\lib\site-packages\django\template\loader_tags.py", line 150, in render
    return compiled_parent._render(context)
  File "C:\Users\ozifi\OneDrive\Masaüstü\django\venv\lib\site-packages\django\template\base.py", line 162, in _render
    return self.nodelist.render(context)
  File "C:\Users\ozifi\OneDrive\Masaüstü\django\venv\lib\site-packages\django\template\base.py", line 938, in render
    bit = node.render_annotated(context)
  File "C:\Users\ozifi\OneDrive\Masaüstü\django\venv\lib\site-packages\django\template\base.py", line 905, in render_annotated
    return self.render(context)
  File "C:\Users\ozifi\OneDrive\Masaüstü\django\venv\lib\site-packages\django\template\loader_tags.py", line 62, in render
    result = block.nodelist.render(context)
  File "C:\Users\ozifi\OneDrive\Masaüstü\django\venv\lib\site-packages\django\template\base.py", line 938, in render
    bit = node.render_annotated(context)
  File "C:\Users\ozifi\OneDrive\Masaüstü\django\venv\lib\site-packages\django\template\base.py", line 905, in render_annotated
    return self.render(context)
  File "C:\Users\ozifi\OneDrive\Masaüstü\django\venv\lib\site-packages\django\template\defaulttags.py", line 168, in render
    len_values = len(values)
  File "C:\Users\ozifi\OneDrive\Masaüstü\django\venv\lib\site-packages\django\db\models\query.py", line 262, in __len__
    self._fetch_all()
  File "C:\Users\ozifi\OneDrive\Masaüstü\django\venv\lib\site-packages\django\db\models\query.py", line 1324, in _fetch_all
    self._result_cache = list(self._iterable_class(self))
  File "C:\Users\ozifi\OneDrive\Masaüstü\django\venv\lib\site-packages\django\db\models\query.py", line 51, in __iter__
    results = compiler.execute_sql(chunked_fetch=self.chunked_fetch, chunk_size=self.chunk_size)
  File "C:\Users\ozifi\OneDrive\Masaüstü\django\venv\lib\site-packages\django\db\models\sql\compiler.py", line 1169, in execute_sql
    cursor.execute(sql, params)
  File "C:\Users\ozifi\OneDrive\Masaüstü\django\venv\lib\site-packages\django\db\backends\utils.py", line 98, in execute
    return super().execute(sql, params)
  File "C:\Users\ozifi\OneDrive\Masaüstü\django\venv\lib\site-packages\django\db\backends\utils.py", line 66, in execute
    return self._execute_with_wrappers(sql, params, many=False, executor=self._execute)
  File "C:\Users\ozifi\OneDrive\Masaüstü\django\venv\lib\site-packages\django\db\backends\utils.py", line 75, in _execute_with_wrappers
    return executor(sql, params, many, context)
  File "C:\Users\ozifi\OneDrive\Masaüstü\django\venv\lib\site-packages\django\db\backends\utils.py", line 79, in _execute
    with self.db.wrap_database_errors:
  File "C:\Users\ozifi\OneDrive\Masaüstü\django\venv\lib\site-packages\django\db\utils.py", line 90, in __exit__
    raise dj_exc_value.with_traceback(traceback) from exc_value
  File "C:\Users\ozifi\OneDrive\Masaüstü\django\venv\lib\site-packages\django\db\backends\utils.py", line 84, in _execute
    return self.cursor.execute(sql, params)
  File "C:\Users\ozifi\OneDrive\Masaüstü\django\venv\lib\site-packages\django\db\backends\mysql\base.py", line 73, in execute
    return self.cursor.execute(query, args)
  File "C:\Users\ozifi\OneDrive\Masaüstü\django\venv\lib\site-packages\MySQLdb\cursors.py", line 179, in execute
    res = self._query(mogrified_query)
  File "C:\Users\ozifi\OneDrive\Masaüstü\django\venv\lib\site-packages\MySQLdb\cursors.py", line 330, in _query
    db.query(q)
  File "C:\Users\ozifi\OneDrive\Masaüstü\django\venv\lib\site-packages\MySQLdb\connections.py", line 280, in query
    _mysql.connection.query(self, query)
django.db.utils.OperationalError: (1054, "Unknown column 'dashboard_product.is_published' in 'field list'")
ERROR 2025-05-24 23:42:05,979 basehttp "GET /products/ HTTP/1.1" 500 231739
